Workbook

Sheet 00_Cover
B3: TEAM FALCONS
B4: Unified Talent Pricing OS · v1.3
B5: One operating system for Players, Creators & Mixed campaigns.
B6: Updated: 18 April 2026 · Currency: SAR · 1 USD = 3.75 SAR · Confidential — internal use only
B7: Updated: 18 April 2026 · Currency: SAR · VAT: 15% · Owner: Team Falcons Commercial
B8: =COUNTA('20_Player_Rate_Card'!C6:C500)+COUNTA('30_Creator_Rate_Card'!C6:C100) -> 206 | D8: =COUNTA('20_Player_Rate_Card'!C6:C500) -> 189 | F8: =COUNTA('30_Creator_Rate_Card'!C6:C100) -> 17 | H8: =COUNTIF('20_Player_Rate_Card'!I6:I500,"Tier 1")&"/"&COUNTIF('20_Player_Rate_Card'!I6:I500,"Tier 2")&"/"&COUNTIF('20_Player_Rate_Card'!I6:I500,"Tier 3") -> 25/106/58
B9: Total Talent | D9: Players | F9: Creators | H9: T1 / T2 / T3 (Players)
B12: NAVIGATION
B13: GOVERNANCE
B14: 01_Settings | C14: Global config · VAT · USD · approvers · bank · Shikenso
B15: 02_Lookups | C15: Canonical dropdown values used across the workbook
B16: 03_Benchmarks | C16: Market benchmarks — Tier 1 / MENA / platform CPMs
B18: DATA BACKBONE
B19: 10_Social_Tracker | C19: Normalized handles + followers (source of truth for social data)
B20: 11_Confidence | C20: Verification rules & measurement confidence tiering
B22: PLAYER LANE
B23: 20_Player_Rate_Card | C23: 189 active entries · platform rates · floor · confidence
B25: CREATOR LANE
B26: 30_Creator_Rate_Card | C26: 17 creators · ceiling rates · opening factor
B28: PRICING ENGINE
B29: 40_Adjustment_Matrix | C29: 9-axis commercial decision system + live price calculator
B30: 41_Add_On_Rights | C30: Rights packages & add-ons (separate from organic)
B32: QUOTATION
B33: 42_Preview | C33: Quick scenario preview calculator — live multipliers
B34: 51_Quote_Preview | C34: Client-facing KFC-style quote — template for Apps Script output
B35: 52_Quote_Log | C35: All generated quotes · audit trail
B36: 53_Inquiry_Log | C36: Inbound pipeline · approval flags
B38: METHODOLOGY & DOCS
B39: 90_Methodology | C39: Rewritten commercial methodology
B40: 91_Roadmap | C40: Phased evolution plan (V1 → Shikenso → rolling)
B41: 95_Guide_EN | C41: English user guide
B42: 96_Guide_AR | C42: دليل المستخدم بالعربي
B43: 97_Changelog | C43: Version log
B44: 99_Script_Map | C44: Named ranges & addresses for future Apps Script
B46: LEGEND — CELL CONVENTIONS
B47: Blue text / yellow fill | C47: User input cell — safe to edit
B48: Black text | C48: Formula — do not overwrite
B49: Green text | C49: Cross-sheet link
B50: Red text | C50: External / placeholder
B52: Team Falcons — Unified Talent Pricing OS v1.1 · Confidential
...

Sheet 01_Settings
B2: 01 — SETTINGS & GOVERNANCE
B3: Single source of truth for global parameters. Anything here is read by every other tab.
B5: WORKBOOK
B6: Key | C6: Value | D6: Notes
B7: Workbook Version | C7: v1.0 | D7: Schema version — bump on breaking changes
B8: Last Updated | C8: 18 April 2026 | D8: Human-readable revision date
B9: Schema Stable Until | C9: v2.0 | D9: Apps Script may bind to addresses until this version
B11: CURRENCY & TAX
B12: Key | C12: Value | D12: Notes
B13: Primary Currency | C13: SAR | D13: All rate cards and quotes in SAR
B14: USD Rate (SAR per USD) | C14: 3.75 | D14: Used for USD preview columns
B15: VAT Rate | C15: 0.15 | D15: Saudi VAT 15%
B17: COMMERCIAL DEFAULTS
B18: Key | C18: Value | D18: Notes
B19: Default Management Fee | C19: 0.1 | D19: Applied to quote subtotal unless overridden
B20: Default Opening Factor | C20: 0.75 | D20: Creator opening offer = Ceiling × Opening Factor
B21: Default Rush Uplift | C21: 0.25 | D21: Rush <72h — aligned to industry standard
B22: Default Markup on Player Cost | C22: 0.75 | D22: Legacy; override per talent on rate card
B24: APPROVAL & COMPLIANCE
B25: Key | C25: Value | D25: Notes
B26: Legal Approver Email | C26: legal@teamfalcons.gg | D26: Quotes > trigger threshold require legal
B27: Finance Approver Email | C27: finance@teamfalcons.gg | D27: Finance co-sign on all invoiced quotes
B28: High-Value Approval Threshold (SAR) | C28: 150000 | D28: Quotes above this trigger legal approval
B29: Exclusivity Approval Required? | C29: Yes | D29: Any exclusivity add-on requires legal sign-off
B30: Approval Secret | C30: falcons2026 | D30: Apps Script approval token (placeholder)
B32: FUTURE AUTOMATION PLACEHOLDERS
B33: Key | C33: Value | D33: Notes
B34: output_folder_id | D34: Google Drive folder for generated PDFs
B35: Shikenso API Key | D35: Enterprise analytics — integrated in roadmap Phase 2
B36: Shikenso Base URL | C36: https://api.shikenso.com/v1 | D36: Default endpoint
B37: client_email | D37: Optional default recipient
B39: BANKING (INVOICE)
B40: Key | C40: Value | D40: Notes
B41: Bank Name | C41: Al Rajhi Bank | D41: Invoice banking details
B42: Account Name | C42: Team Falcons
B43: IBAN | D43: To fill — banking
B44: Swift / BIC
B47: Team Falcons · Unified Talent Pricing OS v1.2 · Confidential

Sheet 02_Lookups
B2: 02 — CANONICAL LOOKUPS
B3: Every dropdown value and multiplier in the workbook resolves here. Change a number here = change the whole engine.
B5: TIERS
B6: Label | C6: Tier | D6: Description / Notes
B7: Tier S — Superstar | C7: Global anchor · 1M+ on any platform
B8: Tier 1 — Star | C8: Core pro or creator · 250K–1M
B9: Tier 2 — Core | C9: Active pros / mid-tier creators · 50K–250K
B10: Tier 3 — Rising | C10: Emerging talent · 10K–50K
B11: Tier 4 — Entry/Staff | C11: Support roles · <10K
B13: ENGAGEMENT
B14: Label | C14: Multiplier | D14: Description / Notes
B15: < 2% — Below | C15: 0.7
B16: 2–4% — Average | C16: 0.9
B17: 4–6% — Baseline | C17: 1
B18: 6–8% — Good | C18: 1.2
B19: 8–10% — Excellent | C19: 1.4
B20: > 10% — Premium | C20: 1.6
B22: AUDIENCE QUALITY / FIT
B23: Label | C23: Multiplier | D23: Description / Notes
B24: Generic / Broad | C24: 0.85
B25: Gaming-adjacent | C25: 1
B26: Core Gaming | C26: 1.2
B27: Esports-focused | C27: 1.4
B28: MENA / Saudi focus | C28: 1.3
B29: Global Esports Elite | C29: 1.5
B30: Sports / Football / Active | C30: 1.1
B31: Youth Entertainment / Variety | C31: 1.05
B33: CAMPAIGN OBJECTIVE
B34: Label | C34: ObjWeight | D34: Description / Notes
B35: Awareness | C35: 0.2
B36: Conversion | C36: 0.4
B37: Trust (Pro Authority) | C37: 0.7
B39: AUTHORITY / STATUS
B40: Label | C40: AuthMult | D40: Description / Notes
B41: Normal | C41: 1
B42: Proven / Established | C42: 1.15
B43: Elite Contender | C43: 1.3
B44: Global Star / Major Winner | C44: 1.5
B46: LANGUAGE
B47: Label | C47: Multiplier | D47: Description / Notes
...

Sheet 03_Benchmarks
B2: 03 — MARKET BENCHMARKS & COMPETITIVE INTELLIGENCE
B3: Industry rate benchmarks and competitive positioning for Team Falcons talent monetisation.
B5: SECTION 1 — GLOBAL TIER 1 ESPORTS ORG BENCHMARKS
B6: Organisation | C6: Region | D6: Tier | E6: Avg Followers | F6: Avg Base Fee / Post (USD) | G6: Avg Stream Deal (USD) | H6: Avg Annual Sponsorship (USD) | I6: Exclusivity Premium | J6: Engagement Benchmark | K6: Source / Notes
B7: T1 Esports | C7: Global | D7: Tier 1 | E7: 2M–8M | F7: $8k–$25k | G7: $20k–$80k | H7: $500K–$2M | I7: +50-100% | J7: 4-7% ER | K7: Newzoo 2025; public disclosures
B8: FaZe Clan | C8: Global | D8: Tier 1 | E8: 3M–15M | F8: $10k–$40k | G8: $30k–$120k | H8: $1M–$5M | I8: +40-75% | J8: 3-6% ER | K8: Newzoo 2025; SEC filings
B9: NaVi | C9: EMEA | D9: Tier 1 | E9: 1M–5M | F9: $5k–$20k | G9: $15k–$60k | H9: $300K–$1.5M | I9: +35-60% | J9: 4-8% ER | K9: Shikenso Esports Sponsorship 2025
B10: Fnatic | C10: EMEA | D10: Tier 1 | E10: 500K–3M | F10: $4k–$15k | G10: $10k–$45k | H10: $200K–$800K | I10: +30-50% | J10: 5-9% ER | K10: Influencity 2026
B11: Cloud9 | C11: NA | D11: Tier 1 | E11: 1M–6M | F11: $6k–$22k | G11: $18k–$70k | H11: $400K–$1.8M | I11: +30-50% | J11: 3-6% ER | K11: Nielsen Esports 2025
B12: 100 Thieves | C12: NA | D12: Tier 1 | E12: 500K–4M | F12: $5k–$18k | G12: $15k–$55k | H12: $350K–$1.2M | I12: +40-70% | J12: 5-10% ER | K12: Porter Wills 2025
B14: SECTION 2 — MENA ESPORTS ORG BENCHMARKS
B15: Organisation | C15: Region | D15: Tier | E15: Avg Followers | F15: Avg Base Fee / Post (SAR) | G15: Avg Stream Deal (SAR) | H15: Avg Annual Sponsorship (SAR) | I15: Exclusivity Premium | J15: Engagement Benchmark | K15: Source / Notes
B16: Team Falcons | C16: KSA/MENA | D16: Tier 1 | E16: 200K–2M | F16: SAR 8k–60k | G16: SAR 20k–120k | H16: SAR 500K–2M | I16: +35-60% | J16: 5-12% ER | K16: Internal Falcons data 2025
B17: Nasr Esports | C17: KSA/MENA | D17: Tier 1 | E17: 100K–800K | F17: SAR 5k–30k | G17: SAR 12k–60k | H17: SAR 200K–800K | I17: +30-50% | J17: 4-9% ER | K17: Shikenso MENA 2025
B18: Twisted Minds | C18: KSA | D18: Tier 2 | E18: 80K–500K | F18: SAR 4k–20k | G18: SAR 10k–45k | H18: SAR 150K–500K | I18: +25-45% | J18: 6-11% ER | K18: Internal market intel 2025
B19: Galaxy Racer | C19: UAE/MENA | D19: Tier 2 | E19: 100K–1M | F19: SAR 4.5k–22k | G19: SAR 11k–50k | H19: SAR 180K–600K | I19: +25-40% | J19: 4-9% ER | K19: Newzoo MENA 2025
B20: Team Vitality | C20: MENA | D20: Tier 1 | E20: 200K–1.5M | F20: SAR 6k–35k | G20: SAR 15k–70k | H20: SAR 250K–900K | I20: +30-50% | J20: 4-8% ER | K20: Shikenso 2025
B22: SECTION 3 — PLATFORM RATE BENCHMARKS (Industry Standard CPM / CPE)
B23: Platform | C23: Content Type | D23: Nano 1-10K | E23: Micro 10-100K | F23: Mid 100K-1M | G23: Macro 1-5M | H23: Mega 5M+ | I23: Min ER | J23: Avg CPM | K23: Notes
B24: Instagram | C24: Reel (60s) | D24: $200–1k | E24: $1k–5k | F24: $5k–15k | G24: $15k–50k | H24: $50k+ | I24: 3% | J24: $8–15 | K24: Reels outperform static 3:1 for brand recall
B25: Instagram | C25: Static | D25: $150–800 | E25: $800–4k | F25: $4k–12k | G25: $12k–40k | H25: $40k+ | I25: 2% | J25: $5–10 | K25: Declining vs Reels
B26: TikTok | C26: Branded video | D26: $300–1.5k | E26: $1.5k–6k | F26: $6k–20k | G26: $20k–60k | H26: $60k+ | I26: 5% | J26: $10–20 | K26: MENA: 20–40% premium vs IG
B27: YouTube | C27: Integration (30s) | D27: $500–2k | E27: $2k–8k | F27: $8k–25k | G27: $25k–80k | H27: $80k+ | I27: 1% | J27: $15–30 | K27: Highest brand recall 72%
B28: YouTube | C28: Short (<60s) | D28: $200–1k | E28: $1k–4k | F28: $4k–12k | G28: $12k–35k | H28: $35k+ | I28: 3% | J28: $8–18 | K28: Growing rapidly in MENA
B29: Twitch | C29: Stream integration (2h) | D29: $1k–4k | E29: $4k–15k | F29: $15k–40k | G29: $40k–100k | H29: $100k+ | I29: 500 CCU | J29: $5–15 | K29: CCU-based not followers
B30: X / Twitter | C30: Sponsored post | D30: $100–500 | E30: $500–2k | F30: $2k–6k | G30: $6k–20k | H30: $20k+ | I30: 1% | J30: $3–8 | K30: Declining post-rebrand
B32: Sources: Newzoo 2025, Nielsen Esports 2025, Shikenso MENA 2025, Influencity 2026, Porter Wills Esports Marketing Guide 2025, StreamElements 2025, Internal Falcons data 2025.
B35: Team Falcons · Unified Talent Pricing OS v1.2 · Confidential

Sheet 10_Social_Tracker
B2: 10 — SOCIAL TRACKER (source of truth for handles & followers)
B3: One row per (talent × platform). Drives rate card follower columns via lookups. Leave Current Count blank if unverified — the engine will tag 'pending' automatically.
B4: Source Row | C4: Game | D4: Team | E4: Nickname | F4: Full Name | G4: Role | H4: Platform | I4: Handle | J4: Normalized URL | K4: Metric | L4: Current Count | M4: Retrieved On | N4: Source Method | O4: Confidence | P4: Notes
B5: 4 | C5: Apex Legends | D5: Apex Legends | E5: Gild | F5: Zachary Dennis | G5: Player | H5: X | I5: Gildersons_ | J5: https://x.com/Gildersons_ | K5: Followers | N5: manual | O5: =IF(ISBLANK(L5),"pending","estimated") -> pending
B6: 4 | C6: Apex Legends | D6: Apex Legends | E6: Gild | F6: Zachary Dennis | G6: Player | H6: Twitch | I6: Gild | J6: https://www.twitch.tv/Gild | K6: Followers | N6: manual | O6: =IF(ISBLANK(L6),"pending","estimated") -> pending
B7: 5 | C7: Apex Legends | D7: Apex Legends | E7: ImperialHal | F7: Phillip Dosen | G7: Player | H7: X | I7: ImperialHal | J7: https://x.com/ImperialHal | K7: Followers | N7: manual | O7: =IF(ISBLANK(L7),"pending","estimated") -> pending
B8: 5 | C8: Apex Legends | D8: Apex Legends | E8: ImperialHal | F8: Phillip Dosen | G8: Player | H8: Instagram | I8: ImperialHal | J8: https://www.instagram.com/ImperialHal/ | K8: Followers | N8: manual | O8: =IF(ISBLANK(L8),"pending","estimated") -> pending | P8: Original entry was shorthand
B9: 5 | C9: Apex Legends | D9: Apex Legends | E9: ImperialHal | F9: Phillip Dosen | G9: Player | H9: Twitch | I9: imperialhal__ | J9: https://www.twitch.tv/imperialhal__ | K9: Followers | N9: manual | O9: =IF(ISBLANK(L9),"pending","estimated") -> pending
B10: 5 | C10: Apex Legends | D10: Apex Legends | E10: ImperialHal | F10: Phillip Dosen | G10: Player | H10: YouTube | I10: ImperialHal | J10: https://www.youtube.com/@ImperialHal | K10: Subscribers | N10: manual | O10: =IF(ISBLANK(L10),"pending","estimated") -> pending | P10: Original entry was shorthand; Channel format may need validation
B11: 7 | C11: Apex Legends | D11: Apex Legends | E11: Wxltzy | F11: Ben Walton | G11: Player | H11: X | I11: Wxltzy | J11: https://x.com/Wxltzy | K11: Followers | N11: manual | O11: =IF(ISBLANK(L11),"pending","estimated") -> pending
B12: 7 | C12: Apex Legends | D12: Apex Legends | E12: Wxltzy | F12: Ben Walton | G12: Player | H12: Instagram | I12: Wxltzy | J12: https://www.instagram.com/Wxltzy/ | K12: Followers | N12: manual | O12: =IF(ISBLANK(L12),"pending","estimated") -> pending | P12: Original entry was shorthand
B13: 7 | C13: Apex Legends | D13: Apex Legends | E13: Wxltzy | F13: Ben Walton | G13: Player | H13: Twitch | I13: wxltzy | J13: https://www.twitch.tv/wxltzy | K13: Followers | N13: manual | O13: =IF(ISBLANK(L13),"pending","estimated") -> pending
B14: 11 | C14: Call of Duty Black Ops 7 | D14: Riyadh Falcons | E14: Cellium | F14: McArthur Jovel | G14: Player | H14: X | I14: Cellium | J14: https://twitter.com/Cellium | K14: Followers | N14: manual | O14: =IF(ISBLANK(L14),"pending","estimated") -> pending
B15: 11 | C15: Call of Duty Black Ops 7 | D15: Riyadh Falcons | E15: Cellium | F15: McArthur Jovel | G15: Player | H15: Instagram | I15: cellium | J15: https://www.instagram.com/cellium/ | K15: Followers | N15: manual | O15: =IF(ISBLANK(L15),"pending","estimated") -> pending
B16: 11 | C16: Call of Duty Black Ops 7 | D16: Riyadh Falcons | E16: Cellium | F16: McArthur Jovel | G16: Player | H16: Twitch | I16: Cellium | J16: https://www.twitch.tv/Cellium | K16: Followers | N16: manual | O16: =IF(ISBLANK(L16),"pending","estimated") -> pending
B17: 12 | C17: Call of Duty Black Ops 7 | D17: Riyadh Falcons | E17: Exnid | F17: Saud Alati | G17: Player | H17: X | I17: Exnid_ | J17: https://x.com/Exnid_ | K17: Followers | N17: manual | O17: =IF(ISBLANK(L17),"pending","estimated") -> pending
B18: 12 | C18: Call of Duty Black Ops 7 | D18: Riyadh Falcons | E18: Exnid | F18: Saud Alati | G18: Player | H18: Twitch | I18: exnid | J18: https://www.twitch.tv/exnid | K18: Followers | N18: manual | O18: =IF(ISBLANK(L18),"pending","estimated") -> pending
B19: 13 | C19: Call of Duty Black Ops 7 | D19: Riyadh Falcons | E19: KiSMET | F19: Matthew Tinsley | G19: Player | H19: X | I19: KiSMET6_ | J19: https://twitter.com/KiSMET6_ | K19: Followers | N19: manual | O19: =IF(ISBLANK(L19),"pending","estimated") -> pending
B20: 13 | C20: Call of Duty Black Ops 7 | D20: Riyadh Falcons | E20: KiSMET | F20: Matthew Tinsley | G20: Player | H20: Instagram | I20: kismet6_ | J20: https://www.instagram.com/kismet6_ | K20: Followers | N20: manual | O20: =IF(ISBLANK(L20),"pending","estimated") -> pending
B21: 13 | C21: Call of Duty Black Ops 7 | D21: Riyadh Falcons | E21: KiSMET | F21: Matthew Tinsley | G21: Player | H21: Twitch | I21: kismet6_ | J21: https://www.twitch.tv/kismet6_ | K21: Followers | N21: manual | O21: =IF(ISBLANK(L21),"pending","estimated") -> pending
B22: 14 | C22: Call of Duty Black Ops 7 | D22: Riyadh Falcons | E22: Pred | F22: Amer Zulbeari | G22: Player | H22: X | I22: Pred | J22: https://x.com/Pred | K22: Followers | N22: manual | O22: =IF(ISBLANK(L22),"pending","estimated") -> pending
B23: 14 | C23: Call of Duty Black Ops 7 | D23: Riyadh Falcons | E23: Pred | F23: Amer Zulbeari | G23: Player | H23: Instagram | I23: amerzulbeariii | J23: https://www.instagram.com/amerzulbeariii | K23: Followers | N23: manual | O23: =IF(ISBLANK(L23),"pending","estimated") -> pending
B24: 14 | C24: Call of Duty Black Ops 7 | D24: Riyadh Falcons | E24: Pred | F24: Amer Zulbeari | G24: Player | H24: Twitch | I24: pred | J24: https://www.twitch.tv/pred | K24: Followers | N24: manual | O24: =IF(ISBLANK(L24),"pending","estimated") -> pending
... B82: 37 | C82: Counterstrike2 | D82: Team Falcons | E82: TeSeS | F82: René Madsen | G82: Player | H82: X | I82: tesescs | J82: https://x.com/tesescs | K82: Followers | N82: manual | O82: =IF(ISBLANK(L82),"pending","estimated") -> pending
B83: 37 | C83: Counterstrike2 | D83: Team Falcons | E83: TeSeS | F83: René Madsen | G83: Player | H83: Instagram | I83: TeseS | J83: https://www.instagram.com/TeseS/ | K83: Followers | N83: manual | O83: =IF(ISBLANK(L83),"pending","estimated") -> pending | P83: Original entry was shorthand
B84: 37 | C84: Counterstrike2 | D84: Team Falcons | E84: TeSeS | F84: René Madsen | G84: Player | H84: Twitch | I84: tesesss | J84: https://www.twitch.tv/tesesss | K84: Followers | N84: manual | O84: =IF(ISBLANK(L84),"pending","estimated") -> pending
B85: 40 | C85: Counterstrike2 | D85: Falcons Force | E85: Tapewaare | F85: Sindre Ellefsen | G85: Player | H85: X | I85: tapewaare | J85: https://x.com/tapewaare | K85: Followers | N85: manual | O85: =IF(ISBLANK(L85),"pending","estimated") -> pending
B86: 40 | C86: Counterstrike2 | D86: Falcons Force | E86: Tapewaare | F86: Sindre Ellefsen | G86: Player | H86: Twitch | I86: Tapewaare | J86: https://www.twitch.tv/Tapewaare | K86: Followers | N86: manual | O86: =IF(ISBLANK(L86),"pending","estimated") -> pending
B87: 41 | C87: Counterstrike2 | D87: Falcons Force | E87: clockzi | F87: Oskar Led Blæsbjerg | G87: Player | H87: X | I87: flcclockzi | J87: https://x.com/flcclockzi | K87: Followers | N87: manual | O87: =IF(ISBLANK(L87),"pending","estimated") -> pending
B88: 42 | C88: Counterstrike2 | D88: Falcons Force | E88: grecu | F88: Andrei Grecu | G88: Player | H88: X | I88: grecuflc | J88: https://x.com/grecuflc | K88: Followers | N88: manual | O88: =IF(ISBLANK(L88),"pending","estimated") -> pending
B89: 42 | C89: Counterstrike2 | D89: Falcons Force | E89: grecu | F89: Andrei Grecu | G89: Player | H89: Twitch | I89: gbcgrecu | J89: https://www.twitch.tv/gbcgrecu | K89: Followers | N89: manual | O89: =IF(ISBLANK(L89),"pending","estimated") -> pending
B90: 43 | C90: Counterstrike2 | D90: Falcons Force | E90: VENO | F90: Vladimir Stanković | G90: Player | H90: X | I90: venocs2 | J90: https://x.com/venocs2 | K90: Followers | N90: manual | O90: =IF(ISBLANK(L90),"pending","estimated") -> pending
B91: 43 | C91: Counterstrike2 | D91: Falcons Force | E91: VENO | F91: Vladimir Stanković | G91: Player | H91: Twitch | I91: venocs2 | J91: https://www.twitch.tv/venocs2 | K91: Followers | N91: manual | O91: =IF(ISBLANK(L91),"pending","estimated") -> pending
B92: 43 | C92: Counterstrike2 | D92: Falcons Force | E92: VENO | F92: Vladimir Stanković | G92: Player | H92: YouTube | I92: @venocs2 | J92: https://www.youtube.com/@venocs2 | K92: Subscribers | N92: manual | O92: =IF(ISBLANK(L92),"pending","estimated") -> pending
B93: 46 | C93: Counterstrike2 | D93: Falcons Force | E93: Nucleonz | F93: Matej Trajkoski | G93: Player | H93: X | I93: NucleonZz | J93: https://x.com/NucleonZz | K93: Followers | N93: manual | O93: =IF(ISBLANK(L93),"pending","estimated") -> pending
B94: 47 | C94: Dota2 | D94: Dota2 | E94: Skiter | F94: Oliver Lepko | G94: Player | H94: X | I94: skiter | J94: https://x.com/skiter | K94: Followers | N94: manual | O94: =IF(ISBLANK(L94),"pending","estimated") -> pending
B95: 47 | C95: Dota2 | D95: Dota2 | E95: Skiter | F95: Oliver Lepko | G95: Player | H95: Instagram | I95: Skiter | J95: https://www.instagram.com/Skiter/ | K95: Followers | N95: manual | O95: =IF(ISBLANK(L95),"pending","estimated") -> pending | P95: Original entry was shorthand
B96: 47 | C96: Dota2 | D96: Dota2 | E96: Skiter | F96: Oliver Lepko | G96: Player | H96: Facebook | I96: SkiterDota | J96: https://www.facebook.com/SkiterDota | K96: Followers / Likes | N96: manual | O96: =IF(ISBLANK(L96),"pending","estimated") -> pending
B97: 48 | C97: Dota2 | D97: Dota2 | E97: Malr1ne | F97: Stanislav Potorak | G97: Player | H97: X | I97: Malr1ne_ | J97: https://x.com/Malr1ne_ | K97: Followers | N97: manual | O97: =IF(ISBLANK(L97),"pending","estimated") -> pending
B98: 48 | C98: Dota2 | D98: Dota2 | E98: Malr1ne | F98: Stanislav Potorak | G98: Player | H98: Instagram | I98: Malr1ne | J98: https://www.instagram.com/Malr1ne/ | K98: Followers | N98: manual | O98: =IF(ISBLANK(L98),"pending","estimated") -> pending | P98: Original entry was shorthand
...

Sheet 11_Confidence
B2: 11 — MEASUREMENT CONFIDENCE & VERIFICATION
B3: Confidence is an enforcement layer, not decoration. Low confidence caps how aggressively premiums can stack, protecting Falcons from over-pricing weakly verified talent.
B5: CONFIDENCE LEVELS & CAPS
B6: Level | C6: Trigger | D6: Premium Policy | E6: Max Combined Stack
B7: exact | C7: Verified via Shikenso API or direct platform access. | D7: All multipliers allowed, no cap. | E7: Computed × 1.00
B8: rounded | C8: Manual verification — clean round numbers from recent check. | D8: All multipliers allowed, no cap. | E8: Computed × 1.00
B9: estimated | C9: Partial data / single-source public scrape. | D9: Eng ≤ 1.20, Authority ≤ 1.30, Season ≤ 1.25. | E9: Computed × 0.90
B10: pending | C10: No follower data yet — awaiting verification. | D10: All premiums forced to 1.00 (baseline). | E10: Computed × 0.75
B12: VERIFICATION WORKFLOW
B13: ① Sync handles | C13: Pull from 10_Social_Tracker — normalized URL + handle per platform
B14: ② Capture count | C14: Enter follower count + Retrieved-On date; source marked
B15: ③ Tag confidence | C15: Set level on 20/30 rate cards; default is 'pending' until data arrives
B16: ④ Quarterly review | C16: Re-pull; estimated → rounded upgrade if recent check passes
B17: ⑤ Shikenso cutover | C17: When API is connected, confidence auto-writes to 'exact'
B19: Confidence is also applied inside 40_Adjustment_Matrix as a gate. See 90_Methodology §5.
B22: Team Falcons · Unified Talent Pricing OS v1.2 · Confidential

Sheet 20_Player_Rate_Card
B2: 20 — PLAYER RATE CARD (v1.0)
B3: Baseline preserved from v7. Follower / CPM / Floor / Confidence extensions preserved from v8. Adjust rates here — every quote pulls from this card.
B4: Identity & Tier | J4: Organic Platform Rates (SAR) | T4: Add-On Fees | X4: Ops & Commercial | AA4: Identity & Handles | AM4: Followers (← fill as verified) | AT4: CPM (auto) | AY4: Authority Floor & Confidence
B5: # | C5: Nickname | D5: Role | E5: Game | F5: Team | G5: Nationality | H5: Platforms | I5: Tier | J5: IG Reel (SAR) | K5: IG Static (SAR) | L5: IG Story (SAR) | M5: TikTok Video (SAR) | N5: YT Short (SAR) | O5: X Post (SAR) | P5: FB Post/Video (SAR) | Q5: Twitch Stream 2h (SAR) | R5: Twitch Integ. (SAR) | S5: IRL / Appear. (SAR) | T5: Rights Fee (SAR) | U5: Exclusivity Fee (SAR) | V5: Rush Fee (SAR) | W5: WL Fee (SAR) | X5: Notes | Y5: Falcons Commission % | Z5: Markup % (on Player Cost) | AA5: Full Name | AB5: X / Twitter | AC5: Instagram | AD5: Twitch | AE5: YouTube | AF5: TikTok | AG5: Kick | AH5: Facebook | AI5: Snapchat | AJ5: Link-in-Bio | AK5: Date of Birth | AL5: Game Role | AM5: X Followers | AN5: IG Followers | AO5: Twitch Followers | AP5: YT Subs | AQ5: TikTok Followers | AR5: Kick Followers | AS5: FB Followers | AT5: IG CPM (SAR) | AU5: TikTok CPM (SAR) | AV5: X CPM (SAR) | AW5: YT CPM (SAR) | AX5: Twitch CPM (SAR) | AY5: Floor Share % | AZ5: Authority Factor | BA5: Default Seasonality | BB5: Default Language | BC5: Authority Floor Baseline (SAR) | BD5: Measurement Confidence | BE5: Tier Review Flag
B6: =IF($C6="","",COUNTA($C$6:C6)) -> 1 | C6: Bijw | D6: Influencer | E6: Esports Influencers | F6: Esports Influencers | G6: Saudi Arabia | H6: 6 | I6: Tier 3 | J6: 11000 | K6: 4600 | L6: =IF(J6="","",ROUND(J6*0.17,0)) -> 1870 | M6: 8600 | N6: 3500 | O6: 2200 | P6: 2200 | Q6: 15950 | R6: 7150 | S6: =IF(J6="","",ROUND(J6*2.2,0)) -> 24200 | T6: 3850 | U6: 3300 | V6: 2000 | W6: 1650 | X6: 6 platforms | Y6: 0.3 | Z6: 1 | AA6: Hisham Nasser | AB6: https://x.com/_bijw | AC6: https://www.instagram.com/bijjw | AD6: https://www.twitch.tv/bijw | AE6: https://www.youtube.com/@Bijw | AF6: https://www.tiktok.com/@biijw | AG6: https://kick.com/bijw | AI6: https://www.snapchat.com/add/bijjw | AJ6: https://linktr.ee/bijw | AT6: =IFERROR(IF(AND(AN6>0,J6>0),ROUND(J6*1000/(AN6*0.2),0),""),"") | AU6: =IFERROR(IF(AND(AQ6>0,M6>0),ROUND(M6*1000/(AQ6*0.3),0),""),"") | AV6: =IFERROR(IF(AND(AM6>0,O6>0),ROUND(O6*1000/(AM6*0.1),0),""),"") | AW6: =IFERROR(IF(AND(AP6>0,N6>0),ROUND(N6*1000/(AP6*0.25),0),""),"") | AX6: =IFERROR(IF(AND(AO6>0,Q6>0),ROUND(Q6*1000/(AO6*1),0),""),"") | AY6: =IFERROR(ifs(I6="Tier S",0.65,I6="Tier 1",0.55,I6="Tier 2",0.45,I6="Tier 3",0.35,I6="Tier 4",0.25),0.35) -> 0.35 | AZ6: 1 | BA6: 1 | BB6: 1 | BC6: =IFERROR(ROUND(S6*AY6*BA6*BB6*AZ6,0),0) -> 8470 | BD6: =IF(COUNT(AM6,AN6,AO6,AP6,AQ6,AR6,AS6)>0,"estimated","pending") -> pending
B7: =IF($C7="","",COUNTA($C$6:C7)) -> 2 | C7: Abo Najd | D7: Influencer | E7: Esports Influencers | F7: Esports Influencers | G7: Saudi Arabia | H7: 4 | I7: Tier 3 | J7: 8100 | K7: 3200 | L7: =IF(J7="","",ROUND(J7*0.17,0)) -> 1377 | M7: 6350 | N7: 2600 | O7: 1600 | P7: 1600 | Q7: 11800 | R7: 5300 | S7: =IF(J7="","",ROUND(J7*2.2,0)) -> 17820 | T7: 2850 | U7: 2450 | V7: 1450 | W7: 1215 | X7: 4 platforms | Y7: 0.3 | Z7: 1 | AA7: Riyad Alfahmi | AB7: https://x.com/K22N8 | AC7: https://www.instagram.com/k2nn8?igsh=ajJsNHoybDlpMzFo | AD7: https://www.twitch.tv/k2nnn8 | AE7: https://www.youtube.com/@k2nn8 | AJ7: https://linktr.ee/K2nnn8 (alt: https://heylink.me/k2nn8) | AT7: =IFERROR(IF(AND(AN7>0,J7>0),ROUND(J7*1000/(AN7*0.2),0),""),"") | AU7: =IFERROR(IF(AND(AQ7>0,M7>0),ROUND(M7*1000/(AQ7*0.3),0),""),"") | AV7: =IFERROR(IF(AND(AM7>0,O7>0),ROUND(O7*1000/(AM7*0.1),0),""),"") | AW7: =IFERROR(IF(AND(AP7>0,N7>0),ROUND(N7*1000/(AP7*0.25),0),""),"") | AX7: =IFERROR(IF(AND(AO7>0,Q7>0),ROUND(Q7*1000/(AO7*1),0),""),"") | AY7: =IFERROR(ifs(I7="Tier S",0.65,I7="Tier 1",0.55,I7="Tier 2",0.45,I7="Tier 3",0.35,I7="Tier 4",0.25),0.35) -> 0.35 | AZ7: 1 | BA7: 1 | BB7: 1 | BC7: =IFERROR(ROUND(S7*AY7*BA7*BB7*AZ7,0),0) -> 6237 | BD7: =IF(COUNT(AM7,AN7,AO7,AP7,AQ7,AR7,AS7)>0,"estimated","pending") -> pending
B8: =IF($C8="","",COUNTA($C$6:C8)) -> 3 | C8: FMG | D8: Influencer | E8: Esports Influencers | F8: Esports Influencers | G8: Saudi Arabia | H8: 4 | I8: Tier 3 | J8: 7450 | K8: 3150 | L8: =IF(J8="","",ROUND(J8*0.17,0)) -> 1267 | M8: 5850 | N8: 2400 | O8: 1500 | P8: 1500 | Q8: 10850 | R8: 4850 | S8: =IF(J8="","",ROUND(J8*2.2,0)) -> 16390 | T8: 2600 | U8: 2250 | V8: 1350 | W8: 1118 | X8: 4 platforms | Y8: 0.3 | Z8: 1 | AA8: Nasser alotaibi | AB8: https://x.com/iFMG_ | AC8: https://www.instagram.com/fm.g/ | AD8: https://www.twitch.tv/fmg_ | AG8: https://kick.com/ifmg | AT8: =IFERROR(IF(AND(AN8>0,J8>0),ROUND(J8*1000/(AN8*0.2),0),""),"") | AU8: =IFERROR(IF(AND(AQ8>0,M8>0),ROUND(M8*1000/(AQ8*0.3),0),""),"") | AV8: =IFERROR(IF(AND(AM8>0,O8>0),ROUND(O8*1000/(AM8*0.1),0),""),"") | AW8: =IFERROR(IF(AND(AP8>0,N8>0),ROUND(N8*1000/(AP8*0.25),0),""),"") | AX8: =IFERROR(IF(AND(AO8>0,Q8>0),ROUND(Q8*1000/(AO8*1),0),""),"") | AY8: =IFERROR(ifs(I8="Tier S",0.65,I8="Tier 1",0.55,I8="Tier 2",0.45,I8="Tier 3",0.35,I8="Tier 4",0.25),0.35) -> 0.35 | AZ8: 1 | BA8: 1 | BB8: 1 | BC8: =IFERROR(ROUND(S8*AY8*BA8*BB8*AZ8,0),0) -> 5737 | BD8: =IF(COUNT(AM8,AN8,AO8,AP8,AQ8,AR8,AS8)>0,"estimated","pending") -> pending
B9: =IF($C9="","",COUNTA($C$6:C9)) -> 4 | C9: Abo Ghazi | D9: Influencer | E9: Esports Influencers | F9: Esports Influencers | G9: Saudi Arabia | H9: 3 | I9: Tier 3 | J9: 5200 | K9: 2200 | L9: =IF(J9="","",ROUND(J9*0.17,0)) -> 884 | M9: 4050 | N9: 1650 | O9: 1050 | P9: 1050 | Q9: 7550 | R9: 3400 | S9: =IF(J9="","",ROUND(J9*2.2,0)) -> 11440 | T9: 1800 | U9: 1550 | V9: 950 | W9: 780 | X9: 3 platforms | Y9: 0.3 | Z9: 1 | AA9: Mohammed Albaqami | AB9: https://x.com/MohxamedZ | AD9: https://www.twitch.tv/ires | AG9: https://kick.com/iabughazi | AH9: https://www.facebook.com/AbuGhaziGaming93 | AI9: https://www.snapchat.com/add/faisalhajhasan | AJ9: https://linktr.ee/abughaazi | AT9: =IFERROR(IF(AND(AN9>0,J9>0),ROUND(J9*1000/(AN9*0.2),0),""),"") | AU9: =IFERROR(IF(AND(AQ9>0,M9>0),ROUND(M9*1000/(AQ9*0.3),0),""),"") | AV9: =IFERROR(IF(AND(AM9>0,O9>0),ROUND(O9*1000/(AM9*0.1),0),""),"") | AW9: =IFERROR(IF(AND(AP9>0,N9>0),ROUND(N9*1000/(AP9*0.25),0),""),"") | AX9: =IFERROR(IF(AND(AO9>0,Q9>0),ROUND(Q9*1000/(AO9*1),0),""),"") | AY9: =IFERROR(ifs(I9="Tier S",0.65,I9="Tier 1",0.55,I9="Tier 2",0.45,I9="Tier 3",0.35,I9="Tier 4",0.25),0.35) -> 0.35 | AZ9: 1 | BA9: 1 | BB9: 1 | BC9: =IFERROR(ROUND(S9*AY9*BA9*BB9*AZ9,0),0) -> 4004 | BD9: =IF(COUNT(AM9,AN9,AO9,AP9,AQ9,AR9,AS9)>0,"estimated","pending") -> pending
B10: =IF($C10="","",COUNTA($C$6:C10)) -> 5 | C10: Mary | D10: Influencer | E10: Esports Influencers | F10: Esports Influencers | G10: Bahraini | H10: 5 | I10: Tier 3 | J10: 8100 | K10: 3400 | L10: =IF(J10="","",ROUND(J10*0.17,0)) -> 1377 | M10: 6350 | N10: 2600 | O10: 1600 | P10: 1600 | Q10: 11800 | R10: 5300 | S10: =IF(J10="","",ROUND(J10*2.2,0)) -> 17820 | T10: 2850 | U10: 2450 | V10: 1450 | W10: 1215 | X10: 5 platforms | Y10: 0.3 | Z10: 1 | AA10: Maryam Maher | AB10: https://x.com/marypink | AC10: https://www.instagram.com/maryvalorantt/?hl=en | AD10: https://www.twitch.tv/mary | AE10: https://www.youtube.com/@maryvalorant/featured | AF10: https://www.tiktok.com/@maryvalorant | AJ10: https://linktr.ee/verymarygaming | AT10: =IFERROR(IF(AND(AN10>0,J10>0),ROUND(J10*1000/(AN10*0.2),0),""),"") | AU10: =IFERROR(IF(AND(AQ10>0,M10>0),ROUND(M10*1000/(AQ10*0.3),0),""),"") | AV10: =IFERROR(IF(AND(AM10>0,O10>0),ROUND(O10*1000/(AM10*0.1),0),""),"") | AW10: =IFERROR(IF(AND(AP10>0,N10>0),ROUND(N10*1000/(AP10*0.25),0),""),"") | AX10: =IFERROR(IF(AND(AO10>0,Q10>0),ROUND(Q10*1000/(AO10*1),0),""),"") | AY10: =IFERROR(ifs(I10="Tier S",0.65,I10="Tier 1",0.55,I10="Tier 2",0.45,I10="Tier 3",0.35,I10="Tier 4",0.25),0.35) -> 0.35 | AZ10: 1 | BA10: 1 | BB10: 1 | BC10: =IFERROR(ROUND(S10*AY10*BA10*BB10*AZ10,0),0) -> 6237 | BD10: =IF(COUNT(AM10,AN10,AO10,AP10,AQ10,AR10,AS10)>0,"estimated","pending") -> pending
B11: =IF($C11="","",COUNTA($C$6:C11)) -> 6 | C11: Ghala | D11: Influencer | E11: Esports Influencers | F11: Esports Influencers | G11: Saudi Arabia | H11: 5 | I11: Tier 3 | J11: 7450 | K11: 3150 | L11: =IF(J11="","",ROUND(J11*0.17,0)) -> 1267 | M11: 5850 | N11: 2400 | O11: 1500 | P11: 1500 | Q11: 10850 | R11: 4850 | S11: =IF(J11="","",ROUND(J11*2.2,0)) -> 16390 | T11: 2600 | U11: 2250 | V11: 1350 | W11: 1118 | X11: 5 platforms | Y11: 0.3 | Z11: 1 | AA11: Ghala Alqahtani | AB11: https://x.com/pg_ghala3?lang=en | AC11: https://www.instagram.com/pg_ghala3 | AE11: https://www.youtube.com/@pg_ghala3 | AF11: https://www.tiktok.com/@pg_ghala3 | AG11: https://kick.com/pg-ghala3 | AI11: https://snapchat.com/t/bLA2ZOsG | AJ11: https://linktr.ee/ga1lll | AT11: =IFERROR(IF(AND(AN11>0,J11>0),ROUND(J11*1000/(AN11*0.2),0),""),"") | AU11: =IFERROR(IF(AND(AQ11>0,M11>0),ROUND(M11*1000/(AQ11*0.3),0),""),"") | AV11: =IFERROR(IF(AND(AM11>0,O11>0),ROUND(O11*1000/(AM11*0.1),0),""),"") | AW11: =IFERROR(IF(AND(AP11>0,N11>0),ROUND(N11*1000/(AP11*0.25),0),""),"") | AX11: =IFERROR(IF(AND(AO11>0,Q11>0),ROUND(Q11*1000/(AO11*1),0),""),"") | AY11: =IFERROR(ifs(I11="Tier S",0.65,I11="Tier 1",0.55,I11="Tier 2",0.45,I11="Tier 3",0.35,I11="Tier 4",0.25),0.35) -> 0.35 | AZ11: 1 | BA11: 1 | BB11: 1 | BC11: =IFERROR(ROUND(S11*AY11*BA11*BB11*AZ11,0),0) -> 5737 | BD11: =IF(COUNT(AM11,AN11,AO11,AP11,AQ11,AR11,AS11)>0,"estimated","pending") -> pending
B12: =IF($C12="","",COUNTA($C$6:C12)) -> 7 | C12: Moaz | D12: Influencer | E12: Esports Influencers | F12: Esports Influencers | G12: Saudi Arabia | H12: 5 | I12: Tier 2 | J12: 6500 | K12: 5300 | L12: =IF(J12="","",ROUND(J12*0.17,0)) -> 1105 | M12: 3400 | N12: 4050 | O12: 2500 | P12: 2500 | Q12: 15950 | R12: 8200 | S12: =IF(J12="","",ROUND(J12*2.2,0)) -> 14300 | T12: 3800 | U12: 1900 | V12: 3150 | W12: 1250 | X12: 5 platforms | Y12: 0.3 | Z12: 1 | AA12: Moaz Asiri | AB12: https://x.com/mezostrong?s=21 | AC12: https://www.instagram.com/mezostrong | AE12: https://www.youtube.com/channel/UCZCgW8WW8K_vrHrO6sZ7oyg?app=desktop | AF12: https://www.tiktok.com/@mezostrong?_r=1&_t=zs-91bbrrsefwl | AG12: https://kick.com/MezoStrong | AT12: =IFERROR(IF(AND(AN12>0,J12>0),ROUND(J12*1000/(AN12*0.2),0),""),"") | AU12: =IFERROR(IF(AND(AQ12>0,M12>0),ROUND(M12*1000/(AQ12*0.3),0),""),"") | AV12: =IFERROR(IF(AND(AM12>0,O12>0),ROUND(O12*1000/(AM12*0.1),0),""),"") | AW12: =IFERROR(IF(AND(AP12>0,N12>0),ROUND(N12*1000/(AP12*0.25),0),""),"") | AX12: =IFERROR(IF(AND(AO12>0,Q12>0),ROUND(Q12*1000/(AO12*1),0),""),"") | AY12: =IFERROR(ifs(I12="Tier S",0.65,I12="Tier 1",0.55,I12="Tier 2",0.45,I12="Tier 3",0.35,I12="Tier 4",0.25),0.35) -> 0.35 | AZ12: 1 | BA12: 1 | BB12: 1 | BC12: =IFERROR(ROUND(S12*AY12*BA12*BB12*AZ12,0),0) -> 5005 | BD12: =IF(COUNT(AM12,AN12,AO12,AP12,AQ12,AR12,AS12)>0,"estimated","pending") -> pending
B13: =IF($C13="","",COUNTA($C$6:C13)) -> 8 | C13: vacwep | D13: Influencer | E13: Esports Influencers | F13: Esports Influencers | G13: Saudi Arabia | H13: 5 | I13: Tier 3 | J13: 7450 | K13: 3150 | L13: =IF(J13="","",ROUND(J13*0.17,0)) -> 1267 | M13: 5800 | N13: 2400 | O13: 1500 | P13: 1500 | Q13: 7500 | R13: 4850 | S13: =IF(J13="","",ROUND(J13*2.2,0)) -> 16390 | T13: 2250 | U13: 1100 | V13: 1850 | W13: 750 | X13: 5 platforms | Y13: 0.3 | Z13: 1 | AA13: Abdullah Mousa A Alsulaymi | AB13: https://x.com/vacwep?s=21&t=PiVx0_LPZgUm0TT5Ok_2Zw | AC13: https://www.instagram.com/vacwep_?igsh=Z28yMXRibTZ0OWlm&utm_source=qr | AF13: https://www.tiktok.com/@vacwep?_r=1&_t=ZS-94jrcxtNGEK | AG13: https://kick.com/vacwep | AH13: https://www.facebook.com/share/1BDLRfGMFS/?mibextid=wwXIfr | AK13: 12/07/1992 | AT13: =IFERROR(IF(AND(AN13>0,J13>0),ROUND(J13*1000/(AN13*0.2),0),""),"") | AU13: =IFERROR(IF(AND(AQ13>0,M13>0),ROUND(M13*1000/(AQ13*0.3),0),""),"") | AV13: =IFERROR(IF(AND(AM13>0,O13>0),ROUND(O13*1000/(AM13*0.1),0),""),"") | AW13: =IFERROR(IF(AND(AP13>0,N13>0),ROUND(N13*1000/(AP13*0.25),0),""),"") | AX13: =IFERROR(IF(AND(AO13>0,Q13>0),ROUND(Q13*1000/(AO13*1),0),""),"") | AY13: =IFERROR(ifs(I13="Tier S",0.65,I13="Tier 1",0.55,I13="Tier 2",0.45,I13="Tier 3",0.35,I13="Tier 4",0.25),0.35) -> 0.35 | AZ13: 1 | BA13: 1 | BB13: 1 | BC13: =IFERROR(ROUND(S13*AY13*BA13*BB13*AZ13,0),0) -> 5737 | BD13: =IF(COUNT(AM13,AN13,AO13,AP13,AQ13,AR13,AS13)>0,"estimated","pending") -> pending
B14: =IF($C14="","",COUNTA($C$6:C14)) -> 9 | C14: Cellium | D14: Player | E14: Call of Duty Black Ops 7 | F14: Riyadh Falcons | G14: American | H14: 3 | I14: Tier 2 | J14: 11250 | K14: 4500 | L14: =IF(J14="","",ROUND(J14*0.17,0)) -> 1913 | M14: 8000 | N14: 3500 | O14: 2000 | P14: 2000 | Q14: 13500 | R14: 6075 | S14: =IF(J14="","",ROUND(J14*2.2,0)) -> 24750 | T14: 4638 | U14: 4063 | V14: 2438 | W14: 2400 | X14: 3 platforms | Y14: 0.3 | Z14: 1 | AA14: McArthur Jovel | AB14: https://twitter.com/Cellium | AC14: https://www.instagram.com/cellium/ | AD14: https://www.twitch.tv/Cellium | AK14: 24/12/2000 | AL14: Assault Rifle / Main AR | AT14: =IFERROR(IF(AND(AN14>0,J14>0),ROUND(J14*1000/(AN14*0.2),0),""),"") | AU14: =IFERROR(IF(AND(AQ14>0,M14>0),ROUND(M14*1000/(AQ14*0.3),0),""),"") | AV14: =IFERROR(IF(AND(AM14>0,O14>0),ROUND(O14*1000/(AM14*0.1),0),""),"") | AW14: =IFERROR(IF(AND(AP14>0,N14>0),ROUND(N14*1000/(AP14*0.25),0),""),"") | AX14: =IFERROR(IF(AND(AO14>0,Q14>0),ROUND(Q14*1000/(AO14*1),0),""),"") | AY14: =IFERROR(ifs(I14="Tier S",0.65,I14="Tier 1",0.55,I14="Tier 2",0.45,I14="Tier 3",0.35,I14="Tier 4",0.25),0.35) -> 0.35 | AZ14: 1 | BA14: 1 | BB14: 1 | BC14: =IFERROR(ROUND(S14*AY14*BA14*BB14*AZ14,0),0) -> 8663 | BD14: =IF(COUNT(AM14,AN14,AO14,AP14,AQ14,AR14,AS14)>0,"estimated","pending") -> pending
B15: =IF($C15="","",COUNTA($C$6:C15)) -> 10 | C15: Exnid | D15: Player | E15: Call of Duty Black Ops 7 | F15: Riyadh Falcons | G15: Saudi Arabia | H15: 2 | I15: Tier 2 | J15: 11000 | K15: 4600 | L15: =IF(J15="","",ROUND(J15*0.17,0)) -> 1870 | M15: 8600 | N15: 3500 | O15: 2200 | P15: 2200 | Q15: 15950 | R15: 7150 | S15: =IF(J15="","",ROUND(J15*2.2,0)) -> 24200 | T15: 3850 | U15: 3300 | V15: 2000 | W15: 2400 | X15: 2 platforms | Y15: 0.3 | Z15: 1 | AA15: Saud Alati | AB15: https://x.com/Exnid_ | AD15: https://www.twitch.tv/exnid | AK15: 28/10/2002 | AL15: Sub-Machine Gun (SMG) | AT15: =IFERROR(IF(AND(AN15>0,J15>0),ROUND(J15*1000/(AN15*0.2),0),""),"") | AU15: =IFERROR(IF(AND(AQ15>0,M15>0),ROUND(M15*1000/(AQ15*0.3),0),""),"") | AV15: =IFERROR(IF(AND(AM15>0,O15>0),ROUND(O15*1000/(AM15*0.1),0),""),"") | AW15: =IFERROR(IF(AND(AP15>0,N15>0),ROUND(N15*1000/(AP15*0.25),0),""),"") | AX15: =IFERROR(IF(AND(AO15>0,Q15>0),ROUND(Q15*1000/(AO15*1),0),""),"") | AY15: =IFERROR(ifs(I15="Tier S",0.65,I15="Tier 1",0.55,I15="Tier 2",0.45,I15="Tier 3",0.35,I15="Tier 4",0.25),0.35) -> 0.35 | AZ15: 1 | BA15: 1 | BB15: 1 | BC15: =IFERROR(ROUND(S15*AY15*BA15*BB15*AZ15,0),0) -> 8470 | BD15: =IF(COUNT(AM15,AN15,AO15,AP15,AQ15,AR15,AS15)>0,"estimated","pending") -> pending
B16: =IF($C16="","",COUNTA($C$6:C16)) -> 11 | C16: KiSMET | D16: Player | E16: Call of Duty Black Ops 7 | F16: Riyadh Falcons | G16: American | H16: 3 | I16: Tier 2 | J16: 12100 | K16: 5100 | L16: =IF(J16="","",ROUND(J16*0.17,0)) -> 2057 | M16: 9450 | N16: 3850 | O16: 2400 | P16: 2400 | Q16: 17550 | R16: 7850 | S16: =IF(J16="","",ROUND(J16*2.2,0)) -> 26620 | T16: 4250 | U16: 3650 | V16: 2200 | W16: 2400 | X16: 3 platforms | Y16: 0.3 | Z16: 1 | AA16: Matthew Tinsley | AB16: https://twitter.com/KiSMET6_ | AC16: https://www.instagram.com/kismet6_ | AD16: https://www.twitch.tv/kismet6_ | AK16: 1999-11-11 00:00:00 | AL16: Assault Rifle / Flex | AT16: =IFERROR(IF(AND(AN16>0,J16>0),ROUND(J16*1000/(AN16*0.2),0),""),"") | AU16: =IFERROR(IF(AND(AQ16>0,M16>0),ROUND(M16*1000/(AQ16*0.3),0),""),"") | AV16: =IFERROR(IF(AND(AM16>0,O16>0),ROUND(O16*1000/(AM16*0.1),0),""),"") | AW16: =IFERROR(IF(AND(AP16>0,N16>0),ROUND(N16*1000/(AP16*0.25),0),""),"") | AX16: =IFERROR(IF(AND(AO16>0,Q16>0),ROUND(Q16*1000/(AO16*1),0),""),"") | AY16: =IFERROR(ifs(I16="Tier S",0.65,I16="Tier 1",0.55,I16="Tier 2",0.45,I16="Tier 3",0.35,I16="Tier 4",0.25),0.35) -> 0.35 | AZ16: 1 | BA16: 1 | BB16: 1 | BC16: =IFERROR(ROUND(S16*AY16*BA16*BB16*AZ16,0),0) -> 9317 | BD16: =IF(COUNT(AM16,AN16,AO16,AP16,AQ16,AR16,AS16)>0,"estimated","pending") -> pending
B17: =IF($C17="","",COUNTA($C$6:C17)) -> 12 | C17: Pred | D17: Player | E17: Call of Duty Black Ops 7 | F17: Riyadh Falcons | G17: American | H17: 3 | I17: Tier 2 | J17: 11000 | K17: 4600 | L17: =IF(J17="","",ROUND(J17*0.17,0)) -> 1870 | M17: 8600 | N17: 3500 | O17: 2200 | P17: 2200 | Q17: 15950 | R17: 7150 | S17: =IF(J17="","",ROUND(J17*2.2,0)) -> 24200 | T17: 3850 | U17: 3300 | V17: 2000 | W17: 2400 | X17: 3 platforms | Y17: 0.3 | Z17: 1 | AA17: Amer Zulbeari | AB17: https://x.com/Pred | AC17: https://www.instagram.com/amerzulbeariii | AD17: https://www.twitch.tv/pred | AK17: 19/08/2001 | AL17: Sub-Machine Gun (SMG) | AT17: =IFERROR(IF(AND(AN17>0,J17>0),ROUND(J17*1000/(AN17*0.2),0),""),"") | AU17: =IFERROR(IF(AND(AQ17>0,M17>0),ROUND(M17*1000/(AQ17*0.3),0),""),"") | AV17: =IFERROR(IF(AND(AM17>0,O17>0),ROUND(O17*1000/(AM17*0.1),0),""),"") | AW17: =IFERROR(IF(AND(AP17>0,N17>0),ROUND(N17*1000/(AP17*0.25),0),""),"") | AX17: =IFERROR(IF(AND(AO17>0,Q17>0),ROUND(Q17*1000/(AO17*1),0),""),"") | AY17: =IFERROR(ifs(I17="Tier S",0.65,I17="Tier 1",0.55,I17="Tier 2",0.45,I17="Tier 3",0.35,I17="Tier 4",0.25),0.35) -> 0.35 | AZ17: 1 | BA17: 1 | BB17: 1 | BC17: =IFERROR(ROUND(S17*AY17*BA17*BB17*AZ17,0),0) -> 8470 | BD17: =IF(COUNT(AM17,AN17,AO17,AP17,AQ17,AR17,AS17)>0,"estimated","pending") -> pending
B18: =IF($C18="","",COUNTA($C$6:C18)) -> 13 | C18: KingAbody | D18: Player | E18: Call of Duty Black Ops 7 | F18: FaZe Falcons | G18: Saudi Arabia | H18: 1 | I18: Tier 2 | J18: 11000 | K18: 4600 | L18: =IF(J18="","",ROUND(J18*0.17,0)) -> 1870 | M18: 8600 | N18: 3500 | O18: 2200 | P18: 2200 | Q18: 15950 | R18: 7150 | S18: =IF(J18="","",ROUND(J18*2.2,0)) -> 24200 | T18: 3850 | U18: 3300 | V18: 2000 | W18: 2400 | X18: 1 platform | Y18: 0.3 | Z18: 1 | AA18: Abdulelah Alrajhi | AB18: https://x.com/KingAbody_ | AK18: 2000-06-02 00:00:00 | AL18: Sub-Machine Gun (SMG) | AT18: =IFERROR(IF(AND(AN18>0,J18>0),ROUND(J18*1000/(AN18*0.2),0),""),"") | AU18: =IFERROR(IF(AND(AQ18>0,M18>0),ROUND(M18*1000/(AQ18*0.3),0),""),"") | AV18: =IFERROR(IF(AND(AM18>0,O18>0),ROUND(O18*1000/(AM18*0.1),0),""),"") | AW18: =IFERROR(IF(AND(AP18>0,N18>0),ROUND(N18*1000/(AP18*0.25),0),""),"") | AX18: =IFERROR(IF(AND(AO18>0,Q18>0),ROUND(Q18*1000/(AO18*1),0),""),"") | AY18: =IFERROR(ifs(I18="Tier S",0.65,I18="Tier 1",0.55,I18="Tier 2",0.45,I18="Tier 3",0.35,I18="Tier 4",0.25),0.35) -> 0.35 | AZ18: 1 | BA18: 1 | BB18: 1 | BC18: =IFERROR(ROUND(S18*AY18*BA18*BB18*AZ18,0),0) -> 8470 | BD18: =IF(COUNT(AM18,AN18,AO18,AP18,AQ18,AR18,AS18)>0,"estimated","pending") -> pending
B19: =IF($C19="","",COUNTA($C$6:C19)) -> 14 | C19: Arcitys | D19: Player | E19: Call of Duty Black Ops 7 | F19: Falcons Academy White | G19: American | H19: 3 | I19: Tier 2 | J19: 12100 | K19: 5100 | L19: =IF(J19="","",ROUND(J19*0.17,0)) -> 2057 | M19: 9450 | N19: 3850 | O19: 2400 | P19: 2400 | Q19: 17550 | R19: 7850 | S19: =IF(J19="","",ROUND(J19*2.2,0)) -> 26620 | T19: 4250 | U19: 3650 | V19: 2200 | W19: 2400 | X19: 3 platforms | Y19: 0.3 | Z19: 1 | AA19: Alec Sanderson | AB19: https://x.com/Arcitys | AC19: https://www.instagram.com/arcitys9 | AD19: https://www.twitch.tv/arcitys | AK19: 1998-09-07 00:00:00 | AL19: Assault Rifle / Main AR | AT19: =IFERROR(IF(AND(AN19>0,J19>0),ROUND(J19*1000/(AN19*0.2),0),""),"") | AU19: =IFERROR(IF(AND(AQ19>0,M19>0),ROUND(M19*1000/(AQ19*0.3),0),""),"") | AV19: =IFERROR(IF(AND(AM19>0,O19>0),ROUND(O19*1000/(AM19*0.1),0),""),"") | AW19: =IFERROR(IF(AND(AP19>0,N19>0),ROUND(N19*1000/(AP19*0.25),0),""),"") | AX19: =IFERROR(IF(AND(AO19>0,Q19>0),ROUND(Q19*1000/(AO19*1),0),""),"") | AY19: =IFERROR(ifs(I19="Tier S",0.65,I19="Tier 1",0.55,I19="Tier 2",0.45,I19="Tier 3",0.35,I19="Tier 4",0.25),0.35) -> 0.35 | AZ19: 1 | BA19: 1 | BB19: 1 | BC19: =IFERROR(ROUND(S19*AY19*BA19*BB19*AZ19,0),0) -> 9317 | BD19: =IF(COUNT(AM19,AN19,AO19,AP19,AQ19,AR19,AS19)>0,"estimated","pending") -> pending
B20: =IF($C20="","",COUNTA($C$6:C20)) -> 15 | C20: Paulehx | D20: Player | E20: Call of Duty Black Ops 7 | F20: Falcons Academy White | G20: American | H20: 2 | I20: Tier 2 | J20: 11000 | K20: 4600 | L20: =IF(J20="","",ROUND(J20*0.17,0)) -> 1870 | M20: 8600 | N20: 3500 | O20: 2200 | P20: 2200 | Q20: 15950 | R20: 7150 | S20: =IF(J20="","",ROUND(J20*2.2,0)) -> 24200 | T20: 3850 | U20: 3300 | V20: 2000 | W20: 2400 | X20: 2 platforms | Y20: 0.3 | Z20: 1 | AA20: Paul Avila | AB20: https://x.com/Paulehx_ | AD20: https://www.twitch.tv/paulehx | AK20: 21/01/2002 | AL20: Assault Rifle / Flex | AT20: =IFERROR(IF(AND(AN20>0,J20>0),ROUND(J20*1000/(AN20*0.2),0),""),"") | AU20: =IFERROR(IF(AND(AQ20>0,M20>0),ROUND(M20*1000/(AQ20*0.3),0),""),"") | AV20: =IFERROR(IF(AND(AM20>0,O20>0),ROUND(O20*1000/(AM20*0.1),0),""),"") | AW20: =IFERROR(IF(AND(AP20>0,N20>0),ROUND(N20*1000/(AP20*0.25),0),""),"") | AX20: =IFERROR(IF(AND(AO20>0,Q20>0),ROUND(Q20*1000/(AO20*1),0),""),"") | AY20: =IFERROR(ifs(I20="Tier S",0.65,I20="Tier 1",0.55,I20="Tier 2",0.45,I20="Tier 3",0.35,I20="Tier 4",0.25),0.35) -> 0.35 | AZ20: 1 | BA20: 1 | BB20: 1 | BC20: =IFERROR(ROUND(S20*AY20*BA20*BB20*AZ20,0),0) -> 8470 | BD20: =IF(COUNT(AM20,AN20,AO20,AP20,AQ20,AR20,AS20)>0,"estimated","pending") -> pending
B21: =IF($C21="","",COUNTA($C$6:C21)) -> 16 | C21: hmoodx | D21: Player | E21: Call of Duty Warzone | F21: Team Falcons MENA | G21: Saudi Arabia | H21: 2 | I21: Tier 2 | J21: 11000 | K21: 4600 | L21: =IF(J21="","",ROUND(J21*0.17,0)) -> 1870 | M21: 8600 | N21: 3500 | O21: 2200 | P21: 2200 | Q21: 15950 | R21: 7150 | S21: =IF(J21="","",ROUND(J21*2.2,0)) -> 24200 | T21: 3850 | U21: 3300 | V21: 2000 | W21: 2400 | X21: 2 platforms | Y21: 0.3 | Z21: 1 | AA21: Mohammed Altowairqi | AB21: https://x.com/xihamoodx | AD21: https://www.twitch.tv/i_hmoodx | AT21: =IFERROR(IF(AND(AN21>0,J21>0),ROUND(J21*1000/(AN21*0.2),0),""),"") | AU21: =IFERROR(IF(AND(AQ21>0,M21>0),ROUND(M21*1000/(AQ21*0.3),0),""),"") | AV21: =IFERROR(IF(AND(AM21>0,O21>0),ROUND(O21*1000/(AM21*0.1),0),""),"") | AW21: =IFERROR(IF(AND(AP21>0,N21>0),ROUND(N21*1000/(AP21*0.25),0),""),"") | AX21: =IFERROR(IF(AND(AO21>0,Q21>0),ROUND(Q21*1000/(AO21*1),0),""),"") | AY21: =IFERROR(ifs(I21="Tier S",0.65,I21="Tier 1",0.55,I21="Tier 2",0.45,I21="Tier 3",0.35,I21="Tier 4",0.25),0.35) -> 0.35 | AZ21: 1 | BA21: 1 | BB21: 1 | BC21: =IFERROR(ROUND(S21*AY21*BA21*BB21*AZ21,0),0) -> 8470 | BD21: =IF(COUNT(AM21,AN21,AO21,AP21,AQ21,AR21,AS21)>0,"estimated","pending") -> pending
B22: =IF($C22="","",COUNTA($C$6:C22)) -> 17 | C22: xizx7 | D22: Player | E22: Call of Duty Warzone | F22: Team Falcons MENA | G22: Saudi Arabia | H22: 4 | I22: Tier 1 | J22: 12100 | K22: 5100 | L22: =IF(J22="","",ROUND(J22*0.17,0)) -> 2057 | M22: 9450 | N22: 3850 | O22: 2400 | P22: 2400 | Q22: 17550 | R22: 7850 | S22: =IF(J22="","",ROUND(J22*2.2,0)) -> 26620 | T22: 4250 | U22: 3650 | V22: 2200 | W22: 2400 | X22: 4 platforms | Y22: 0.3 | Z22: 1 | AA22: Jawad Al-Thawab | AB22: https://x.com/Jawxd7 | AC22: https://www.instagram.com/Jawxd7 | AD22: https://www.twitch.tv/jawad | AE22: https://www.youtube.com/channel/UCUWL8dR-JyA4FXZ08aSjjcg/videos | AT22: =IFERROR(IF(AND(AN22>0,J22>0),ROUND(J22*1000/(AN22*0.2),0),""),"") | AU22: =IFERROR(IF(AND(AQ22>0,M22>0),ROUND(M22*1000/(AQ22*0.3),0),""),"") | AV22: =IFERROR(IF(AND(AM22>0,O22>0),ROUND(O22*1000/(AM22*0.1),0),""),"") | AW22: =IFERROR(IF(AND(AP22>0,N22>0),ROUND(N22*1000/(AP22*0.25),0),""),"") | AX22: =IFERROR(IF(AND(AO22>0,Q22>0),ROUND(Q22*1000/(AO22*1),0),""),"") | AY22: =IFERROR(ifs(I22="Tier S",0.65,I22="Tier 1",0.55,I22="Tier 2",0.45,I22="Tier 3",0.35,I22="Tier 4",0.25),0.35) -> 0.35 | AZ22: 1 | BA22: 1 | BB22: 1 | BC22: =IFERROR(ROUND(S22*AY22*BA22*BB22*AZ22,0),0) -> 9317 | BD22: =IF(COUNT(AM22,AN22,AO22,AP22,AQ22,AR22,AS22)>0,"estimated","pending") -> pending
B23: =IF($C23="","",COUNTA($C$6:C23)) -> 18 | C23: Alpine | D23: Manager | E23: Call of Duty Warzone | F23: Team Falcons | G23: American | H23: 1 | I23: Tier 3 | J23: 22750 | K23: 9550 | L23: =IF(J23="","",ROUND(J23*0.17,0)) -> 3868 | M23: 17750 | N23: 7300 | O23: 4550 | P23: 0 | Q23: 33000 | R23: 14800 | S23: =IF(J23="","",ROUND(J23*2.2,0)) -> 50050 | T23: 7950 | U23: 6850 | V23: 4100 | W23: 0 | X23: 1 platform | Y23: 0.3 | Z23: 1 | AA23: Alejandro Ayala | AB23: https://x.com/alpinedadog?lang=en | AK23: 24/02/1997 | AT23: =IFERROR(IF(AND(AN23>0,J23>0),ROUND(J23*1000/(AN23*0.2),0),""),"") | AU23: =IFERROR(IF(AND(AQ23>0,M23>0),ROUND(M23*1000/(AQ23*0.3),0),""),"") | AV23: =IFERROR(IF(AND(AM23>0,O23>0),ROUND(O23*1000/(AM23*0.1),0),""),"") | AW23: =IFERROR(IF(AND(AP23>0,N23>0),ROUND(N23*1000/(AP23*0.25),0),""),"") | AX23: =IFERROR(IF(AND(AO23>0,Q23>0),ROUND(Q23*1000/(AO23*1),0),""),"") | AY23: =IFERROR(ifs(I23="Tier S",0.65,I23="Tier 1",0.55,I23="Tier 2",0.45,I23="Tier 3",0.35,I23="Tier 4",0.25),0.35) -> 0.35 | AZ23: 1 | BA23: 1 | BB23: 1 | BC23: =IFERROR(ROUND(S23*AY23*BA23*BB23*AZ23,0),0) -> 17518 | BD23: =IF(COUNT(AM23,AN23,AO23,AP23,AQ23,AR23,AS23)>0,"estimated","pending") -> pending
B24: =IF($C24="","",COUNTA($C$6:C24)) -> 19 | C24: Newbz | D24: Player | E24: Call of Duty Warzone | F24: Team Falcons | G24: American | H24: 2 | I24: Tier 3 | J24: 20700 | K24: 8700 | L24: =IF(J24="","",ROUND(J24*0.17,0)) -> 3519 | M24: 16150 | N24: 6600 | O24: 4150 | P24: 4150 | Q24: 30000 | R24: 13450 | S24: =IF(J24="","",ROUND(J24*2.2,0)) -> 45540 | T24: 7250 | U24: 6200 | V24: 3750 | W24: 2400 | X24: 2 platforms | Y24: 0.2 | Z24: 1 | AA24: Edy Juan | AB24: https://x.com/TBE_Newbzz | AD24: https://www.twitch.tv/newbz | AK24: 2000-01-02 00:00:00 | AT24: =IFERROR(IF(AND(AN24>0,J24>0),ROUND(J24*1000/(AN24*0.2),0),""),"") | AU24: =IFERROR(IF(AND(AQ24>0,M24>0),ROUND(M24*1000/(AQ24*0.3),0),""),"") | AV24: =IFERROR(IF(AND(AM24>0,O24>0),ROUND(O24*1000/(AM24*0.1),0),""),"") | AW24: =IFERROR(IF(AND(AP24>0,N24>0),ROUND(N24*1000/(AP24*0.25),0),""),"") | AX24: =IFERROR(IF(AND(AO24>0,Q24>0),ROUND(Q24*1000/(AO24*1),0),""),"") | AY24: =IFERROR(ifs(I24="Tier S",0.65,I24="Tier 1",0.55,I24="Tier 2",0.45,I24="Tier 3",0.35,I24="Tier 4",0.25),0.35) -> 0.35 | AZ24: 1 | BA24: 1 | BB24: 1 | BC24: =IFERROR(ROUND(S24*AY24*BA24*BB24*AZ24,0),0) -> 15939 | BD24: =IF(COUNT(AM24,AN24,AO24,AP24,AQ24,AR24,AS24)>0,"estimated","pending") -> pending
B25: =IF($C25="","",COUNTA($C$6:C25)) -> 20 | C25: Dongy | D25: Player | E25: Call of Duty Warzone | F25: Team Falcons | G25: American | H25: 2 | I25: Tier 3 | J25: 6500 | K25: 2750 | L25: =IF(J25="","",ROUND(J25*0.17,0)) -> 1105 | M25: 5050 | N25: 2100 | O25: 1300 | P25: 1300 | Q25: 9400 | R25: 4200 | S25: =IF(J25="","",ROUND(J25*2.2,0)) -> 14300 | T25: 2300 | U25: 1950 | V25: 1150 | W25: 2400 | X25: 2 platforms | Y25: 0.2 | Z25: 1 | AA25: Christopher Ledbetter | AB25: https://x.com/zDongyy | AD25: https://www.twitch.tv/Dongy | AK25: 23/03/2004 | AT25: =IFERROR(IF(AND(AN25>0,J25>0),ROUND(J25*1000/(AN25*0.2),0),""),"") | AU25: =IFERROR(IF(AND(AQ25>0,M25>0),ROUND(M25*1000/(AQ25*0.3),0),""),"") | AV25: =IFERROR(IF(AND(AM25>0,O25>0),ROUND(O25*1000/(AM25*0.1),0),""),"") | AW25: =IFERROR(IF(AND(AP25>0,N25>0),ROUND(N25*1000/(AP25*0.25),0),""),"") | AX25: =IFERROR(IF(AND(AO25>0,Q25>0),ROUND(Q25*1000/(AO25*1),0),""),"") | AY25: =IFERROR(ifs(I25="Tier S",0.65,I25="Tier 1",0.55,I25="Tier 2",0.45,I25="Tier 3",0.35,I25="Tier 4",0.25),0.35) -> 0.35 | AZ25: 1 | BA25: 1 | BB25: 1 | BC25: =IFERROR(ROUND(S25*AY25*BA25*BB25*AZ25,0),0) -> 5005 | BD25: =IF(COUNT(AM25,AN25,AO25,AP25,AQ25,AR25,AS25)>0,"estimated","pending") -> pending
B26: =IF($C26="","",COUNTA($C$6:C26)) -> 21 | C26: Soka | D26: Player | E26: Call of Duty Warzone | F26: Team Falcons | G26: Tongan | H26: 5 | I26: Tier 1 | J26: 6500 | K26: 2750 | L26: =IF(J26="","",ROUND(J26*0.17,0)) -> 1105 | M26: 5050 | N26: 2100 | O26: 1300 | P26: 1300 | Q26: 9400 | R26: 4200 | S26: =IF(J26="","",ROUND(J26*2.2,0)) -> 14300 | T26: 2300 | U26: 1950 | V26: 1150 | W26: 2400 | X26: 5 platforms | Y26: 0.2 | Z26: 1 | AA26: Kasimili Tonga Tongamoa | AB26: https://twitter.com/HisokaT42 | AC26: https://www.instagram.com/hisokat42 | AD26: https://www.twitch.tv/HisokaT42 | AE26: https://www.youtube.com/channel/UCQDRE8aZRsrvF5OwMk_KmBg | AF26: https://tiktok.com/@missionarysoka | AK26: 28/01/2002 | AT26: =IFERROR(IF(AND(AN26>0,J26>0),ROUND(J26*1000/(AN26*0.2),0),""),"") | AU26: =IFERROR(IF(AND(AQ26>0,M26>0),ROUND(M26*1000/(AQ26*0.3),0),""),"") | AV26: =IFERROR(IF(AND(AM26>0,O26>0),ROUND(O26*1000/(AM26*0.1),0),""),"") | AW26: =IFERROR(IF(AND(AP26>0,N26>0),ROUND(N26*1000/(AP26*0.25),0),""),"") | AX26: =IFERROR(IF(AND(AO26>0,Q26>0),ROUND(Q26*1000/(AO26*1),0),""),"") | AY26: =IFERROR(ifs(I26="Tier S",0.65,I26="Tier 1",0.55,I26="Tier 2",0.45,I26="Tier 3",0.35,I26="Tier 4",0.25),0.35) -> 0.35 | AZ26: 1 | BA26: 1 | BB26: 1 | BC26: =IFERROR(ROUND(S26*AY26*BA26*BB26*AZ26,0),0) -> 5005 | BD26: =IF(COUNT(AM26,AN26,AO26,AP26,AQ26,AR26,AS26)>0,"estimated","pending") -> pending
B27: =IF($C27="","",COUNTA($C$6:C27)) -> 22 | C27: Alireza Firouzja | D27: Player | E27: Chess | F27: Chess | G27: French/Iranian | H27: 5 | I27: Tier 1 | J27: 20700 | K27: 8700 | L27: =IF(J27="","",ROUND(J27*0.17,0)) -> 3519 | M27: 16150 | N27: 6600 | O27: 4150 | P27: 4150 | Q27: 30000 | R27: 13450 | S27: =IF(J27="","",ROUND(J27*2.2,0)) -> 45540 | T27: 7250 | U27: 6200 | V27: 3750 | W27: 2400 | X27: 5 platforms | Y27: 0.5 | Z27: 1 | AA27: Alireza Firouzja | AB27: https://twitter.com/AlirezaFirouzja | AC27: https://www.instagram.com/alirezafirouzja | AD27: https://www.twitch.tv/alirezafirouzja | AE27: https://www.youtube.com/@alirezafirouzja4080 | AH27: https://www.facebook.com/login/?next=https%3A%2F%2Fwww.facebook.com%2FAlireza.Firouzja.chess%2F | AK27: 18/06/2003 | AT27: =IFERROR(IF(AND(AN27>0,J27>0),ROUND(J27*1000/(AN27*0.2),0),""),"") | AU27: =IFERROR(IF(AND(AQ27>0,M27>0),ROUND(M27*1000/(AQ27*0.3),0),""),"") | AV27: =IFERROR(IF(AND(AM27>0,O27>0),ROUND(O27*1000/(AM27*0.1),0),""),"") | AW27: =IFERROR(IF(AND(AP27>0,N27>0),ROUND(N27*1000/(AP27*0.25),0),""),"") | AX27: =IFERROR(IF(AND(AO27>0,Q27>0),ROUND(Q27*1000/(AO27*1),0),""),"") | AY27: =IFERROR(ifs(I27="Tier S",0.65,I27="Tier 1",0.55,I27="Tier 2",0.45,I27="Tier 3",0.35,I27="Tier 4",0.25),0.35) -> 0.35 | AZ27: 1 | BA27: 1 | BB27: 1 | BC27: =IFERROR(ROUND(S27*AY27*BA27*BB27*AZ27,0),0) -> 15939 | BD27: =IF(COUNT(AM27,AN27,AO27,AP27,AQ27,AR27,AS27)>0,"estimated","pending") -> pending
B28: =IF($C28="","",COUNTA($C$6:C28)) -> 23 | C28: Hikaru Nakamura | D28: Player | E28: Chess | F28: Chess | G28: American | H28: 6 | I28: Tier 1 | J28: 22500 | K28: 9450 | L28: =IF(J28="","",ROUND(J28*0.17,0)) -> 3825 | M28: 17550 | N28: 7200 | O28: 4500 | P28: 4500 | Q28: 32600 | R28: 14600 | S28: =IF(J28="","",ROUND(J28*2.2,0)) -> 49500 | T28: 7850 | U28: 6750 | V28: 4050 | W28: 2400 | X28: 6 platforms | Y28: 0.5 | Z28: 1 | AA28: Hikaru Nakamura | AB28: https://twitter.com/GMHikaru | AC28: https://www.instagram.com/gmhikaru | AD28: https://www.twitch.tv/gmhikaru | AE28: https://www.youtube.com/@gmhikaru | AG28: https://kick.com/gmhikaru | AH28: https://www.facebook.com/login/?next=https%3A%2F%2Fwww.facebook.com%2FGMHikaru%2F | AK28: 1987-12-09 00:00:00 | AT28: =IFERROR(IF(AND(AN28>0,J28>0),ROUND(J28*1000/(AN28*0.2),0),""),"") | AU28: =IFERROR(IF(AND(AQ28>0,M28>0),ROUND(M28*1000/(AQ28*0.3),0),""),"") | AV28: =IFERROR(IF(AND(AM28>0,O28>0),ROUND(O28*1000/(AM28*0.1),0),""),"") | AW28: =IFERROR(IF(AND(AP28>0,N28>0),ROUND(N28*1000/(AP28*0.25),0),""),"") | AX28: =IFERROR(IF(AND(AO28>0,Q28>0),ROUND(Q28*1000/(AO28*1),0),""),"") | AY28: =IFERROR(ifs(I28="Tier S",0.65,I28="Tier 1",0.55,I28="Tier 2",0.45,I28="Tier 3",0.35,I28="Tier 4",0.25),0.35) -> 0.35 | AZ28: 1 | BA28: 1 | BB28: 1 | BC28: =IFERROR(ROUND(S28*AY28*BA28*BB28*AZ28,0),0) -> 17325 | BD28: =IF(COUNT(AM28,AN28,AO28,AP28,AQ28,AR28,AS28)>0,"estimated","pending") -> pending
B29: =IF($C29="","",COUNTA($C$6:C29)) -> 24 | C29: Jon Ellis | D29: Manager | E29: Chess | F29: Chess | H29: 0 | I29: Tier 3 | J29: 22500 | K29: 9450 | L29: =IF(J29="","",ROUND(J29*0.17,0)) -> 3825 | M29: 17550 | N29: 7200 | O29: 4500 | P29: 0 | Q29: 32600 | R29: 14600 | S29: =IF(J29="","",ROUND(J29*2.2,0)) -> 49500 | T29: 7850 | U29: 6750 | V29: 4050 | W29: 0 | X29: 0 platforms | Y29: 0.3 | Z29: 1 | AA29: Jonathan Ellis | AT29: =IFERROR(IF(AND(AN29>0,J29>0),ROUND(J29*1000/(AN29*0.2),0),""),"") | AU29: =IFERROR(IF(AND(AQ29>0,M29>0),ROUND(M29*1000/(AQ29*0.3),0),""),"") | AV29: =IFERROR(IF(AND(AM29>0,O29>0),ROUND(O29*1000/(AM29*0.1),0),""),"") | AW29: =IFERROR(IF(AND(AP29>0,N29>0),ROUND(N29*1000/(AP29*0.25),0),""),"") | AX29: =IFERROR(IF(AND(AO29>0,Q29>0),ROUND(Q29*1000/(AO29*1),0),""),"") | AY29: =IFERROR(ifs(I29="Tier S",0.65,I29="Tier 1",0.55,I29="Tier 2",0.45,I29="Tier 3",0.35,I29="Tier 4",0.25),0.35) -> 0.35 | AZ29: 1 | BA29: 1 | BB29: 1 | BC29: =IFERROR(ROUND(S29*AY29*BA29*BB29*AZ29,0),0) -> 17325 | BD29: =IF(COUNT(AM29,AN29,AO29,AP29,AQ29,AR29,AS29)>0,"estimated","pending") -> pending
B30: =IF($C30="","",COUNTA($C$6:C30)) -> 25 | C30: kyousuke | D30: Player | E30: Counterstrike2 | F30: Team Falcons | G30: Russian | H30: 3 | I30: Tier 1 | J30: 15000 | K30: 6750 | L30: =IF(J30="","",ROUND(J30*0.17,0)) -> 2550 | M30: 11000 | N30: 5000 | O30: 3200 | P30: 3200 | Q30: 19500 | R30: 8775 | S30: =IF(J30="","",ROUND(J30*2.2,0)) -> 33000 | T30: 6800 | U30: 5950 | V30: 3570 | W30: 2400 | X30: 3 platforms | Y30: 0.75 | Z30: 1 | AA30: Maxim Lukin | AB30: https://twitter.com/FLCkyousuke | AC30: https://www.instagram.com/flckyousuke | AD30: https://www.twitch.tv/kyousuke999 | AK30: 30/01/2008 | AL30: Rifler | AT30: =IFERROR(IF(AND(AN30>0,J30>0),ROUND(J30*1000/(AN30*0.2),0),""),"") | AU30: =IFERROR(IF(AND(AQ30>0,M30>0),ROUND(M30*1000/(AQ30*0.3),0),""),"") | AV30: =IFERROR(IF(AND(AM30>0,O30>0),ROUND(O30*1000/(AM30*0.1),0),""),"") | AW30: =IFERROR(IF(AND(AP30>0,N30>0),ROUND(N30*1000/(AP30*0.25),0),""),"") | AX30: =IFERROR(IF(AND(AO30>0,Q30>0),ROUND(Q30*1000/(AO30*1),0),""),"") | AY30: =IFERROR(ifs(I30="Tier S",0.65,I30="Tier 1",0.55,I30="Tier 2",0.45,I30="Tier 3",0.35,I30="Tier 4",0.25),0.35) -> 0.35 | AZ30: 1 | BA30: 1 | BB30: 1 | BC30: =IFERROR(ROUND(S30*AY30*BA30*BB30*AZ30,0),0) -> 11550 | BD30: =IF(COUNT(AM30,AN30,AO30,AP30,AQ30,AR30,AS30)>0,"estimated","pending") -> pending
B31: =IF($C31="","",COUNTA($C$6:C31)) -> 26 | C31: kyxsan | D31: Player | E31: Counterstrike2 | F31: Team Falcons | G31: North Macedonia | H31: 2 | I31: Tier 1 | J31: 22500 | K31: 9450 | L31: =IF(J31="","",ROUND(J31*0.17,0)) -> 3825 | M31: 17550 | N31: 7200 | O31: 4500 | P31: 4500 | Q31: 32600 | R31: 14600 | S31: =IF(J31="","",ROUND(J31*2.2,0)) -> 49500 | T31: 7850 | U31: 6750 | V31: 4050 | W31: 2400 | X31: 2 platforms | Y31: 0.75 | Z31: 1 | AA31: Damjan Stoilkovski | AB31: https://x.com/kyxsancs | AC31: https://www.instagram.com/kyxsancs/ | AK31: 26/05/2000 | AL31: IGL | AT31: =IFERROR(IF(AND(AN31>0,J31>0),ROUND(J31*1000/(AN31*0.2),0),""),"") | AU31: =IFERROR(IF(AND(AQ31>0,M31>0),ROUND(M31*1000/(AQ31*0.3),0),""),"") | AV31: =IFERROR(IF(AND(AM31>0,O31>0),ROUND(O31*1000/(AM31*0.1),0),""),"") | AW31: =IFERROR(IF(AND(AP31>0,N31>0),ROUND(N31*1000/(AP31*0.25),0),""),"") | AX31: =IFERROR(IF(AND(AO31>0,Q31>0),ROUND(Q31*1000/(AO31*1),0),""),"") | AY31: =IFERROR(ifs(I31="Tier S",0.65,I31="Tier 1",0.55,I31="Tier 2",0.45,I31="Tier 3",0.35,I31="Tier 4",0.25),0.35) -> 0.35 | AZ31: 1 | BA31: 1 | BB31: 1 | BC31: =IFERROR(ROUND(S31*AY31*BA31*BB31*AZ31,0),0) -> 17325 | BD31: =IF(COUNT(AM31,AN31,AO31,AP31,AQ31,AR31,AS31)>0,"estimated","pending") -> pending
B32: =IF($C32="","",COUNTA($C$6:C32)) -> 27 | C32: m0NESY | D32: Player | E32: Counterstrike2 | F32: Team Falcons | G32: Russian | H32: 4 | I32: Tier 1 | J32: 22500 | K32: 9450 | L32: =IF(J32="","",ROUND(J32*0.17,0)) -> 3825 | M32: 17550 | N32: 7200 | O32: 4500 | P32: 4500 | Q32: 32600 | R32: 14600 | S32: =IF(J32="","",ROUND(J32*2.2,0)) -> 49500 | T32: 7850 | U32: 6750 | V32: 4050 | W32: 2400 | X32: 4 platforms | Y32: 0.2 | Z32: 1 | AA32: Ilya Osipov | AB32: https://x.com/FLCm0NESY | AC32: https://www.instagram.com/m0nesy13 | AD32: https://www.twitch.tv/m0nesyof | AE32: https://www.youtube.com/channel/UCJxjKA1Cl--4tCN1l_cHHvQ | AK32: 2005-01-05 00:00:00 | AL32: Awper | AT32: =IFERROR(IF(AND(AN32>0,J32>0),ROUND(J32*1000/(AN32*0.2),0),""),"") | AU32: =IFERROR(IF(AND(AQ32>0,M32>0),ROUND(M32*1000/(AQ32*0.3),0),""),"") | AV32: =IFERROR(IF(AND(AM32>0,O32>0),ROUND(O32*1000/(AM32*0.1),0),""),"") | AW32: =IFERROR(IF(AND(AP32>0,N32>0),ROUND(N32*1000/(AP32*0.25),0),""),"") | AX32: =IFERROR(IF(AND(AO32>0,Q32>0),ROUND(Q32*1000/(AO32*1),0),""),"") | AY32: =IFERROR(ifs(I32="Tier S",0.65,I32="Tier 1",0.55,I32="Tier 2",0.45,I32="Tier 3",0.35,I32="Tier 4",0.25),0.35) -> 0.35 | AZ32: 1 | BA32: 1 | BB32: 1 | BC32: =IFERROR(ROUND(S32*AY32*BA32*BB32*AZ32,0),0) -> 17325 | BD32: =IF(COUNT(AM32,AN32,AO32,AP32,AQ32,AR32,AS32)>0,"estimated","pending") -> pending
