Workbook

Sheet 00_Cover
B3: TEAM FALCONS
B4: Talent Commercial Rate Card · 2026
B5: Global Esports Pricing & Monetization Framework
B6: Updated: 14 April, 2026 · Currency: SAR · 1 USD = 3.75 SAR
B7: ="Total Talent: "&COUNTA('01_Player_Rate_Card'!$C$5:$C$500)+COUNTA('02_Creator_Rate_Card'!$C$5:$C$500)&" entries · "&COUNTA('01_Player_Rate_Card'!$C$5:$C$500)&" players · "&COUNTA('02_Creator_Rate_Card'!$C$5:$C$500)&" creators · Confidential — Internal Use Only" -> Total Talent: 206 entries · 189 players · 17 creators · Confidential — Internal Use Only
B10: =COUNTA('01_Player_Rate_Card'!$C$5:$C$500) -> 189 | D10: =COUNTIF('01_Player_Rate_Card'!$D$5:$D$500,"Player") -> 131 | F10: =COUNTIF('01_Player_Rate_Card'!$D$5:$D$500,"Influencer") -> 8 | H10: =COUNTA('01_Player_Rate_Card'!$C$5:$C$500)-COUNTIF('01_Player_Rate_Card'!$D$5:$D$500,"Player")-COUNTIF('01_Player_Rate_Card'!$D$5:$D$500,"Influencer") -> 50 | J10: =COUNTIF('01_Player_Rate_Card'!$I$5:$I$500,"Tier 1")&"/"&COUNTIF('01_Player_Rate_Card'!$I$5:$I$500,"Tier 2")&"/"&COUNTIF('01_Player_Rate_Card'!$I$5:$I$500,"Tier 3") -> 25/106/58
B11: Total Entries | D11: Players | F11: Esports Influencers | H11: Staff & Coaches | J11: T1 / T2 / T3
B13: SHEET NAVIGATION
B14: 01_Player_Rate_Card | D14: ="All "&COUNTA('01_Player_Rate_Card'!$C$5:$C$500)&" entries · rates per platform · filterable by role/game/team/tier" -> All 189 entries · rates per platform · filterable by role/game/team/tier
B15: 02_Creator_Rate_Card | D15: ="All "&COUNTA('02_Creator_Rate_Card'!$C$5:$C$500)&" content creators · ceiling rates" -> All 17 content creators · ceiling rates
B16: 03_Adjustment_Matrix | D16: Engagement · Audience · Seasonality · Confidence + Live Calculator
B17: 04_Add_On_Rights | D17: Rights packages with uplift % + toggle grid
B18: 05_Quote_Template | D18: KFC-style quotation template — Apps Script outputs to here
B19: 06_Quote_Log | D19: Archive of all issued quotes (auto-populated)
B20: 07_Settings | D20: Global config · VAT · USD · approvers · bank
B21: 08_Benchmarks | D21: Market benchmarks — Tier 1 / MENA / platform CPMs
B22: 09_Guide_EN | D22: Pricing methodology, formula, best practices (English)
B23: 10_Guide_AR | D23: دليل التسعير الكامل بالعربي
B24: 11_Methodology | D24: Why this pricing OS works — principles + decision flows
B26: COLOR LEGEND
B27: Tier S — Superstar | D27: 1M+ followers · Global icon · World-class anchor
B28: Tier 1 — Premium | D28: 250K–1M followers · 8%+ engagement · Established
B29: Tier 2 — Target | D29: 50K–250K followers · 5–8% engagement · Core pros
B30: Tier 3 — Emerging | D30: 10K–50K followers · High engagement · Rising stars
B31: Tier 4 — Entry / Staff | D31: Support roles · Appearance rates
B32: Coach / Head Coach | D32: Coaching staff — rates apply for appearances & content
B33: Manager | D33: Management staff — rates apply for appearances
B34: Analyst | D34: Analyst staff — rates apply for appearances
B35: Influencer | D35: Esports influencers — social-first creators
B36: Creator | D36: Content creators — ceiling-based pricing

Sheet 01_Player_Rate_Card
B2: ="TALENT RATE CARD — ALL "&COUNTA($C$5:$C$500)&" ENTRIES" -> TALENT RATE CARD — ALL 189 ENTRIES
A3: ROLE LEGEND | B3: ● Player | C3: ● Head Coach | D3: ● Coach | E3: ● Manager | F3: ● Analyst | G3: ● Influencer | H3: ● Coach
B4: # | C4: Nickname | D4: Role | E4: Game | F4: Team | G4: Nationality | H4: Platforms | I4: Tier | J4: IG Reel (SAR) | K4: IG Static (SAR) | L4: IG Story (SAR) | M4: TikTok Video | N4: YT Short (SAR) | O4: X Post (SAR) | P4: FB Post/Video (SAR) | Q4: Twitch Stream 2h | R4: Twitch Integ. | S4: IRL / Appear. | T4: Rights Fee | U4: Exclusivity Fee | V4: Rush Fee | W4: WL Fee | X4: Notes | Y4: Falcons Commission % | Z4: Markup % (on Player Cost) | AA4: Full Name | AB4: X / Twitter | AC4: Instagram | AD4: Twitch | AE4: YouTube | AF4: TikTok | AG4: Kick | AH4: Facebook | AI4: Snapchat | AJ4: Link-in-Bio | AK4: Date of Birth | AL4: Game Role
B5: =IF($C5="","",COUNTA($C$5:C5)) -> 1 | C5: Bijw | D5: Influencer | E5: Esports Influencers | F5: Esports Influencers | G5: Saudi Arabia | H5: 6 | I5: Tier 3 | J5: 11000 | K5: 4600 | L5: =IF($C5="","",ROUND($J5*0.17,0)) -> 1870 | M5: 8600 | N5: 3500 | O5: 2200 | P5: 2200 | Q5: 15950 | R5: 7150 | S5: =IF($C5="","",ROUND($J5*2.2,0)) -> 24200 | T5: 3850 | U5: 3300 | V5: 2000 | W5: 1650 | X5: 6 platforms | Y5: 0.3 | Z5: 1 | AA5: Hisham Nasser | AB5: https://x.com/_bijw | AC5: https://www.instagram.com/bijjw | AD5: https://www.twitch.tv/bijw | AE5: https://www.youtube.com/@Bijw | AF5: https://www.tiktok.com/@biijw | AG5: https://kick.com/bijw | AI5: https://www.snapchat.com/add/bijjw | AJ5: https://linktr.ee/bijw
B6: =IF($C6="","",COUNTA($C$5:C6)) -> 2 | C6: Abo Najd | D6: Influencer | E6: Esports Influencers | F6: Esports Influencers | G6: Saudi Arabia | H6: 4 | I6: Tier 3 | J6: 8100 | K6: 3200 | L6: =IF($C6="","",ROUND($J6*0.17,0)) -> 1377 | M6: 6350 | N6: 2600 | O6: 1600 | P6: 1600 | Q6: 11800 | R6: 5300 | S6: =IF($C6="","",ROUND($J6*2.2,0)) -> 17820 | T6: 2850 | U6: 2450 | V6: 1450 | W6: 1215 | X6: 4 platforms | Y6: 0.3 | Z6: 1 | AA6: Riyad Alfahmi | AB6: https://x.com/K22N8 | AC6: https://www.instagram.com/k2nn8?igsh=ajJsNHoybDlpMzFo | AD6: https://www.twitch.tv/k2nnn8 | AE6: https://www.youtube.com/@k2nn8 | AJ6: https://linktr.ee/K2nnn8 (alt: https://heylink.me/k2nn8)
B7: =IF($C7="","",COUNTA($C$5:C7)) -> 3 | C7: FMG | D7: Influencer | E7: Esports Influencers | F7: Esports Influencers | G7: Saudi Arabia | H7: 4 | I7: Tier 3 | J7: 7450 | K7: 3150 | L7: =IF($C7="","",ROUND($J7*0.17,0)) -> 1267 | M7: 5850 | N7: 2400 | O7: 1500 | P7: 1500 | Q7: 10850 | R7: 4850 | S7: =IF($C7="","",ROUND($J7*2.2,0)) -> 16390 | T7: 2600 | U7: 2250 | V7: 1350 | W7: 1118 | X7: 4 platforms | Y7: 0.3 | Z7: 1 | AA7: Nasser alotaibi | AB7: https://x.com/iFMG_ | AC7: https://www.instagram.com/fm.g/ | AD7: https://www.twitch.tv/fmg_ | AG7: https://kick.com/ifmg
B8: =IF($C8="","",COUNTA($C$5:C8)) -> 4 | C8: Abo Ghazi | D8: Influencer | E8: Esports Influencers | F8: Esports Influencers | G8: Saudi Arabia | H8: 3 | I8: Tier 3 | J8: 5200 | K8: 2200 | L8: =IF($C8="","",ROUND($J8*0.17,0)) -> 884 | M8: 4050 | N8: 1650 | O8: 1050 | P8: 1050 | Q8: 7550 | R8: 3400 | S8: =IF($C8="","",ROUND($J8*2.2,0)) -> 11440 | T8: 1800 | U8: 1550 | V8: 950 | W8: 780 | X8: 3 platforms | Y8: 0.3 | Z8: 1 | AA8: Mohammed Albaqami | AB8: https://x.com/MohxamedZ | AD8: https://www.twitch.tv/ires | AG8: https://kick.com/iabughazi | AH8: https://www.facebook.com/AbuGhaziGaming93 | AI8: https://www.snapchat.com/add/faisalhajhasan | AJ8: https://linktr.ee/abughaazi
B9: =IF($C9="","",COUNTA($C$5:C9)) -> 5 | C9: Mary | D9: Influencer | E9: Esports Influencers | F9: Esports Influencers | G9: Bahraini | H9: 5 | I9: Tier 3 | J9: 8100 | K9: 3400 | L9: =IF($C9="","",ROUND($J9*0.17,0)) -> 1377 | M9: 6350 | N9: 2600 | O9: 1600 | P9: 1600 | Q9: 11800 | R9: 5300 | S9: =IF($C9="","",ROUND($J9*2.2,0)) -> 17820 | T9: 2850 | U9: 2450 | V9: 1450 | W9: 1215 | X9: 5 platforms | Y9: 0.3 | Z9: 1 | AA9: Maryam Maher | AB9: https://x.com/marypink | AC9: https://www.instagram.com/maryvalorantt/?hl=en | AD9: https://www.twitch.tv/mary | AE9: https://www.youtube.com/@maryvalorant/featured | AF9: https://www.tiktok.com/@maryvalorant | AJ9: https://linktr.ee/verymarygaming
B10: =IF($C10="","",COUNTA($C$5:C10)) -> 6 | C10: Ghala | D10: Influencer | E10: Esports Influencers | F10: Esports Influencers | G10: Saudi Arabia | H10: 5 | I10: Tier 3 | J10: 7450 | K10: 3150 | L10: =IF($C10="","",ROUND($J10*0.17,0)) -> 1267 | M10: 5850 | N10: 2400 | O10: 1500 | P10: 1500 | Q10: 10850 | R10: 4850 | S10: =IF($C10="","",ROUND($J10*2.2,0)) -> 16390 | T10: 2600 | U10: 2250 | V10: 1350 | W10: 1118 | X10: 5 platforms | Y10: 0.3 | Z10: 1 | AA10: Ghala Alqahtani | AB10: https://x.com/pg_ghala3?lang=en | AC10: https://www.instagram.com/pg_ghala3 | AE10: https://www.youtube.com/@pg_ghala3 | AF10: https://www.tiktok.com/@pg_ghala3 | AG10: https://kick.com/pg-ghala3 | AI10: https://snapchat.com/t/bLA2ZOsG | AJ10: https://linktr.ee/ga1lll
B11: =IF($C11="","",COUNTA($C$5:C11)) -> 7 | C11: Moaz | D11: Influencer | E11: Esports Influencers | F11: Esports Influencers | G11: Saudi Arabia | H11: 5 | I11: Tier 2 | J11: 6500 | K11: 5300 | L11: =IF($C11="","",ROUND($J11*0.17,0)) -> 1105 | M11: 3400 | N11: 4050 | O11: 2500 | P11: 2500 | Q11: 15950 | R11: 8200 | S11: =IF($C11="","",ROUND($J11*2.2,0)) -> 14300 | T11: 3800 | U11: 1900 | V11: 3150 | W11: 1250 | X11: 5 platforms | Y11: 0.3 | Z11: 1 | AA11: Moaz Asiri | AB11: https://x.com/mezostrong?s=21 | AC11: https://www.instagram.com/mezostrong | AE11: https://www.youtube.com/channel/UCZCgW8WW8K_vrHrO6sZ7oyg?app=desktop | AF11: https://www.tiktok.com/@mezostrong?_r=1&_t=zs-91bbrrsefwl | AG11: https://kick.com/MezoStrong
B12: =IF($C12="","",COUNTA($C$5:C12)) -> 8 | C12: vacwep | D12: Influencer | E12: Esports Influencers | F12: Esports Influencers | G12: Saudi Arabia | H12: 5 | I12: Tier 3 | J12: 7450 | K12: 3150 | L12: =IF($C12="","",ROUND($J12*0.17,0)) -> 1267 | M12: 5800 | N12: 2400 | O12: 1500 | P12: 1500 | Q12: 7500 | R12: 4850 | S12: =IF($C12="","",ROUND($J12*2.2,0)) -> 16390 | T12: 2250 | U12: 1100 | V12: 1850 | W12: 750 | X12: 5 platforms | Y12: 0.3 | Z12: 1 | AA12: Abdullah Mousa A Alsulaymi | AB12: https://x.com/vacwep?s=21&t=PiVx0_LPZgUm0TT5Ok_2Zw | AC12: https://www.instagram.com/vacwep_?igsh=Z28yMXRibTZ0OWlm&utm_source=qr | AF12: https://www.tiktok.com/@vacwep?_r=1&_t=ZS-94jrcxtNGEK | AG12: https://kick.com/vacwep | AH12: https://www.facebook.com/share/1BDLRfGMFS/?mibextid=wwXIfr | AK12: 12/07/1992
B13: =IF($C13="","",COUNTA($C$5:C13)) -> 9 | C13: Cellium | D13: Player | E13: Call of Duty Black Ops 7 | F13: Riyadh Falcons | G13: American | H13: 3 | I13: Tier 2 | J13: 11250 | K13: 4500 | L13: =IF($C13="","",ROUND($J13*0.17,0)) -> 1913 | M13: 8000 | N13: 3500 | O13: 2000 | P13: 2000 | Q13: 13500 | R13: 6075 | S13: =IF($C13="","",ROUND($J13*2.2,0)) -> 24750 | T13: 4638 | U13: 4063 | V13: 2438 | W13: 2400 | X13: 3 platforms | Y13: 0.3 | Z13: 1 | AA13: McArthur Jovel | AB13: https://twitter.com/Cellium | AC13: https://www.instagram.com/cellium/ | AD13: https://www.twitch.tv/Cellium | AK13: 24/12/2000 | AL13: Assault Rifle / Main AR
B14: =IF($C14="","",COUNTA($C$5:C14)) -> 10 | C14: Exnid | D14: Player | E14: Call of Duty Black Ops 7 | F14: Riyadh Falcons | G14: Saudi Arabia | H14: 2 | I14: Tier 2 | J14: 11000 | K14: 4600 | L14: =IF($C14="","",ROUND($J14*0.17,0)) -> 1870 | M14: 8600 | N14: 3500 | O14: 2200 | P14: 2200 | Q14: 15950 | R14: 7150 | S14: =IF($C14="","",ROUND($J14*2.2,0)) -> 24200 | T14: 3850 | U14: 3300 | V14: 2000 | W14: 2400 | X14: 2 platforms | Y14: 0.3 | Z14: 1 | AA14: Saud Alati | AB14: https://x.com/Exnid_ | AD14: https://www.twitch.tv/exnid | AK14: 28/10/2002 | AL14: Sub-Machine Gun (SMG)
B15: =IF($C15="","",COUNTA($C$5:C15)) -> 11 | C15: KiSMET | D15: Player | E15: Call of Duty Black Ops 7 | F15: Riyadh Falcons | G15: American | H15: 3 | I15: Tier 2 | J15: 12100 | K15: 5100 | L15: =IF($C15="","",ROUND($J15*0.17,0)) -> 2057 | M15: 9450 | N15: 3850 | O15: 2400 | P15: 2400 | Q15: 17550 | R15: 7850 | S15: =IF($C15="","",ROUND($J15*2.2,0)) -> 26620 | T15: 4250 | U15: 3650 | V15: 2200 | W15: 2400 | X15: 3 platforms | Y15: 0.3 | Z15: 1 | AA15: Matthew Tinsley | AB15: https://twitter.com/KiSMET6_ | AC15: https://www.instagram.com/kismet6_ | AD15: https://www.twitch.tv/kismet6_ | AK15: 36475 | AL15: Assault Rifle / Flex
B16: =IF($C16="","",COUNTA($C$5:C16)) -> 12 | C16: Pred | D16: Player | E16: Call of Duty Black Ops 7 | F16: Riyadh Falcons | G16: American | H16: 3 | I16: Tier 2 | J16: 11000 | K16: 4600 | L16: =IF($C16="","",ROUND($J16*0.17,0)) -> 1870 | M16: 8600 | N16: 3500 | O16: 2200 | P16: 2200 | Q16: 15950 | R16: 7150 | S16: =IF($C16="","",ROUND($J16*2.2,0)) -> 24200 | T16: 3850 | U16: 3300 | V16: 2000 | W16: 2400 | X16: 3 platforms | Y16: 0.3 | Z16: 1 | AA16: Amer Zulbeari | AB16: https://x.com/Pred | AC16: https://www.instagram.com/amerzulbeariii | AD16: https://www.twitch.tv/pred | AK16: 19/08/2001 | AL16: Sub-Machine Gun (SMG)
B17: =IF($C17="","",COUNTA($C$5:C17)) -> 13 | C17: KingAbody | D17: Player | E17: Call of Duty Black Ops 7 | F17: FaZe Falcons | G17: Saudi Arabia | H17: 1 | I17: Tier 2 | J17: 11000 | K17: 4600 | L17: =IF($C17="","",ROUND($J17*0.17,0)) -> 1870 | M17: 8600 | N17: 3500 | O17: 2200 | P17: 2200 | Q17: 15950 | R17: 7150 | S17: =IF($C17="","",ROUND($J17*2.2,0)) -> 24200 | T17: 3850 | U17: 3300 | V17: 2000 | W17: 2400 | X17: 1 platform | Y17: 0.3 | Z17: 1 | AA17: Abdulelah Alrajhi | AB17: https://x.com/KingAbody_ | AK17: 36679 | AL17: Sub-Machine Gun (SMG)
B18: =IF($C18="","",COUNTA($C$5:C18)) -> 14 | C18: Arcitys | D18: Player | E18: Call of Duty Black Ops 7 | F18: Falcons Academy White | G18: American | H18: 3 | I18: Tier 2 | J18: 12100 | K18: 5100 | L18: =IF($C18="","",ROUND($J18*0.17,0)) -> 2057 | M18: 9450 | N18: 3850 | O18: 2400 | P18: 2400 | Q18: 17550 | R18: 7850 | S18: =IF($C18="","",ROUND($J18*2.2,0)) -> 26620 | T18: 4250 | U18: 3650 | V18: 2200 | W18: 2400 | X18: 3 platforms | Y18: 0.3 | Z18: 1 | AA18: Alec Sanderson | AB18: https://x.com/Arcitys | AC18: https://www.instagram.com/arcitys9 | AD18: https://www.twitch.tv/arcitys | AK18: 36045 | AL18: Assault Rifle / Main AR
B19: =IF($C19="","",COUNTA($C$5:C19)) -> 15 | C19: Paulehx | D19: Player | E19: Call of Duty Black Ops 7 | F19: Falcons Academy White | G19: American | H19: 2 | I19: Tier 2 | J19: 11000 | K19: 4600 | L19: =IF($C19="","",ROUND($J19*0.17,0)) -> 1870 | M19: 8600 | N19: 3500 | O19: 2200 | P19: 2200 | Q19: 15950 | R19: 7150 | S19: =IF($C19="","",ROUND($J19*2.2,0)) -> 24200 | T19: 3850 | U19: 3300 | V19: 2000 | W19: 2400 | X19: 2 platforms | Y19: 0.3 | Z19: 1 | AA19: Paul Avila | AB19: https://x.com/Paulehx_ | AD19: https://www.twitch.tv/paulehx | AK19: 21/01/2002 | AL19: Assault Rifle / Flex
B20: =IF($C20="","",COUNTA($C$5:C20)) -> 16 | C20: hmoodx | D20: Player | E20: Call of Duty Warzone | F20: Team Falcons MENA | G20: Saudi Arabia | H20: 2 | I20: Tier 2 | J20: 11000 | K20: 4600 | L20: =IF($C20="","",ROUND($J20*0.17,0)) -> 1870 | M20: 8600 | N20: 3500 | O20: 2200 | P20: 2200 | Q20: 15950 | R20: 7150 | S20: =IF($C20="","",ROUND($J20*2.2,0)) -> 24200 | T20: 3850 | U20: 3300 | V20: 2000 | W20: 2400 | X20: 2 platforms | Y20: 0.3 | Z20: 1 | AA20: Mohammed Altowairqi | AB20: https://x.com/xihamoodx | AD20: https://www.twitch.tv/i_hmoodx
B21: =IF($C21="","",COUNTA($C$5:C21)) -> 17 | C21: xizx7 | D21: Player | E21: Call of Duty Warzone | F21: Team Falcons MENA | G21: Saudi Arabia | H21: 4 | I21: Tier 1 | J21: 12100 | K21: 5100 | L21: =IF($C21="","",ROUND($J21*0.17,0)) -> 2057 | M21: 9450 | N21: 3850 | O21: 2400 | P21: 2400 | Q21: 17550 | R21: 7850 | S21: =IF($C21="","",ROUND($J21*2.2,0)) -> 26620 | T21: 4250 | U21: 3650 | V21: 2200 | W21: 2400 | X21: 4 platforms | Y21: 0.3 | Z21: 1 | AA21: Jawad Al-Thawab | AB21: https://x.com/Jawxd7 | AC21: https://www.instagram.com/Jawxd7 | AD21: https://www.twitch.tv/jawad | AE21: https://www.youtube.com/channel/UCUWL8dR-JyA4FXZ08aSjjcg/videos
B22: =IF($C22="","",COUNTA($C$5:C22)) -> 18 | C22: Alpine | D22: Manager | E22: Call of Duty Warzone | F22: Team Falcons | G22: American | H22: 1 | I22: Tier 3 | J22: 22750 | K22: 9550 | L22: =IF($C22="","",ROUND($J22*0.17,0)) -> 3868 | M22: 17750 | N22: 7300 | O22: 4550 | P22: 0 | Q22: 33000 | R22: 14800 | S22: =IF($C22="","",ROUND($J22*2.2,0)) -> 50050 | T22: 7950 | U22: 6850 | V22: 4100 | W22: 0 | X22: 1 platform | Y22: 0.3 | Z22: 1 | AA22: Alejandro Ayala | AB22: https://x.com/alpinedadog?lang=en | AK22: 24/02/1997
B23: =IF($C23="","",COUNTA($C$5:C23)) -> 19 | C23: Newbz | D23: Player | E23: Call of Duty Warzone | F23: Team Falcons | G23: American | H23: 2 | I23: Tier 3 | J23: 20700 | K23: 8700 | L23: =IF($C23="","",ROUND($J23*0.17,0)) -> 3519 | M23: 16150 | N23: 6600 | O23: 4150 | P23: 4150 | Q23: 30000 | R23: 13450 | S23: =IF($C23="","",ROUND($J23*2.2,0)) -> 45540 | T23: 7250 | U23: 6200 | V23: 3750 | W23: 2400 | X23: 2 platforms | Y23: 0.2 | Z23: 1 | AA23: Edy Juan | AB23: https://x.com/TBE_Newbzz | AD23: https://www.twitch.tv/newbz | AK23: 36527
B24: =IF($C24="","",COUNTA($C$5:C24)) -> 20 | C24: Dongy | D24: Player | E24: Call of Duty Warzone | F24: Team Falcons | G24: American | H24: 2 | I24: Tier 3 | J24: 6500 | K24: 2750 | L24: =IF($C24="","",ROUND($J24*0.17,0)) -> 1105 | M24: 5050 | N24: 2100 | O24: 1300 | P24: 1300 | Q24: 9400 | R24: 4200 | S24: =IF($C24="","",ROUND($J24*2.2,0)) -> 14300 | T24: 2300 | U24: 1950 | V24: 1150 | W24: 2400 | X24: 2 platforms | Y24: 0.2 | Z24: 1 | AA24: Christopher Ledbetter | AB24: https://x.com/zDongyy | AD24: https://www.twitch.tv/Dongy | AK24: 23/03/2004
B25: =IF($C25="","",COUNTA($C$5:C25)) -> 21 | C25: Soka | D25: Player | E25: Call of Duty Warzone | F25: Team Falcons | G25: Tongan | H25: 5 | I25: Tier 1 | J25: 6500 | K25: 2750 | L25: =IF($C25="","",ROUND($J25*0.17,0)) -> 1105 | M25: 5050 | N25: 2100 | O25: 1300 | P25: 1300 | Q25: 9400 | R25: 4200 | S25: =IF($C25="","",ROUND($J25*2.2,0)) -> 14300 | T25: 2300 | U25: 1950 | V25: 1150 | W25: 2400 | X25: 5 platforms | Y25: 0.2 | Z25: 1 | AA25: Kasimili Tonga Tongamoa | AB25: https://twitter.com/HisokaT42 | AC25: https://www.instagram.com/hisokat42 | AD25: https://www.twitch.tv/HisokaT42 | AE25: https://www.youtube.com/channel/UCQDRE8aZRsrvF5OwMk_KmBg | AF25: https://tiktok.com/@missionarysoka | AK25: 28/01/2002
B26: =IF($C26="","",COUNTA($C$5:C26)) -> 22 | C26: Alireza Firouzja | D26: Player | E26: Chess | F26: Chess | G26: French/Iranian | H26: 5 | I26: Tier 1 | J26: 20700 | K26: 8700 | L26: =IF($C26="","",ROUND($J26*0.17,0)) -> 3519 | M26: 16150 | N26: 6600 | O26: 4150 | P26: 4150 | Q26: 30000 | R26: 13450 | S26: =IF($C26="","",ROUND($J26*2.2,0)) -> 45540 | T26: 7250 | U26: 6200 | V26: 3750 | W26: 2400 | X26: 5 platforms | Y26: 0.5 | Z26: 1 | AA26: Alireza Firouzja | AB26: https://twitter.com/AlirezaFirouzja | AC26: https://www.instagram.com/alirezafirouzja | AD26: https://www.twitch.tv/alirezafirouzja | AE26: https://www.youtube.com/@alirezafirouzja4080 | AH26: https://www.facebook.com/login/?next=https%3A%2F%2Fwww.facebook.com%2FAlireza.Firouzja.chess%2F | AK26: 18/06/2003
B27: =IF($C27="","",COUNTA($C$5:C27)) -> 23 | C27: Hikaru Nakamura | D27: Player | E27: Chess | F27: Chess | G27: American | H27: 6 | I27: Tier 1 | J27: 22500 | K27: 9450 | L27: =IF($C27="","",ROUND($J27*0.17,0)) -> 3825 | M27: 17550 | N27: 7200 | O27: 4500 | P27: 4500 | Q27: 32600 | R27: 14600 | S27: =IF($C27="","",ROUND($J27*2.2,0)) -> 49500 | T27: 7850 | U27: 6750 | V27: 4050 | W27: 2400 | X27: 6 platforms | Y27: 0.5 | Z27: 1 | AA27: Hikaru Nakamura | AB27: https://twitter.com/GMHikaru | AC27: https://www.instagram.com/gmhikaru | AD27: https://www.twitch.tv/gmhikaru | AE27: https://www.youtube.com/@gmhikaru | AG27: https://kick.com/gmhikaru | AH27: https://www.facebook.com/login/?next=https%3A%2F%2Fwww.facebook.com%2FGMHikaru%2F | AK27: 32120
B28: =IF($C28="","",COUNTA($C$5:C28)) -> 24 | C28: Jon Ellis | D28: Manager | E28: Chess | F28: Chess | H28: 0 | I28: Tier 3 | J28: 22500 | K28: 9450 | L28: =IF($C28="","",ROUND($J28*0.17,0)) -> 3825 | M28: 17550 | N28: 7200 | O28: 4500 | P28: 0 | Q28: 32600 | R28: 14600 | S28: =IF($C28="","",ROUND($J28*2.2,0)) -> 49500 | T28: 7850 | U28: 6750 | V28: 4050 | W28: 0 | X28: 0 platforms | Y28: 0.3 | Z28: 1 | AA28: Jonathan Ellis
B29: =IF($C29="","",COUNTA($C$5:C29)) -> 25 | C29: kyousuke | D29: Player | E29: Counterstrike2 | F29: Team Falcons | G29: Russian | H29: 3 | I29: Tier 1 | J29: 15000 | K29: 6750 | L29: =IF($C29="","",ROUND($J29*0.17,0)) -> 2550 | M29: 11000 | N29: 5000 | O29: 3200 | P29: 3200 | Q29: 19500 | R29: 8775 | S29: =IF($C29="","",ROUND($J29*2.2,0)) -> 33000 | T29: 6800 | U29: 5950 | V29: 3570 | W29: 2400 | X29: 3 platforms | Y29: 0.75 | Z29: 1 | AA29: Maxim Lukin | AB29: https://twitter.com/FLCkyousuke | AC29: https://www.instagram.com/flckyousuke | AD29: https://www.twitch.tv/kyousuke999 | AK29: 30/01/2008 | AL29: Rifler
B30: =IF($C30="","",COUNTA($C$5:C30)) -> 26 | C30: kyxsan | D30: Player | E30: Counterstrike2 | F30: Team Falcons | G30: North Macedonia | H30: 2 | I30: Tier 1 | J30: 22500 | K30: 9450 | L30: =IF($C30="","",ROUND($J30*0.17,0)) -> 3825 | M30: 17550 | N30: 7200 | O30: 4500 | P30: 4500 | Q30: 32600 | R30: 14600 | S30: =IF($C30="","",ROUND($J30*2.2,0)) -> 49500 | T30: 7850 | U30: 6750 | V30: 4050 | W30: 2400 | X30: 2 platforms | Y30: 0.75 | Z30: 1 | AA30: Damjan Stoilkovski | AB30: https://x.com/kyxsancs | AC30: https://www.instagram.com/kyxsancs/ | AK30: 26/05/2000 | AL30: IGL
B31: =IF($C31="","",COUNTA($C$5:C31)) -> 27 | C31: m0NESY | D31: Player | E31: Counterstrike2 | F31: Team Falcons | G31: Russian | H31: 4 | I31: Tier 1 | J31: 22500 | K31: 9450 | L31: =IF($C31="","",ROUND($J31*0.17,0)) -> 3825 | M31: 17550 | N31: 7200 | O31: 4500 | P31: 4500 | Q31: 32600 | R31: 14600 | S31: =IF($C31="","",ROUND($J31*2.2,0)) -> 49500 | T31: 7850 | U31: 6750 | V31: 4050 | W31: 2400 | X31: 4 platforms | Y31: 0.2 | Z31: 1 | AA31: Ilya Osipov | AB31: https://x.com/FLCm0NESY | AC31: https://www.instagram.com/m0nesy13 | AD31: https://www.twitch.tv/m0nesyof | AE31: https://www.youtube.com/channel/UCJxjKA1Cl--4tCN1l_cHHvQ | AK31: 38357 | AL31: Awper
B32: =IF($C32="","",COUNTA($C$5:C32)) -> 28 | C32: NiKo | D32: Player | E32: Counterstrike2 | F32: Team Falcons | G32: Bosnian | H32: 5 | I32: Tier 1 | J32: 22500 | K32: 9450 | L32: =IF($C32="","",ROUND($J32*0.17,0)) -> 3825 | M32: 17550 | N32: 7200 | O32: 4500 | P32: 4500 | Q32: 32600 | R32: 14600 | S32: =IF($C32="","",ROUND($J32*2.2,0)) -> 49500 | T32: 7850 | U32: 6750 | V32: 4050 | W32: 2400 | X32: 5 platforms | Y32: 0.3 | Z32: 1 | AA32: Nikola Kovač | AB32: https://x.com/NiKoCS_ | AC32: https://www.instagram.com/csgoniko/# | AD32: https://www.twitch.tv/NiKo | AE32: https://www.youtube.com/@NiKo_cs | AH32: https://www.facebook.com/csgoNiKo | AK32: 16/02/1997 | AL32: Rifler
B33: =IF($C33="","",COUNTA($C$5:C33)) -> 29 | C33: OMYA | D33: Manager | E33: Counterstrike2 | F33: Team Falcons | G33: French | H33: 1 | I33: Tier 3 | J33: 22500 | K33: 9450 | L33: =IF($C33="","",ROUND($J33*0.17,0)) -> 3825 | M33: 17550 | N33: 7200 | O33: 4500 | P33: 0 | Q33: 32600 | R33: 14600 | S33: =IF($C33="","",ROUND($J33*2.2,0)) -> 49500 | T33: 7850 | U33: 6750 | V33: 4050 | W33: 0 | X33: 1 platform | Y33: 0.3 | Z33: 1 | AA33: Xavier Roussac | AB33: https://x.com/Xavier_Roussac | AK33: 20/05/1987
B34: =IF($C34="","",COUNTA($C$5:C34)) -> 30 | C34: TeSeS | D34: Player | E34: Counterstrike2 | F34: Team Falcons | G34: Danish | H34: 2 | I34: Tier 2 | J34: 11250 | K34: 4500 | L34: =IF($C34="","",ROUND($J34*0.17,0)) -> 1913 | M34: 8000 | N34: 3500 | O34: 2000 | P34: 2000 | Q34: 13500 | R34: 6075 | S34: =IF($C34="","",ROUND($J34*2.2,0)) -> 24750 | T34: 4638 | U34: 4063 | V34: 2438 | W34: 2400 | X34: 2 platforms | Y34: 0.75 | Z34: 1 | AA34: René Madsen | AB34: https://x.com/tesescs | AC34: Instagram/TeseS | AD34: https://www.twitch.tv/tesesss | AK34: 36872 | AL34: Rifler
B35: =IF($C35="","",COUNTA($C$5:C35)) -> 31 | C35: Aymeinstein | D35: Assistant Coach | E35: Counterstrike2 | F35: Team Falcons | G35: French | H35: 2 | I35: Tier 2 | J35: 11000 | K35: 4600 | L35: =IF($C35="","",ROUND($J35*0.17,0)) -> 1870 | M35: 8600 | N35: 3500 | O35: 2200 | P35: 0 | Q35: 15950 | R35: 7150 | S35: =IF($C35="","",ROUND($J35*2.2,0)) -> 24200 | T35: 3850 | U35: 3300 | V35: 2000 | W35: 0 | X35: 2 platforms | Y35: 0.5 | Z35: 1 | AA35: Aymen Bencheikh | AB35: https://x.com/aymeinstein | AC35: https://www.instagram.com/aymeinsteintv | AK35: 22/04/1996
B36: =IF($C36="","",COUNTA($C$5:C36)) -> 32 | C36: Zonic | D36: Head Coach | E36: Counterstrike2 | F36: Team Falcons | G36: Danish | H36: 2 | I36: Tier 1 | J36: 0 | K36: 0 | L36: =IF($C36="","",ROUND($J36*0.17,0)) -> 0 | M36: 0 | N36: 0 | O36: 0 | P36: 0 | Q36: 0 | R36: 0 | S36: =IF($C36="","",ROUND($J36*2.2,0)) -> 0 | T36: 0 | U36: 0 | V36: 2000 | W36: 0 | X36: 2 platforms | Y36: 0.5 | Z36: 1 | AA36: Danny Sørensen | AB36: https://x.com/zonic | AC36: Instagram/Zonic | AD36: https://www.twitch.tv/zonic | AH36: Facebook/Zonic | AK36: 30/07/1986
B37: =IF($C37="","",COUNTA($C$5:C37)) -> 33 | C37: clockzi | D37: Player | E37: Counterstrike2 | F37: Falcons Force | G37: Danish | H37: 1 | I37: Tier 3 | J37: 11000 | K37: 4600 | L37: =IF($C37="","",ROUND($J37*0.17,0)) -> 1870 | M37: 8600 | N37: 3500 | O37: 2200 | P37: 2200 | Q37: 15950 | R37: 7150 | S37: =IF($C37="","",ROUND($J37*2.2,0)) -> 24200 | T37: 3850 | U37: 3300 | V37: 2000 | W37: 2400 | X37: 1 platform | Y37: 0.75 | Z37: 1 | AA37: Oskar Led Blæsbjerg | AB37: https://x.com/flcclockzi | AK37: 21/04/2011 | AL37: Rifler
B38: =IF($C38="","",COUNTA($C$5:C38)) -> 34 | C38: grecu | D38: Player | E38: Counterstrike2 | F38: Falcons Force | G38: Romanian | H38: 2 | I38: Tier 2 | J38: 5200 | K38: 2200 | L38: =IF($C38="","",ROUND($J38*0.17,0)) -> 884 | M38: 4050 | N38: 1650 | O38: 1050 | P38: 1050 | Q38: 7550 | R38: 3400 | S38: =IF($C38="","",ROUND($J38*2.2,0)) -> 11440 | T38: 1800 | U38: 1550 | V38: 950 | W38: 2400 | X38: 2 platforms | Y38: 0.75 | Z38: 1 | AA38: Andrei Grecu | AB38: https://x.com/grecuflc | AD38: https://www.twitch.tv/gbcgrecu | AK38: 15/11/2007 | AL38: AWPer
B39: =IF($C39="","",COUNTA($C$5:C39)) -> 35 | C39: VENO | D39: Player | E39: Counterstrike2 | F39: Falcons Force | G39: Serbian | H39: 3 | I39: Tier 2 | J39: 12100 | K39: 5100 | L39: =IF($C39="","",ROUND($J39*0.17,0)) -> 2057 | M39: 9450 | N39: 3850 | O39: 2400 | P39: 2400 | Q39: 17550 | R39: 7850 | S39: =IF($C39="","",ROUND($J39*2.2,0)) -> 26620 | T39: 4250 | U39: 3650 | V39: 2200 | W39: 2400 | X39: 3 platforms | Y39: 0.75 | Z39: 1 | AA39: Vladimir Stanković | AB39: https://x.com/venocs2 | AD39: https://www.twitch.tv/venocs2 | AE39: https://www.youtube.com/@venocs2 | AK39: 30/04/2007 | AL39: Rifler
B40: =IF($C40="","",COUNTA($C$5:C40)) -> 36 | C40: NaToSaphiX | D40: Head Coach | E40: Counterstrike2 | F40: Falcons Force | G40: Danish | H40: 5 | I40: Tier 2 | J40: 11000 | K40: 4600 | L40: =IF($C40="","",ROUND($J40*0.17,0)) -> 1870 | M40: 8600 | N40: 3500 | O40: 2200 | P40: 0 | Q40: 15950 | R40: 7150 | S40: =IF($C40="","",ROUND($J40*2.2,0)) -> 24200 | T40: 3850 | U40: 3300 | V40: 2000 | W40: 0 | X40: 5 platforms | Y40: 0.2 | Z40: 1 | AA40: Niels Christian Sillassen | AB40: https://x.com/NaToSaphiX | AC40: https://www.instagram.com/natosaphix | AD40: https://www.twitch.tv/natosaphix | AE40: https://www.youtube.com/NaToSaphiX | AK40: 17/08/1996
B41: =IF($C41="","",COUNTA($C$5:C41)) -> 37 | C41: Neoskai | D41: Manager | E41: Counterstrike2 | F41: Falcons Force | G41: French | H41: 2 | I41: Tier 2 | J41: 0 | K41: 0 | L41: =IF($C41="","",ROUND($J41*0.17,0)) -> 0 | M41: 0 | N41: 0 | O41: 0 | P41: 0 | Q41: 0 | R41: 0 | S41: =IF($C41="","",ROUND($J41*2.2,0)) -> 0 | T41: 0 | U41: 0 | V41: 1200 | W41: 0 | X41: 2 platforms | Y41: 0.2 | Z41: 1 | AA41: Loïc Potages | AB41: https://x.com/Neoskai | AC41: https://www.instagram.com/neoskai/ | AK41: 16/06/1994
...

Sheet 02_Creator_Rate_Card
B2: ="CREATOR RATE CARD — "&COUNTA($C$5:$C$500)&" ENTRIES" -> CREATOR RATE CARD — 17 ENTRIES
A3: ROLE LEGEND | B3: ● Creator
B4: # | C4: Creator | D4: Weighted Score | E4: Tier | F4: X Post/Quote | G4: X Repost | H4: IG Post | I4: IG Story | J4: IG Reels | K4: YT Full Video | L4: YT 1-2min Pre-roll | M4: TikTok Our-side | N4: TikTok Client Vids | O4: Kick IRL | P4: Twitch/Kick Live | Q4: Telegram | R4: Event + Snap
B5: =IF($C5="","",COUNTA($C$5:C5)) -> 1 | C5: BanderitaX | D5: 98 | E5: Tier S | F5: 56250 | G5: 22500 | H5: 28125 | I5: 16875 | J5: 28125 | K5: 67500 | L5: 50625 | M5: 39375 | N5: 31500 | O5: 14063 | P5: 28125 | Q5: 11250 | R5: 39375
B6: =IF($C6="","",COUNTA($C$5:C6)) -> 2 | C6: oPiiLz | D6: 72 | E6: Tier 1 | F6: 22500 | G6: 9000 | H6: 11250 | I6: 6750 | J6: 11250 | K6: 27000 | L6: 20250 | M6: 15750 | N6: 12600 | O6: 5625 | P6: 11250 | Q6: 4500 | R6: 15750
B7: =IF($C7="","",COUNTA($C$5:C7)) -> 3 | C7: Msdossary7 | D7: 72 | E7: Tier 1 | F7: 22500 | G7: 9000 | H7: 11250 | I7: 6750 | J7: 11250 | K7: 27000 | L7: 20250 | M7: 15750 | N7: 12600 | O7: 5625 | P7: 11250 | Q7: 4500 | R7: 15750
B8: =IF($C8="","",COUNTA($C$5:C8)) -> 4 | C8: Aziz | D8: 68 | E8: Tier 1 | F8: 18000 | G8: 7200 | H8: 9000 | I8: 5400 | J8: 9000 | K8: 21600 | L8: 16200 | M8: 12600 | N8: 10080 | O8: 4500 | P8: 9000 | Q8: 3600 | R8: 12600
B9: =IF($C9="","",COUNTA($C$5:C9)) -> 5 | C9: Bo3omar22 | D9: 68 | E9: Tier 1 | F9: 18000 | G9: 7200 | H9: 9000 | I9: 5400 | J9: 9000 | K9: 21600 | L9: 16200 | M9: 12600 | N9: 10080 | O9: 4500 | P9: 9000 | Q9: 3600 | R9: 12600
B10: =IF($C10="","",COUNTA($C$5:C10)) -> 6 | C10: Abu abeer | D10: 60 | E10: Tier 2 | F10: 11250 | G10: 4500 | H10: 5625 | I10: 3375 | J10: 5625 | K10: 13500 | L10: 10125 | M10: 7875 | N10: 6300 | O10: 2813 | P10: 5625 | Q10: 2250 | R10: 7875
B11: =IF($C11="","",COUNTA($C$5:C11)) -> 7 | C11: LLE | D11: 58 | E11: Tier 2 | F11: 10125 | G11: 4050 | H11: 5063 | I11: 3038 | J11: 5063 | K11: 12150 | L11: 9113 | M11: 7088 | N11: 5670 | O11: 2531 | P11: 5063 | Q11: 2025 | R11: 7088
B12: =IF($C12="","",COUNTA($C$5:C12)) -> 8 | C12: Oden | D12: 55 | E12: Tier 2 | F12: 9000 | G12: 3600 | H12: 4500 | I12: 2700 | J12: 4500 | K12: 10800 | L12: 8100 | M12: 6300 | N12: 5040 | O12: 2250 | P12: 4500 | Q12: 1800 | R12: 6300
B13: =IF($C13="","",COUNTA($C$5:C13)) -> 9 | C13: xSMA333 | D13: 52 | E13: Tier 2 | F13: 7875 | G13: 3150 | H13: 3938 | I13: 2363 | J13: 3938 | K13: 9450 | L13: 7088 | M13: 5513 | N13: 4410 | O13: 1969 | P13: 3938 | Q13: 1575 | R13: 5513
B14: =IF($C14="","",COUNTA($C$5:C14)) -> 10 | C14: 3ADEL | D14: 50 | E14: Tier 2 | F14: 6750 | G14: 2700 | H14: 3375 | I14: 2025 | J14: 3375 | K14: 8100 | L14: 6075 | M14: 4725 | N14: 3780 | O14: 1688 | P14: 3375 | Q14: 1350 | R14: 4725
B15: =IF($C15="","",COUNTA($C$5:C15)) -> 11 | C15: RAED | D15: 48 | E15: Tier 2 | F15: 6188 | G15: 2475 | H15: 3094 | I15: 1856 | J15: 3094 | K15: 7425 | L15: 5569 | M15: 4331 | N15: 3465 | O15: 1547 | P15: 3094 | Q15: 1238 | R15: 4331
B16: =IF($C16="","",COUNTA($C$5:C16)) -> 12 | C16: Falcons | D16: 45 | E16: Tier 2 | F16: 5625 | G16: 2250 | H16: 2813 | I16: 1688 | J16: 2813 | K16: 6750 | L16: 5063 | M16: 3938 | N16: 3150 | O16: 1406 | P16: 2813 | Q16: 1125 | R16: 3938
... B21: =IF($C21="","",COUNTA($C$5:C21)) -> 17 | C21: 9leeh | D21: 32 | E21: Tier 3 | F21: 2250 | G21: 900 | H21: 1125 | I21: 675 | J21: 1125 | K21: 2700 | L21: 2025 | M21: 1575 | N21: 1260 | O21: 563 | P21: 1125 | Q21: 450 | R21: 1575

Sheet 03_Adjustment_Matrix
B2: DYNAMIC PRICING ADJUSTMENT MATRIX
B3: Select a player → choose an asset → adjust multipliers → get the final price
B5: 🔍 Search Player | D5: moaz | F5: =IFERROR(__xludf.dummyfunction("IF(TRIM(D5)="""","""",IFERROR(INDEX(FILTER('01_Player_Rate_Card'!C$5:C1016,REGEXMATCH(LOWER('01_Player_Rate_Card'!C$5:C1016),LOWER(TRIM(D5)))) ,1),""No match — check spelling""))"),"Moaz") -> Moaz | H5: Type a full or partial name in D5 → best matching player appears in F5 → selection syncs automatically below
B7: ① PLAYER SELECTOR
B8: Select Player | C8: Game | D8: Team | E8: Role | F8: Tier | G8: Nationality | H8: Platforms
B9: =IF(OR($F$5="",$F$5="No match — check spelling"),"",$F$5) -> Moaz | C9: =IFERROR(VLOOKUP(B9,'01_Player_Rate_Card'!$C$5:$AL$500,3,0),"") -> Esports Influencers | D9: =IFERROR(VLOOKUP(B9,'01_Player_Rate_Card'!$C$5:$AL$500,4,0),"") -> Esports Influencers | E9: =IFERROR(VLOOKUP(B9,'01_Player_Rate_Card'!$C$5:$AL$500,2,0),"") -> Influencer | F9: =IFERROR(VLOOKUP(B9,'01_Player_Rate_Card'!$C$5:$AL$500,7,0),"") -> Tier 2 | G9: =IFERROR(VLOOKUP(B9,'01_Player_Rate_Card'!$C$5:$AL$500,5,0),"") -> Saudi Arabia | H9: =IFERROR(VLOOKUP(B9,'01_Player_Rate_Card'!$C$5:$AL$500,6,0),"") -> 5
B10: ② PLAYER RATE CARD (all values in SAR)
B11: IG Reel | C11: IG Static | D11: IG Story | E11: TikTok Video | F11: YT Short | G11: X Post | H11: FB Post/Video | I11: Twitch 2h | J11: Twitch Integ. | K11: IRL / Appear. | L11: Rights Fee | M11: Exclusivity | N11: Rush Fee | O11: WL Fee | P11: Repost
B12: =IFERROR(VLOOKUP(B9,'01_Player_Rate_Card'!$C$5:$AL$500,8,0),"N/A") -> 6500 | C12: =IFERROR(VLOOKUP(B9,'01_Player_Rate_Card'!$C$5:$AL$500,9,0),"N/A") -> 5300 | D12: =IFERROR(VLOOKUP(B9,'01_Player_Rate_Card'!$C$5:$AL$500,10,0),"N/A") -> 1105 | E12: =IFERROR(VLOOKUP(B9,'01_Player_Rate_Card'!$C$5:$AL$500,11,0),"N/A") -> 3400 | F12: =IFERROR(VLOOKUP(B9,'01_Player_Rate_Card'!$C$5:$AL$500,12,0),"N/A") -> 4050 | G12: =IFERROR(VLOOKUP(B9,'01_Player_Rate_Card'!$C$5:$AL$500,13,0),"N/A") -> 2500 | H12: =IFERROR(VLOOKUP(B9,'01_Player_Rate_Card'!$C$5:$AL$500,14,0),"N/A") -> 2500 | I12: =IFERROR(VLOOKUP(B9,'01_Player_Rate_Card'!$C$5:$AL$500,15,0),"N/A") -> 15950 | J12: =IFERROR(VLOOKUP(B9,'01_Player_Rate_Card'!$C$5:$AL$500,16,0),"N/A") -> 8200 | K12: =IFERROR(VLOOKUP(B9,'01_Player_Rate_Card'!$C$5:$AL$500,17,0),"N/A") -> 14300 | L12: =IFERROR(VLOOKUP(B9,'01_Player_Rate_Card'!$C$5:$AL$500,18,0),"N/A") -> 3800 | M12: =IFERROR(VLOOKUP(B9,'01_Player_Rate_Card'!$C$5:$AL$500,19,0),"N/A") -> 1900 | N12: =IFERROR(VLOOKUP(B9,'01_Player_Rate_Card'!$C$5:$AL$500,20,0),"N/A") -> 3150 | O12: =IFERROR(VLOOKUP(B9,'01_Player_Rate_Card'!$C$5:$AL$500,21,0),"N/A") -> 1250 | P12: =IFERROR(ROUND(IFERROR(VLOOKUP(B9,'01_Player_Rate_Card'!$C$5:$AL$500,8,0),0)*0.15,0),"N/A") -> 975
B14: ③ ASSET SELECTOR — Choose the deliverable type
B15: Asset Type | D15: Base Fee (SAR) | F15: Notes / Basis
B16: Podcast Guesting | D16: {=IFERROR(xlookup(B16,$B$17:$B$34,$D$17:$D$34,0),0)} -> 0
B17: IG Reel | D17: =IFERROR(VLOOKUP($B$9,'01_Player_Rate_Card'!$C$5:$AL$500,8,FALSE()),0) -> 6500 | F17: Player IG Reel rate from Rate Card
B18: IG Static Post | D18: =IFERROR(VLOOKUP($B$9,'01_Player_Rate_Card'!$C$5:$AL$500,9,FALSE()),0) -> 5300 | F18: Player IG Static rate
B19: IG Story | D19: =IFERROR(VLOOKUP($B$9,'01_Player_Rate_Card'!$C$5:$AL$500,10,FALSE()),0) -> 1105 | F19: Player IG Story rate
B20: TikTok Video | D20: =IFERROR(VLOOKUP($B$9,'01_Player_Rate_Card'!$C$5:$AL$500,11,FALSE()),0) -> 3400 | F20: Player TikTok rate
B21: YT Short | D21: =IFERROR(VLOOKUP($B$9,'01_Player_Rate_Card'!$C$5:$AL$500,12,FALSE()),0) -> 4050 | F21: Player YT Short rate
B22: X Post | D22: =IFERROR(VLOOKUP($B$9,'01_Player_Rate_Card'!$C$5:$AL$500,13,FALSE()),0) -> 2500 | F22: Player X Post rate
B23: FB Post / Video | D23: =IFERROR(VLOOKUP($B$9,'01_Player_Rate_Card'!$C$5:$AL$500,14,FALSE()),0) -> 2500 | F23: Player FB rate
B24: Content Repost | D24: =IFERROR(VLOOKUP($B$9,'01_Player_Rate_Card'!$C$5:$AL$500,8,FALSE())*0.15,0) -> 975 | F24: 15% of IG Reel rate
B25: — LIVE & STREAM —
B26: Twitch Stream 2h | D26: =IFERROR(VLOOKUP($B$9,'01_Player_Rate_Card'!$C$5:$AL$500,15,FALSE()),0) -> 15950 | F26: Player Twitch 2h rate
B27: Twitch Integration | D27: =IFERROR(VLOOKUP($B$9,'01_Player_Rate_Card'!$C$5:$AL$500,16,FALSE()),0) -> 8200 | F27: Player Twitch Integ. rate
B28: — ON-GROUND & EVENTS —
B29: IRL Appearance | D29: =IFERROR(VLOOKUP($B$9,'01_Player_Rate_Card'!$C$5:$AL$500,17,FALSE()),0) -> 14300 | F29: Player IRL rate
B30: Podcast Guesting | D30: =IFERROR(VLOOKUP($B$9,'01_Player_Rate_Card'!$C$5:$AL$500,17,FALSE())*0.5,0) -> 7150 | F30: 50% of IRL — 1-2h time commitment
B31: PR Appearance / CSR | D31: =IFERROR(VLOOKUP($B$9,'01_Player_Rate_Card'!$C$5:$AL$500,17,FALSE()),0) -> 14300 | F31: Full IRL rate — brand presence + media
B32: Fan Meet & Greet | D32: =IFERROR(VLOOKUP($B$9,'01_Player_Rate_Card'!$C$5:$AL$500,17,FALSE())*0.7,0) -> 10010 | F32: 70% of IRL — structured 2-4h fan interaction
B33: — OTHER —
B34: Photo Shoot (Brand) | D34: =IFERROR(VLOOKUP($B$9,'01_Player_Rate_Card'!$C$5:$AL$500,17,FALSE())*0.75,0) -> 10725 | F34: 75% of IRL — half-day shoot, brand usage rights incl. | H34: Weight | I34: Description
B35: < 2% | D35: 0.70x | E35: Below average — audience not engaged | F35: Awareness | H35: 0.2 | I35: Brand visibility — social reach matters most
B36: 2% – 4% | D36: 0.90x | E36: Average — slight discount from baseline | F36: Conversion | H36: 0.4 | I36: Direct response — engagement + credibility
B37: 4% – 6% | D37: 1.00x | E37: Baseline — standard market rate | F37: Trust (Pro Authority) | H37: 0.7 | I37: Credibility campaigns — pro status is the product
B38: 6% – 8% | D38: 1.20x | E38: Good — 20% premium
B39: 8% – 10% | D39: 1.40x | E39: Excellent — strong audience connection | F39: AUTHORITY MULTIPLIER PRESETS | H39: Value | I39: Profile
B40: > 10% | D40: 1.60x | E40: Premium micro-influencer effect | F40: Normal | H40: 1 | I40: Content creator / standard player
F41: Proven / Established | H41: 1.15 | I41: Regional champion, 2+ years pro
B42: AUDIENCE QUALITY | D42: Multiplier | E42: Notes | F42: Elite Contender | H42: 1.3 | I42: Top-10 world ranking, major finalist
B43: Generic / Broad | D43: 0.85x | E43: Mixed interests, low targeting | F43: Global Star / Major Winner | H43: 1.5 | I43: World champion, iconic pro name
B44: Gaming-adjacent | D44: 1.00x | E44: Baseline — general gaming
...

Sheet 04_Add_On_Rights
B2: ADD-ON RIGHTS PACKAGES
B3: Select applicable add-ons and sum the uplift percentages · Enter total in cell C35 of the Live Calculator (02_Adjustment_Matrix)
B5: RIGHTS PACKAGES — PRICE UPLIFT TABLE
B6: Add-on Type | C6: Uplift % | D6: Description
B7: Organic Repost — Min | C7: 0.15 | D7: Single repost, 1 month
B8: Organic Repost — Std | C8: 0.35 | D8: 3-5 reposts, 3 months
B9: Organic Repost — Max | C9: 0.6 | D9: Unlimited + takeover, 6 months
B10: Paid Usage — Min | C10: 0.25 | D10: Limited, SAR 25K cap
B11: Paid Usage — Std | C11: 0.5 | D11: Standard, SAR 75K cap
B12: Paid Usage — Max | C12: 1 | D12: Unlimited paid media
B13: Whitelisting — Std | C13: 0.4 | D13: 30 days, single platform
B14: Whitelisting — Extended | C14: 0.75 | D14: 90 days, multi-platform
B15: Whitelisting — Premium | C15: 1.2 | D15: 180 days, dark posts included
B16: Territory — MENA | C16: 0.2 | D16: MENA rights, 3 months
B17: Territory — Global | C17: 0.75 | D17: Worldwide, 6 months
B18: Exclusivity — Category | C18: 1.5 | D18: Exclusive category, 12 months
B19: Exclusivity — Full | C19: 2 | D19: Full exclusivity, 12 months
B22: BUNDLE PRESETS — READY TO PITCH
B23: Bundle Tier | C23: Included Add-ons | D23: Total Uplift
B24: Basic | C24: Organic Repost Min | D24: 15%
B25: Standard | C25: Organic Repost Std + Paid Usage Min | D25: 60%
B26: Premium | C26: Organic Repost Max + Paid Usage Std + MENA Territory | D26: 115%
B27: Full | C27: Organic Max + Paid Max + Whitelisting Std + MENA Territory | D27: 170%
B28: Exclusive | C28: All above + Category Exclusivity (12 months) | D28: 320%
B1003: ⑥ ADD-ON TOGGLE GRID · flip to Yes to include in live calculator
B1005: Include? | C1005: Add-On / Rights | D1005: Uplift % | E1005: Description
B1006: No | C1006: Paid Usage 30d MENA | D1006: 0.1 | E1006: Media spend boost, MENA region, 30 days
B1007: No | C1007: Paid Usage 30d Global | D1007: 0.15 | E1007: Media spend boost, Global, 30 days
B1008: No | C1008: Paid Usage 60d MENA | D1008: 0.2 | E1008: Media spend boost, MENA region, 60 days
B1009: No | C1009: Paid Usage 60d Global | D1009: 0.3 | E1009: Media spend boost, Global, 60 days
B1010: No | C1010: Paid Usage 90d MENA | D1010: 0.3 | E1010: Media spend boost, MENA region, 90 days
B1011: No | C1011: Paid Usage 90d Global | D1011: 0.45 | E1011: Media spend boost, Global, 90 days
B1012: No | C1012: Whitelisting / Spark Ads | D1012: 0.1 | E1012: Enable brand to run Spark Ads from talent handle
B1013: No | C1013: Exclusivity 30d (category) | D1013: 0.15 | E1013: No competing brand in category for 30 days
B1014: No | C1014: Exclusivity 90d (category) | D1014: 0.35 | E1014: No competing brand in category for 90 days
B1015: No | C1015: Brand Lockup / Logo Usage | D1015: 0.1 | E1015: Talent image + brand lockup for OOH/print
B1016: No | C1016: Licensing (image, 1 year) | D1016: 0.25 | E1016: Likeness license for brand assets, 12 months
B1017: No | C1017: Dedicated Content (non-integrated) | D1017: 0.2 | E1017: Stand-alone brand content, not integration
... B1020: No | C1020: Cross-post to Team Falcons org | D1020: 0.1 | E1020: Re-post from official Team Falcons channels
B1021: TOTAL UPLIFT | C1021: =SUMPRODUCT((B1006:B1020="Yes")*D1006:D1020) -> 0 | E1021: → pulled into 03_Adjustment_Matrix D66 (Add-on Uplift)

Sheet 05_Quote_Template
B2: TEAM FALCONS | D2: Prepared by: | E2: Abdalrahman
D3: Approved by: | E3: TBD
D4: Date: | E4: 14/04/2026
D5: Quote #: | E5: QT-20260414-477
D6: Client: | E6: asdasd
D7: Currency: | E7: SAR
B12: Description | C12: Unit Cost (SAR) | D12: Qty | E12: Amount (SAR)
B14: ImperialHal — IG Static [Dedicated (Brand-led)] | C14: SAR 5,980 | D14: 1 | E14: SAR 5,980
B15: Skiter — Twitch Integration [Dedicated (Brand-led)] | C15: SAR 4,420 | D15: 1 | E15: SAR 4,420
B16: Special notes and instructions | D16: SUBTOTAL | E16: SAR 10,400
B17: asdsddsadsaf | D17: (TAX RATE) | E17: 0.15
D18: TAX | E18: SAR 1,560
D20: TOTAL | E20: SAR 11,960
B23: PRICING MULTIPLIERS BREAKDOWN
B24: Multiplier | C24: Selected Value | D24: Factor | E24: Impact
B25: ① Content Type | C25: Dedicated (Brand-led) | D25: 1.30× | E25: ▲ Premium
B26: ② Engagement Rate | C26: 4% – 6% (1×) | D26: 1.00× | E26: — Baseline
B27: ③ Audience Quality | C27: Gaming-adjacent (1×) | D27: 1.00× | E27: — Baseline
B28: ④ Seasonality | C28: Regular season (1×) | D28: 1.00× | E28: — Baseline
B29: ⑤ Language | C29: English (1×) | D29: 1.00× | E29: — Baseline
B30: ⑥ Authority Level | C30: Normal (1×) | D30: 1.00× | E30: — Baseline
B31: ⑦ Campaign Objective | C31: Awareness (Wt 0.2) | D31: 1.00× | E31: — Baseline
B32: COMBINED PRICE MULTIPLIER | D32: 1.300× | E32: Applied to Base Fee
B34: Formula: Base Fee × ContentType × Engagement × Audience × Seasonality × Language × AuthorityFactor + Add-On Uplifts
B37: King Abdulaziz Road, Riyadh, Saudi Arabia, Al-Yasmeen District Phone: +966 53370 4233 | Sales@falcons.sa | store.falcons.sa
B38: [INTERNAL] ImperialHal: 15% comm | Skiter: 75% comm

Sheet 06_Quote_Log
B2: QUOTE LOG — ARCHIVE OF ISSUED QUOTES
B3: Every quote issued to a client is logged here. Apps Script writes new rows automatically.
B4: Quote ID | C4: Date | D4: Client | E4: Campaign | F4: Owner | G4: Currency | H4: # Lines | I4: Subtotal | J4: Add-Ons % | K4: Pre-VAT | L4: VAT | M4: TOTAL | N4: Confidence | O4: Sheet Name
B5: TF-Q-20260418-001 | C5: 2026-04-18 | D5: Aramco Digital | E5: Ramadan 2026 | F5: commercial@teamfalcons.gg | G5: SAR | H5: 3 | I5: 125000 | J5: 10% | K5: 137500 | L5: 20625 | M5: 158125 | N5: estimated | O5: Quote_TF-Q-20260418-001

Sheet 07_Settings
A1: A (Key) | B1: B (Value)
A2: output_folder_id | B2: (Drive folder ID where PDFs go)
A3: legal_approver_email | B3: legal@…
A4: finance_approver_email | B4: finance@…
A5: client_email | B5: (optional default)
A6: approval_secret | B6: (any random word like falcons2026)

Sheet 08_Benchmarks
A1: 09 — MARKET BENCHMARKS & COMPETITIVE INTELLIGENCE 2025/2026
A2: Industry rate benchmarks, multiplier standards, and competitive positioning for Team Falcons talent monetisation
A4: SECTION 1 — GLOBAL TIER 1 ESPORTS ORG BENCHMARKS
A5: Organisation | B5: Region | C5: Tier | D5: Avg Followers (Key Talent) | E5: Avg Base Fee / Post (USD) | F5: Avg Stream Deal (USD) | G5: Avg Annual Sponsorship (USD) | H5: Exclusivity Premium | I5: Engagement Benchmark | J5: Source / Notes
A6: T1 Esports | B6: Global | C6: Tier 1 | D6: 2M–8M | E6: $8,000–$25,000 | F6: $20,000–$80,000 | G6: $500K–$2M | H6: '+50-100% | I6: 4–7% avg ER | J6: Newzoo 2025; public deal disclosures
A7: FaZe Clan | B7: Global | C7: Tier 1 | D7: 3M–15M | E7: $10,000–$40,000 | F7: $30,000–$120,000 | G7: $1M–$5M | H7: '+40-75% | I7: 3–6% avg ER | J7: Newzoo 2025; SEC filing data
A8: Natus Vincere (NaVi) | B8: EMEA | C8: Tier 1 | D8: 1M–5M | E8: $5,000–$20,000 | F8: $15,000–$60,000 | G8: $300K–$1.5M | H8: '+35-60% | I8: 4–8% avg ER | J8: Shikenso Esports Sponsorship Report 2025
A9: Fnatic | B9: EMEA | C9: Tier 1 | D9: 500K–3M | E9: $4,000–$15,000 | F9: $10,000–$45,000 | G9: $200K–$800K | H9: '+30-50% | I9: 5–9% avg ER | J9: Influencity 2026 Rate Benchmarks
A10: Cloud9 | B10: NA | C10: Tier 1 | D10: 1M–6M | E10: $6,000–$22,000 | F10: $18,000–$70,000 | G10: $400K–$1.8M | H10: '+30-50% | I10: 3–6% avg ER | J10: Nielsen Esports Audience Report 2025
A11: 100 Thieves | B11: NA | C11: Tier 1 | D11: 500K–4M | E11: $5,000–$18,000 | F11: $15,000–$55,000 | G11: $350K–$1.2M | H11: '+40-70% | I11: 5–10% avg ER | J11: Porter Wills Esports Marketing Guide 2025
A13: SECTION 2 — MENA ESPORTS ORG BENCHMARKS
A14: Organisation | B14: Region | C14: Tier | D14: Avg Followers (Key Talent) | E14: Avg Base Fee / Post (SAR) | F14: Avg Stream Deal (SAR) | G14: Avg Annual Sponsorship (SAR) | H14: Exclusivity Premium | I14: Engagement Benchmark | J14: Source / Notes
A15: Team Falcons | B15: KSA / MENA | C15: Tier 1 | D15: 200K–2M | E15: SAR 8,000–60,000 | F15: SAR 20,000–120,000 | G15: SAR 500K–2M | H15: '+35-60% | I15: 5–12% avg ER | J15: Internal Falcons data 2025; Newzoo MENA Report
A16: Nasr Esports | B16: KSA / MENA | C16: Tier 1 | D16: 100K–800K | E16: SAR 5,000–30,000 | F16: SAR 12,000–60,000 | G16: SAR 200K–800K | H16: '+30-50% | I16: 4–9% avg ER | J16: Shikenso MENA Esports Report 2025
A17: GE Wolves | B17: MENA | C17: Tier 2 | D17: 50K–400K | E17: SAR 3,000–15,000 | F17: SAR 8,000–35,000 | G17: SAR 100K–400K | H17: '+25-40% | I17: 5–10% avg ER | J17: Influencity MENA 2025
A18: Twisted Minds | B18: KSA | C18: Tier 2 | D18: 80K–500K | E18: SAR 4,000–20,000 | F18: SAR 10,000–45,000 | G18: SAR 150K–500K | H18: '+25-45% | I18: 6–11% avg ER | J18: Internal market intelligence 2025
A19: Galaxy Racer | B19: UAE / MENA | C19: Tier 2 | D19: 100K–1M | E19: SAR 4,500–22,000 | F19: SAR 11,000–50,000 | G19: SAR 180K–600K | H19: '+25-40% | I19: 4–9% avg ER | J19: Newzoo MENA 2025
A20: Team Vitality (MENA) | B20: MENA | C20: Tier 1 | D20: 200K–1.5M | E20: SAR 6,000–35,000 | F20: SAR 15,000–70,000 | G20: SAR 250K–900K | H20: '+30-50% | I20: 4–8% avg ER | J20: Shikenso Esports Report 2025
A22: SECTION 3 — PLATFORM RATE BENCHMARKS (Industry Standard CPM / CPE)
A23: Platform | B23: Content Type | C23: Nano (1K–10K) | D23: Micro (10K–100K) | E23: Mid (100K–1M) | F23: Macro (1M–5M) | G23: Mega (5M+) | H23: Min Engagement Req. | I23: Avg CPM (Gaming Niche) | J23: Notes / Source
A24: Instagram | B24: Reel (60s) | C24: $200–$1,000 | D24: $1,000–$5,000 | E24: $5,000–$15,000 | F24: $15,000–$50,000 | G24: $50,000+ | H24: Min 3% ER | I24: $8–$15 CPM | J24: Reels outperform static 3:1 for brand recall in gaming. Source: Influencity 2026
A25: Instagram | B25: Static Post | C25: $150–$800 | D25: $800–$4,000 | E25: $4,000–$12,000 | F25: $12,000–$40,000 | G25: $40,000+ | H25: Min 2% ER | I25: $5–$10 CPM | J25: Static posts declining vs Reels. Use for product shots. Source: Influencity 2026
A26: TikTok | B26: Branded Video | C26: $300–$1,500 | D26: $1,500–$6,000 | E26: $6,000–$20,000 | F26: $20,000–$60,000 | G26: $60,000+ | H26: Min 5% ER | I26: $10–$20 CPM | J26: TikTok commands 20–40% premium over IG in MENA. Source: Nielsen 2025
A27: YouTube | B27: Integration (30s) | C27: $500–$2,000 | D27: $2,000–$8,000 | E27: $8,000–$25,000 | F27: $25,000–$80,000 | G27: $80,000+ | H27: Min 1% ER | I27: $15–$30 CPM | J27: Highest brand recall (72% vs 45% social posts). Source: Nielsen Esports 2025
A28: YouTube | B28: Short (<60s) | C28: $200–$1,000 | D28: $1,000–$4,000 | E28: $4,000–$12,000 | F28: $12,000–$35,000 | G28: $35,000+ | H28: Min 3% ER | I28: $8–$18 CPM | J28: YouTube Shorts growing rapidly in MENA. Source: Newzoo 2025
A29: Twitch | B29: Stream Integration (2h) | C29: $1,000–$4,000 | D29: $4,000–$15,000 | E29: $15,000–$40,000 | F29: $40,000–$100,000 | G29: $100,000+ | H29: Min 500 avg viewers | I29: $5–$15 CPM | J29: Rates based on concurrent viewership not followers. Source: StreamElements 2025
A30: X (Twitter) | B30: Sponsored Post | C30: $100–$500 | D30: $500–$2,000 | E30: $2,000–$6,000 | F30: $6,000–$20,000 | G30: $20,000+ | H30: Min 1% ER | I30: $3–$8 CPM | J30: X declining in brand value post-rebrand. Use for real-time only. Source: Influencity 2026
A32: SECTION 4 — MULTIPLIER BENCHMARKS (Industry Standard vs Team Falcons)
A33: Multiplier Type | B33: Industry Low | C33: Industry Standard | D33: Industry High | E33: Team Falcons Rate | F33: Variance vs Industry | G33: Recommendation | H33: Source
A34: Exclusivity (30 days) | B34: 0.15 | C34: 0.25 | D34: 0.4 | E34: 0.25 | F34: At standard | G34: At standard | H34: Influencity 2026; Porter Wills Guide
A35: Exclusivity (90 days) | B35: 0.3 | C35: 0.5 | D35: 0.75 | E35: 0.4 | F35: Below standard — gap of 10% | G35: Below standard — gap of 10% | H35: Influencity 2026; Shikenso 2025
A36: Rush Fee (<72h) | B36: 0.15 | C36: 0.25 | D36: 0.35 | E36: 0.2 | F36: Below standard — gap of 5% | G36: Below standard — gap of 5% | H36: Internal benchmark; Influencity 2026
A37: Usage Rights (6 months) | B37: 0.2 | C37: 0.35 | D37: 0.5 | E37: 0.3 | F37: Below standard — gap of 5% | G37: Below standard — gap of 5% | H37: Porter Wills Esports Guide 2025
A38: Usage Rights (12 months) | B38: 0.4 | C38: 0.6 | D38: 0.8 | E38: 0.5 | F38: Below standard — gap of 10% | G38: Below standard — gap of 10% | H38: Porter Wills Esports Guide 2025
A39: Whitelist / Dark Post | B39: 0.15 | C39: 0.25 | D39: 0.4 | E39: 0.2 | F39: Below standard — gap of 5% | G39: Below standard — gap of 5% | H39: Influencity 2026
A40: Ramadan Premium (MENA) | B40: 0.25 | C40: 0.35 | D40: 0.5 | E40: 0.35 | F40: At standard | G40: At standard | H40: Newzoo MENA 2025; Internal data
A42: SECTION 5 — TEAM FALCONS COMPETITIVE POSITIONING
A43: Metric | B43: Team Falcons | C43: MENA Average | D43: Global Tier 1 | E43: Gap vs MENA | F43: Gap vs Global | G43: Action Required
A44: Roster Size | B44: 188 entries (131 players, 6 influencers, 51 staff) | C44: 80–120 players | D44: 150–200 players | E44: Above MENA avg (+78%) | F44: Above global avg | G44: Leverage scale — offer multi-player bundle packages
A45: Game Coverage | B45: 23 titles | C45: 10–15 titles | D45: 15–20 titles | E45: Above MENA avg | F45: Above global avg | G45: Position as one-stop-shop for brand esports activations
...

Sheet 09_Guide_EN
B2: 05 — PRICING GUIDE & BEST PRACTICES (ENGLISH)
B3: How to use this Rate Card · Pricing Formula · Tier Definitions · Base Fee Methodology · Best Practices · Data Sources
B5: HOW TO USE THIS RATE CARD — 5 STEPS
B6: Step 1 — Find the Talent
B7: Go to 01_Player_Rate_Card. All 188 entries are listed. Use the filter on column D (Role) or I (Tier) or E (Game). Players: 131 | Influencers: 6 | Staff & Coaches: 51 | Across 23 games and 21 teams.
B9: Step 2 — Read the Base Fees
B10: The base fee is the starting price for each asset type based on talent tier. Tier 1 = premium price, Tier 2 = target price, Tier 3 = emerging price. Base fees are in SAR and include a USD equivalent at the current rate.
B12: Step 3 — Apply Adjustment Multipliers
B13: Go to 02_Adjustment_Matrix. Enter the base fee in cell C31. Select the appropriate multipliers for engagement quality (C32), audience quality (C33), and seasonality (C34). The matrix auto-calculates the adjusted price.
B15: Step 4 — Add Rights Packages
B16: Go to 03_Add_On_Rights. Select the required rights packages (exclusivity, usage rights, whitelist, rush fee, etc.). Sum the uplift percentages and enter the total in cell C35 of the Adjustment Matrix.
B18: Step 5 — Build the Full Deal
... B144: STEP-BY-STEP
B145: Step 1 | C145: Fill Campaign Details (rows 5-9): Campaign name, brand, period, prepared by
B146: Step 2
B147: Step 3 | C147: Add line items (rows 19-33): For each deliverable, select from dropdowns:
C148: • Player / Talent — select from full roster dropdown
C149: • Deliverable — IG Reel, TikTok Video, Twitch Stream, IRL Appearance, etc.
C150: • Qty — number of posts/appearances
C151: • Timing — Regular Season, Ramadan, EWC, etc. (auto-applies multiplier)
C152: • Audience — Core Gaming, Esports-focused, MENA/Saudi, etc. (auto-applies multiplier)
C153: • Add-on Package — None, Basic, Standard, Premium, Full, Exclusive (auto-applies uplift %)
B154: Step 4 | C154: Unit Price auto-calculates: Base Rate × Timing Multiplier × Audience Multiplier × (1 + Add-on %)
B155: Step 5 | C155: Summary auto-calculates: Subtotal → +10% Mgmt Fee → +15% VAT → Total SAR + USD
B156: Step 6 | C156: Click "GENERATE PDF QUOTE" button to export a formatted client document
B158: PRICING METHODOLOGY (Updated 2025)
B159: All player rates have been recalibrated using best-practice 2025 benchmarks:
B160: Source | C160: Porter Wills Esports Guide 2025, InfluenceFlow Benchmarks, Cloutboost Gaming Rates
B161: Tier 1 IG Reel Base | C161: 18,000 SAR (was 15,000) — aligned to macro esports creator rates ($4,800 USD)
B162: Tier 2 IG Reel Base | C162: 11,000 SAR (was 11,250) — refined for 100K-500K reach segment
B163: Tier 3 IG Reel Base | C163: 6,500 SAR (was 8,750) — corrected downward to match micro-creator benchmarks
B164: Platform Ratios | C164: TikTok = 78% of IG Reel | Twitch 2h = 145% | IRL = 220% | X Post = 20%
B165: Platform Count Bonus | C165: 0-1 platforms: -20% | 2-3: standard | 4-5: +15% | 6-7: +25% | 8+: +35%
B166: MENA Premium
B168: ADD-ON PACKAGES (simplified from 03_Add_On_Rights)
B169: None | C169: 0% uplift — base rate only
B170: Basic (+15%) | C170: Organic repost, 1 month — single platform
B171: Standard (+60%) | C171: Organic repost (3 months) + paid usage (limited)
B172: Premium (+115%) | C172: Organic repost (6 months) + paid usage (standard) + MENA territory
B173: Full (+170%) | C173: All organic + paid max + whitelisting (30 days)
...

Sheet 10_Guide_AR
B2: دليل التسعير وأفضل الممارسات — عربي
B3: كيفية الاستخدام · معادلة التسعير · منهجية الرسوم الأساسية · تعريفات الفئات · أفضل الممارسات · مصادر البيانات
B5: كيفية استخدام بطاقة الأسعار — 5 خطوات
B6: الخطوة 1 — ابحث عن المواهب
B7: اذهب إلى 01_Player_Rate_Card. جميع الـ 188 إدخالاً مدرجة. استخدم الفلتر على عمود D (الدور) أو I (الفئة) أو E (اللعبة). اللاعبون: 131 | المؤثرون: 6 | الطاقم والمدربون: 51 | عبر 23 لعبة و21 فريق.
B9: الخطوة 2 — اقرأ الرسوم الأساسية
B10: الرسوم الأساسية هي السعر المبدئي لكل نوع من الأصول بناءً على فئة الموهبة. الفئة 1 = سعر مرتفع، الفئة 2 = السعر المستهدف، الفئة 3 = سعر منخفض. الرسوم بالريال السعودي مع ما يعادلها بالدولار.
B12: الخطوة 3 — طبّق معاملات التعديل
B13: اذهب إلى 02_Adjustment_Matrix. أدخل الرسوم الأساسية في الخلية C31. اختر المضاعفات المناسبة لجودة التفاعل (C32) وجودة الجمهور (C33) والموسمية (C34). تحسب الورقة تلقائياً السعر المعدّل.
B15: الخطوة 4 — أضف حزم الحقوق
B16: اذهب إلى 03_Add_On_Rights. اختر حزم الحقوق المطلوبة (الحصرية، حقوق الاستخدام، القائمة البيضاء، رسوم الاستعجال، إلخ). اجمع نسب الزيادة وأدخل الإجمالي في الخلية C35 من مصفوفة التعديل.
B18: الخطوة 5 — ابنِ الصفقة الكاملة
... B143: خطوات الاستخدام
B144: الخطوة 1 | C144: تفاصيل الحملة (صفوف 5-9): اسم الحملة، العلامة التجارية، الفترة، المُعِد
B145: الخطوة 2
B146: الخطوة 3 | C146: أضف بنود التسليم (صفوف 19-33): لكل تسليم، اختر من القوائم:
C147: • اللاعب / الموهبة — اختر من القائمة الكاملة للرياضيين
C148: • نوع التسليم — ريلز إنستغرام، فيديو تيك توك، بث تويتش، حضور شخصي، إلخ
C149: • الكمية — عدد المنشورات أو الظهورات
C150: • التوقيت — الموسم العادي، رمضان، كأس العالم للرياضات الإلكترونية، إلخ
C151: • الجمهور — ألعاب أساسية، رياضات إلكترونية، منطقة الشرق الأوسط وشمال أفريقيا، إلخ
C152: • باقة الإضافات — لا شيء، أساسية، قياسية، مميزة، كاملة، حصرية
B153: الخطوة 4 | C153: يُحسب سعر الوحدة تلقائياً: السعر الأساسي × مضاعف التوقيت × مضاعف الجمهور × (1 + نسبة الإضافات)
B154: الخطوة 5 | C154: الملخص يُحسب تلقائياً: المجموع الفرعي + رسوم الإدارة 10% + ضريبة القيمة المضافة 15%
B155: الخطوة 6 | C155: انقر على "إنشاء عرض سعري PDF" لتصدير وثيقة منسقة للعميل
B157: منهجية التسعير (محدّثة 2025)
B158: تم إعادة معايرة جميع أسعار اللاعبين وفق أفضل الممارسات العالمية لعام 2025:
B159: الدرجة الأولى — ريلز إنستغرام | C159: 18,000 ريال (كانت 15,000) — متوافق مع معدلات منشئي المحتوى الكبار في الرياضات الإلكترونية
B160: الدرجة الثانية — ريلز إنستغرام | C160: 11,000 ريال (كانت 11,250) — محسّن لشريحة 100K-500K متابع
B161: الدرجة الثالثة — ريلز إنستغرام | C161: 6,500 ريال (كانت 8,750) — مصحّح للتوافق مع معايير منشئي المحتوى الصغار
B162: نسب المنصات | C162: تيك توك = 78% من ريلز إنستغرام | تويتش 2 ساعة = 145% | حضور شخصي = 220%
B163: مكافأة عدد المنصات | C163: 0-1 منصة: -20% | 2-3: معياري | 4-5: +15% | 6-7: +25% | 8+: +35%
B164: علاوة منطقة MENA
B166: باقات الإضافات (مبسّطة)
B167: لا شيء
B168: أساسية (+15%) | C168: إعادة نشر عضوي، شهر واحد — منصة واحدة
B169: قياسية (+60%) | C169: إعادة نشر عضوي (3 أشهر) + استخدام مدفوع (محدود)
B170: مميزة (+115%) | C170: إعادة نشر عضوي (6 أشهر) + استخدام مدفوع (قياسي) + حقوق منطقة MENA
B171: كاملة (+170%) | C171: جميع الحقوق العضوية + الاستخدام المدفوع الكامل + القائمة البيضاء (30 يوماً)
B172: حصرية (+320%) | C172: الباقة الكاملة + حصرية الفئة (12 شهراً)
...

Sheet 11_Methodology
A1: TEAM FALCONS — COMMERCIAL PRICING METHODOLOGY & ROADMAP
A3: ① CURRENT PRICING MODEL (v2.0 — April 2026)
A4: Our current pricing engine uses a Base Rate + Multiplier model. This ensures baseline consistency across 189+ players while allowing dynamic adjustments for campaign specifics, audience quality, and content type.
A6: BASE RATES (The Foundation)
A7: Base rates are established per player, per platform, based on their Tier (1, 2, or 3) and Role (Player, Influencer, Coach, etc.).
A8: • Social Media: IG Reel, TikTok, YT Short, X Post, FB Post/Video
A9: • Live & Stream: Twitch 2h Stream, Twitch Integration
A10: • On-Ground & Events: IRL Appearance, Podcast Guesting (50% IRL), PR/CSR (100% IRL), Fan Meet (70% IRL), Photo Shoot (75% IRL) | B10: C | C10: D | D10: E | E10: F
B11: Audience Reach × CPM Rate | C11: Base Fee = (Followers × Avg Reach Rate × CPM) ÷ 1,000 Reach rates: IG 15–25%, TikTok 20–35%, YT 10–20% Gaming CPM: $8–$20 USD (MENA: $10–$15) | D11: WME, CAA, Wasserman standard FaZe: $15–25 CPM for gaming T1: $12–18 CPM for esports | E11: Applied as Floor 1 in our 3-input model. Sets the minimum viable rate based on expected impressions.
A12: THE MULTIPLIER CHAIN (The Adjustments) | B12: Engagement Quality Multiplier | C12: Multiplier applied on top of CPM floor: < 2%: 0.70x (below market) 2–4%: 0.90x (average) 4–6%: 1.00x (baseline) 6–8%: 1.20x (good) 8–10%: 1.40x (excellent) > 10%: 1.60x (premium micro) | D12: Industry standard: 4–6% is baseline for gaming Micro-influencers (< 100K) often 8–15% Macro (> 1M) typically 2–4% | E12: Applied as Engagement Multiplier in 02_Adjustment_Matrix. Reflects true audience quality beyond raw follower count.
A13: Final Price = Base Rate × Content Type × Engagement × Audience × Seasonality × Language × Authority Factor | B13: Targeting Value Multiplier | C13: Multiplier based on audience composition: Generic/Broad: 0.85x Gaming-adjacent: 1.00x Core Gaming: 1.20x MENA/Saudi focus: 1.30x Esports-focused: 1.40x Global Esports Elite: 1.50x | D13: Esports audiences command 30–50% premium over general gaming due to purchase intent. MENA premium: 20–35% above global baseline. | E13: Applied as Audience Quality Multiplier. Esports-focused Saudi audiences = highest value tier.
A14: • Content Type: Integrated (1.00x) vs. Dedicated/Brand-led (1.30x) | B14: Follower + Engagement Tier System | C14: Tier 1 (Premium): 1M+ followers, 8%+ engagement Tier 2 (Target): 100K–1M followers, 5–8% Tier 3 (Emerging): 10K–100K followers, high engagement Base rates set per tier per platform. | D14: T1 Esports: Faker = $50K+/post FaZe Clan Tier 1: $15K–$30K IG Reel NRG Tier 2: $5K–$12K IG Reel Micro-esports: $1K–$5K | E14: Tier 1 IG Reel: SAR 18,000 (~$4,800) Tier 2 IG Reel: SAR 11,000 (~$2,933) Tier 3 IG Reel: SAR 6,500 (~$1,733)
