Workbook

Sheet 00_Cover
B3: TEAM FALCONS
B4: Talent Commercial Rate Card · 2026
B5: Global Esports Pricing & Monetization Framework
B6: Updated: 14 April, 2026 · Currency: SAR · 1 USD = 3.75 SAR
B7: =IFERROR(__xludf.dummyfunction("""Total Talent: ""&COUNTA('01_Player_Rate_Card'!$C$5:$C$500)&"" entries across ""&COUNTUNIQUE(FILTER('01_Player_Rate_Card'!$E$5:$E$500,'01_Player_Rate_Card'!$E$5:$E$500<>""""))&"" games · ""&COUNTIF('01_Player_Rate_Card'!$D$5:$D$500,""Player"")&"" playe"&"rs · ""&COUNTUNIQUE(FILTER('01_Player_Rate_Card'!$F$5:$F$500,'01_Player_Rate_Card'!$F$5:$F$500<>""""))&"" teams · Confidential — Internal Use Only"""),"Total Talent: 189 entries across 23 games · 131 players · 21 teams · Confidential — Internal Use Only") -> Total Talent: 189 entries across 23 games · 131 players · 21 teams · Confidential — Internal Use Only
B10: =COUNTA('01_Player_Rate_Card'!$C$5:$C$500) -> 189 | D10: =COUNTIF('01_Player_Rate_Card'!$D$5:$D$500,"Player") -> 131 | F10: =COUNTIF('01_Player_Rate_Card'!$D$5:$D$500,"Influencer") -> 8 | H10: =COUNTA('01_Player_Rate_Card'!$C$5:$C$500)-COUNTIF('01_Player_Rate_Card'!$D$5:$D$500,"Player")-COUNTIF('01_Player_Rate_Card'!$D$5:$D$500,"Influencer") -> 50 | J10: =COUNTIF('01_Player_Rate_Card'!$I$5:$I$500,"Tier 1")&"/"&COUNTIF('01_Player_Rate_Card'!$I$5:$I$500,"Tier 2")&"/"&COUNTIF('01_Player_Rate_Card'!$I$5:$I$500,"Tier 3") -> 10/71/71
B11: Total Entries | D11: Players | F11: Esports Influencers | H11: Staff & Coaches | J11: T1 / T2 / T3
B13: SHEET NAVIGATION
B14: 01_Player_Rate_Card | D14: ="All "&COUNTA('01_Player_Rate_Card'!$C$5:$C$500)&" entries · rates per platform · filterable by role/game/team/tier" -> All 189 entries · rates per platform · filterable by role/game/team/tier
B15: 02_Adjustment_Matrix | D15: Engagement · Audience · Seasonality multipliers + Live Calculator
B16: 03_Add_On_Rights | D16: Rights packages with uplift % + bundle presets
B18: 05_Guide_EN | D18: Pricing methodology, formula, best practices (English)
B19: 06_Guide_AR | D19: دليل التسعير الكامل بالعربي
B20: COLOR LEGEND | D20: 1M+ followers · 8%+ engagement · World-class talent
B21: Tier 1 — Premium | D21: 100K–1M followers · 5–8% engagement · Established
B22: Tier 2 — Target | D22: 10K–100K followers · High engagement · Rising stars
B23: Tier 3 — Emerging | D23: Coaching staff — rates apply for appearances & content
B24: Coach / Head Coach | D24: Management staff — rates apply for appearances
B25: Manager | D25: Analyst staff — rates apply for appearances
B26: Analyst

Sheet QT_Template
B2: TEAM FALCONS | E2: Prepared by: | F2: —
E3: Approved by: | F3: —
E4: Date: | F4: {{DATE}}
E5: Quote #: | F5: {{QUOTE_ID}}
E6: Client: | F6: {{CLIENT}}
E7: Currency: | F7: SAR
B12: QUOTE LINE ITEMS
B13: Description | C13: Unit Cost (SAR) | D13: Qty | E13: Amount (SAR)
B14: — (line 1) — | C14: 0 | D14: 1 | E14: =C14*D14 -> 0
B15: — (line 2) — | C15: 0 | D15: 1 | E15: =C15*D15 -> 0
B16: — (line 3) — | C16: 0 | D16: 1 | E16: =C16*D16 -> 0
B17: — (line 4) — | C17: 0 | D17: 1 | E17: =C17*D17 -> 0
B18: — (line 5) — | C18: 0 | D18: 1 | E18: =C18*D18 -> 0
B19: — (line 6) — | C19: 0 | D19: 1 | E19: =C19*D19 -> 0
B20: — (line 7) — | C20: 0 | D20: 1 | E20: =C20*D20 -> 0
B21: Special notes and instructions: | D21: SUBTOTAL | E21: =SUM(E14:E20) -> 0
B22: {{CLIENT_NOTES}} | D22: (TAX RATE) | E22: 0.15
D23: TAX | E23: =E21*E22 -> 0
D25: TOTAL | E25: =E21+E23 -> 0
B28: PRICING MULTIPLIERS (9-AXIS MATRIX)
B29: Multiplier | C29: Selected Value | D29: Factor | E29: Impact
B30: ① Content Type | C30: {{CONTENT}} | D30: 1 | E30: — Baseline
B31: ② Engagement Rate | C31: {{ENGAGEMENT}} | D31: 1 | E31: — Baseline
B32: ③ Audience Quality | C32: {{AUDIENCE}} | D32: 1 | E32: — Baseline
B33: ④ Seasonality | C33: {{SEASONALITY}} | D33: 1 | E33: — Baseline
B34: ⑤ Language | C34: {{LANGUAGE}} | D34: 1 | E34: — Baseline
B35: ⑥ Authority Level | C35: {{AUTHORITY}} | D35: 1 | E35: — Baseline
B36: ⑦ Campaign Objective | C36: {{CAMPAIGN}} | D36: 1 | E36: — Baseline
B37: COMBINED PRICE MULTIPLIER | D37: =PRODUCT(D30:D36) -> 1 | E37: Applied to Base Fee
B40: Formula: Base Fee × Combined Multiplier + Add-Ons → Subtotal → TAX → TOTAL | Authority Floor = IRL × FloorShare × Seasonality × Language × AuthorityFactor
B42: King Abdulaziz Road, Riyadh 11564, Saudi Arabia · contact@teamfalcons.com
B43: [INTERNAL] FMG: 30% commission baseline. Authority Floor enforced per Methodology §3.

Sheet 07_Settings
A1: A (Key) | B1: B (Value)
A2: output_folder_id | B2: (Drive folder ID where PDFs go)
A3: legal_approver_email | B3: legal@…
A4: finance_approver_email | B4: finance@…
A5: client_email | B5: (optional default)
A6: approval_secret | B6: (any random word like falcons2026)
A8: TIER DEFAULTS TABLE
A9: Tier | B9: Label | C9: Follower Threshold | D9: Base Fee Min (SAR) | E9: Base Fee Max (SAR) | F9: Floor Share % | G9: Notes
A10: Tier S | B10: Superstar | C10: >1M on any platform | D10: 40000 | E10: 50000 | F10: 0.65 | G10: Global anchors — premium brand deals
A11: Tier 1 | B11: Star | C11: 250K–1M | D11: 22000 | E11: 30000 | F11: 0.55 | G11: Core pro athletes with notable reach
A12: Tier 2 | B12: Core Influencer | C12: 50K–250K | D12: 11000 | E12: 18000 | F12: 0.45 | G12: Active pros + mid-tier creators
A13: Tier 3 | B13: Rising | C13: 10K–50K | D13: 6500 | E13: 10000 | F13: 0.35 | G13: Emerging talent + niche specialists
A14: Tier 4 | B14: Entry / Staff | C14: <10K or staff | D14: 3000 | E14: 5500 | F14: 0.25 | G14: Support roles + developing roster
A17: MEASUREMENT CONFIDENCE LEVELS
A18: Level | B18: Trigger | C18: Premium Multipliers Allowed?
A19: exact | B19: Verified via Shikenso or direct platform API | C19: Yes — all multipliers available
A20: rounded | B20: Manual verification with clean round numbers | C20: Yes — all multipliers available
A21: estimated | B21: Partial data, public research, single-source | C21: Limited — engagement <1.2x, authority <1.3x
A22: pending | B22: No follower data yet | C22: No — default 1.0x multipliers only
A24: AUTHORITY FLOOR FORMULA
A25: Authority Floor = IRL Fee × Floor Share × Seasonality × Language × Authority Factor
A26: Final Price = MAX(Social Price, Authority Floor) × (1 + Add-on Rights %)

Sheet 01_Player_Rate_Card
B2: ="TALENT RATE CARD — ALL "&COUNTA($C$5:$C$500)&" ENTRIES" -> TALENT RATE CARD — ALL 189 ENTRIES | AO2: FOLLOWERS / SUBSCRIBERS ← enter real numbers here | AV2: CPM (SAR) ← auto-calculated | IG 20% reach · TikTok 30% · Twitter 10% · YouTube 25% · Twitch 100% | BA2: AUTHORITY FLOOR + CONFIDENCE LAYER ← new v8 engine
A3: ROLE LEGEND | B3: ● Player | C3: ● Head Coach | D3: ● Coach | E3: ● Manager | F3: ● Analyst | G3: ● Influencer | H3: ● Coach
B4: # | C4: Nickname | D4: Role | E4: Game | F4: Team | G4: Nationality | H4: Platforms | I4: Tier | J4: IG Reel (SAR) | K4: IG Static (SAR) | L4: IG Story (SAR) | M4: TikTok Video | N4: YT Short (SAR) | O4: X Post (SAR) | P4: FB Post/Video (SAR) | Q4: Twitch Stream 2h | R4: Twitch Integ. | S4: IRL / Appear. | T4: Rights Fee | U4: Exclusivity Fee | V4: Rush Fee | W4: WL Fee | X4: Notes | Y4: Falcons Commission % | Z4: Markup % (on Player Cost) | AA4: Full Name | AB4: X / Twitter | AC4: Instagram | AD4: Twitch | AE4: YouTube | AF4: TikTok | AG4: Kick | AH4: Facebook | AI4: Snapchat | AJ4: Link-in-Bio | AK4: Date of Birth | AL4: Game Role | AO4: Twitter Followers | AP4: Instagram Followers | AQ4: Twitch Followers | AR4: YouTube Subs | AS4: TikTok Followers | AT4: Kick Followers | AU4: Facebook Followers | AV4: IG CPM (SAR) | AW4: TikTok CPM (SAR) | AX4: Twitter CPM (SAR) | AY4: YouTube CPM (SAR) | AZ4: Twitch CPM (SAR) | BA4: Floor Share % | BB4: Authority Factor | BC4: Default Seasonality | BD4: Default Language | BE4: Authority Floor Baseline (SAR) | BF4: Measurement Confidence | BG4: Tier Review Flag
B5: =IF($C5="","",COUNTA($C$5:C5)) -> 1 | C5: Bijw | D5: Influencer | E5: Esports Influencers | F5: Esports Influencers | G5: Saudi Arabia | H5: 6 | I5: Tier 3 | J5: 11000 | K5: 4600 | L5: =IF($C5="","",ROUND($J5*0.17,0)) -> 1870 | M5: 8600 | N5: 3500 | O5: 2200 | P5: 2200 | Q5: 15950 | R5: 7150 | S5: =IF($C5="","",ROUND($J5*2.2,0)) -> 24200 | T5: 3850 | U5: 3300 | V5: 2000 | W5: 1650 | X5: 6 platforms | Y5: 0.3 | Z5: 1 | AA5: Hisham Nasser | AB5: https://x.com/_bijw | AC5: https://www.instagram.com/bijjw | AD5: https://www.twitch.tv/bijw | AE5: https://www.youtube.com/@Bijw | AF5: https://www.tiktok.com/@biijw | AG5: https://kick.com/bijw | AI5: https://www.snapchat.com/add/bijjw | AJ5: https://linktr.ee/bijw | AV5: =IF(AND(AP5>0,J5>0),J5*1000/(AP5*0.2),"") | AW5: =IF(AND(AS5>0,M5>0),M5*1000/(AS5*0.3),"") | AX5: =IF(AND(AO5>0,O5>0),O5*1000/(AO5*0.1),"") | AY5: =IF(AND(AR5>0,N5>0),N5*1000/(AR5*0.25),"") | AZ5: =IF(AND(AQ5>0,Q5>0),Q5*1000/(AQ5*1),"") | BA5: =IFERROR(VLOOKUP($I5,'07_Settings'!$A$10:$F$14,6,FALSE()),0.25) -> 0.35 | BB5: 1 | BC5: 1 | BD5: 1 | BE5: =IFERROR(ROUND($S5*BA5*BC5*BD5*BB5,0),0) -> 8470 | BF5: =IF(COUNT(AO5:AU5)>0,"estimated","pending") -> pending
B6: =IF($C6="","",COUNTA($C$5:C6)) -> 2 | C6: Abo Najd | D6: Influencer | E6: Esports Influencers | F6: Esports Influencers | G6: Saudi Arabia | H6: 4 | I6: Tier 3 | J6: 8100 | K6: 3200 | L6: =IF($C6="","",ROUND($J6*0.17,0)) -> 1377 | M6: 6350 | N6: 2600 | O6: 1600 | P6: 1600 | Q6: 11800 | R6: 5300 | S6: =IF($C6="","",ROUND($J6*2.2,0)) -> 17820 | T6: 2850 | U6: 2450 | V6: 1450 | W6: 1215 | X6: 4 platforms | Y6: 0.3 | Z6: 1 | AA6: Riyad Alfahmi | AB6: https://x.com/K22N8 | AC6: https://www.instagram.com/k2nn8?igsh=ajJsNHoybDlpMzFo | AD6: https://www.twitch.tv/k2nnn8 | AE6: https://www.youtube.com/@k2nn8 | AJ6: https://linktr.ee/K2nnn8 (alt: https://heylink.me/k2nn8) | AV6: =IF(AND(AP6>0,J6>0),J6*1000/(AP6*0.2),"") | AW6: =IF(AND(AS6>0,M6>0),M6*1000/(AS6*0.3),"") | AX6: =IF(AND(AO6>0,O6>0),O6*1000/(AO6*0.1),"") | AY6: =IF(AND(AR6>0,N6>0),N6*1000/(AR6*0.25),"") | AZ6: =IF(AND(AQ6>0,Q6>0),Q6*1000/(AQ6*1),"") | BA6: =IFERROR(VLOOKUP($I6,'07_Settings'!$A$10:$F$14,6,FALSE()),0.25) -> 0.35 | BB6: 1 | BC6: 1 | BD6: 1 | BE6: =IFERROR(ROUND($S6*BA6*BC6*BD6*BB6,0),0) -> 6237 | BF6: =IF(COUNT(AO6:AU6)>0,"estimated","pending") -> pending
B7: =IF($C7="","",COUNTA($C$5:C7)) -> 3 | C7: FMG | D7: Influencer | E7: Esports Influencers | F7: Esports Influencers | G7: Saudi Arabia | H7: 4 | I7: Tier 3 | J7: 7450 | K7: 3150 | L7: =IF($C7="","",ROUND($J7*0.17,0)) -> 1267 | M7: 5850 | N7: 2400 | O7: 1500 | P7: 1500 | Q7: 10850 | R7: 4850 | S7: =IF($C7="","",ROUND($J7*2.2,0)) -> 16390 | T7: 2600 | U7: 2250 | V7: 1350 | W7: 1118 | X7: 4 platforms | Y7: 0.3 | Z7: 1 | AA7: Nasser alotaibi | AB7: https://x.com/iFMG_ | AC7: https://www.instagram.com/fm.g/ | AD7: https://www.twitch.tv/fmg_ | AG7: https://kick.com/ifmg | AO7: 4792 | AP7: 4080 | AV7: =IF(AND(AP7>0,J7>0),J7*1000/(AP7*0.2),"") -> 9129.902 | AW7: =IF(AND(AS7>0,M7>0),M7*1000/(AS7*0.3),"") | AX7: =IF(AND(AO7>0,O7>0),O7*1000/(AO7*0.1),"") -> 3130.217 | AY7: =IF(AND(AR7>0,N7>0),N7*1000/(AR7*0.25),"") | AZ7: =IF(AND(AQ7>0,Q7>0),Q7*1000/(AQ7*1),"") | BA7: =IFERROR(VLOOKUP($I7,'07_Settings'!$A$10:$F$14,6,FALSE()),0.25) -> 0.35 | BB7: 1 | BC7: 1 | BD7: 1 | BE7: =IFERROR(ROUND($S7*BA7*BC7*BD7*BB7,0),0) -> 5737 | BF7: =IF(COUNT(AO7:AU7)>0,"estimated","pending") -> estimated
B8: =IF($C8="","",COUNTA($C$5:C8)) -> 4 | C8: Abo Ghazi | D8: Influencer | E8: Esports Influencers | F8: Esports Influencers | G8: Saudi Arabia | H8: 3 | I8: Tier 3 | J8: 5200 | K8: 2200 | L8: =IF($C8="","",ROUND($J8*0.17,0)) -> 884 | M8: 4050 | N8: 1650 | O8: 1050 | P8: 1050 | Q8: 7550 | R8: 3400 | S8: =IF($C8="","",ROUND($J8*2.2,0)) -> 11440 | T8: 1800 | U8: 1550 | V8: 950 | W8: 780 | X8: 3 platforms | Y8: 0.3 | Z8: 1 | AA8: Mohammed Albaqami | AB8: https://x.com/MohxamedZ | AD8: https://www.twitch.tv/ires | AG8: https://kick.com/iabughazi | AH8: https://www.facebook.com/AbuGhaziGaming93 | AI8: https://www.snapchat.com/add/faisalhajhasan | AJ8: https://linktr.ee/abughaazi | AV8: =IF(AND(AP8>0,J8>0),J8*1000/(AP8*0.2),"") | AW8: =IF(AND(AS8>0,M8>0),M8*1000/(AS8*0.3),"") | AX8: =IF(AND(AO8>0,O8>0),O8*1000/(AO8*0.1),"") | AY8: =IF(AND(AR8>0,N8>0),N8*1000/(AR8*0.25),"") | AZ8: =IF(AND(AQ8>0,Q8>0),Q8*1000/(AQ8*1),"") | BA8: =IFERROR(VLOOKUP($I8,'07_Settings'!$A$10:$F$14,6,FALSE()),0.25) -> 0.35 | BB8: 1 | BC8: 1 | BD8: 1 | BE8: =IFERROR(ROUND($S8*BA8*BC8*BD8*BB8,0),0) -> 4004 | BF8: =IF(COUNT(AO8:AU8)>0,"estimated","pending") -> pending
B9: =IF($C9="","",COUNTA($C$5:C9)) -> 5 | C9: Mary | D9: Influencer | E9: Esports Influencers | F9: Esports Influencers | G9: Bahraini | H9: 5 | I9: Tier 2 | J9: 8100 | K9: 3400 | L9: =IF($C9="","",ROUND($J9*0.17,0)) -> 1377 | M9: 6350 | N9: 2600 | O9: 1600 | P9: 1600 | Q9: 11800 | R9: 5300 | S9: =IF($C9="","",ROUND($J9*2.2,0)) -> 17820 | T9: 2850 | U9: 2450 | V9: 1450 | W9: 1215 | X9: 5 platforms | Y9: 0.3 | Z9: 1 | AA9: Maryam Maher | AB9: https://x.com/marypink | AC9: https://www.instagram.com/maryvalorantt/?hl=en | AD9: https://www.twitch.tv/mary | AE9: https://www.youtube.com/@maryvalorant/featured | AF9: https://www.tiktok.com/@maryvalorant | AJ9: https://linktr.ee/verymarygaming | AP9: 67000 | AV9: =IF(AND(AP9>0,J9>0),J9*1000/(AP9*0.2),"") -> 604.47761 | AW9: =IF(AND(AS9>0,M9>0),M9*1000/(AS9*0.3),"") | AX9: =IF(AND(AO9>0,O9>0),O9*1000/(AO9*0.1),"") | AY9: =IF(AND(AR9>0,N9>0),N9*1000/(AR9*0.25),"") | AZ9: =IF(AND(AQ9>0,Q9>0),Q9*1000/(AQ9*1),"") | BA9: =IFERROR(VLOOKUP($I9,'07_Settings'!$A$10:$F$14,6,FALSE()),0.25) -> 0.45 | BB9: 1 | BC9: 1 | BD9: 1 | BE9: =IFERROR(ROUND($S9*BA9*BC9*BD9*BB9,0),0) -> 8019 | BF9: =IF(COUNT(AO9:AU9)>0,"estimated","pending") -> estimated
B10: =IF($C10="","",COUNTA($C$5:C10)) -> 6 | C10: Ghala | D10: Influencer | E10: Esports Influencers | F10: Esports Influencers | G10: Saudi Arabia | H10: 5 | I10: Tier 3 | J10: 7450 | K10: 3150 | L10: =IF($C10="","",ROUND($J10*0.17,0)) -> 1267 | M10: 5850 | N10: 2400 | O10: 1500 | P10: 1500 | Q10: 10850 | R10: 4850 | S10: =IF($C10="","",ROUND($J10*2.2,0)) -> 16390 | T10: 2600 | U10: 2250 | V10: 1350 | W10: 1118 | X10: 5 platforms | Y10: 0.3 | Z10: 1 | AA10: Ghala Alqahtani | AB10: https://x.com/pg_ghala3?lang=en | AC10: https://www.instagram.com/pg_ghala3 | AE10: https://www.youtube.com/@pg_ghala3 | AF10: https://www.tiktok.com/@pg_ghala3 | AG10: https://kick.com/pg-ghala3 | AI10: https://snapchat.com/t/bLA2ZOsG | AJ10: https://linktr.ee/ga1lll | AV10: =IF(AND(AP10>0,J10>0),J10*1000/(AP10*0.2),"") | AW10: =IF(AND(AS10>0,M10>0),M10*1000/(AS10*0.3),"") | AX10: =IF(AND(AO10>0,O10>0),O10*1000/(AO10*0.1),"") | AY10: =IF(AND(AR10>0,N10>0),N10*1000/(AR10*0.25),"") | AZ10: =IF(AND(AQ10>0,Q10>0),Q10*1000/(AQ10*1),"") | BA10: =IFERROR(VLOOKUP($I10,'07_Settings'!$A$10:$F$14,6,FALSE()),0.25) -> 0.35 | BB10: 1 | BC10: 1 | BD10: 1 | BE10: =IFERROR(ROUND($S10*BA10*BC10*BD10*BB10,0),0) -> 5737 | BF10: =IF(COUNT(AO10:AU10)>0,"estimated","pending") -> pending
B11: =IF($C11="","",COUNTA($C$5:C11)) -> 7 | C11: Moaz | D11: Influencer | E11: Esports Influencers | F11: Esports Influencers | G11: Saudi Arabia | H11: 5 | I11: Tier 2 | J11: 6500 | K11: 5300 | L11: =IF($C11="","",ROUND($J11*0.17,0)) -> 1105 | M11: 3400 | N11: 4050 | O11: 2500 | P11: 2500 | Q11: 15950 | R11: 8200 | S11: =IF($C11="","",ROUND($J11*2.2,0)) -> 14300 | T11: 3800 | U11: 1900 | V11: 3150 | W11: 1250 | X11: 5 platforms | Y11: 0.3 | Z11: 1 | AA11: Moaz Asiri | AB11: https://x.com/mezostrong?s=21 | AC11: https://www.instagram.com/mezostrong | AE11: https://www.youtube.com/channel/UCZCgW8WW8K_vrHrO6sZ7oyg?app=desktop | AF11: https://www.tiktok.com/@mezostrong?_r=1&_t=zs-91bbrrsefwl | AG11: https://kick.com/MezoStrong | AV11: =IF(AND(AP11>0,J11>0),J11*1000/(AP11*0.2),"") | AW11: =IF(AND(AS11>0,M11>0),M11*1000/(AS11*0.3),"") | AX11: =IF(AND(AO11>0,O11>0),O11*1000/(AO11*0.1),"") | AY11: =IF(AND(AR11>0,N11>0),N11*1000/(AR11*0.25),"") | AZ11: =IF(AND(AQ11>0,Q11>0),Q11*1000/(AQ11*1),"") | BA11: =IFERROR(VLOOKUP($I11,'07_Settings'!$A$10:$F$14,6,FALSE()),0.25) -> 0.45 | BB11: 1 | BC11: 1 | BD11: 1 | BE11: =IFERROR(ROUND($S11*BA11*BC11*BD11*BB11,0),0) -> 6435 | BF11: =IF(COUNT(AO11:AU11)>0,"estimated","pending") -> pending
B12: =IF($C12="","",COUNTA($C$5:C12)) -> 8 | C12: vacwep | D12: Influencer | E12: Esports Influencers | F12: Esports Influencers | G12: Saudi Arabia | H12: 5 | I12: Tier 3 | J12: 7450 | K12: 3150 | L12: =IF($C12="","",ROUND($J12*0.17,0)) -> 1267 | M12: 5800 | N12: 2400 | O12: 1500 | P12: 1500 | Q12: 7500 | R12: 4850 | S12: =IF($C12="","",ROUND($J12*2.2,0)) -> 16390 | T12: 2250 | U12: 1100 | V12: 1850 | W12: 750 | X12: 5 platforms | Y12: 0.3 | Z12: 1 | AA12: Abdullah Mousa A Alsulaymi | AB12: https://x.com/vacwep?s=21&t=PiVx0_LPZgUm0TT5Ok_2Zw | AC12: https://www.instagram.com/vacwep_?igsh=Z28yMXRibTZ0OWlm&utm_source=qr | AF12: https://www.tiktok.com/@vacwep?_r=1&_t=ZS-94jrcxtNGEK | AG12: https://kick.com/vacwep | AH12: https://www.facebook.com/share/1BDLRfGMFS/?mibextid=wwXIfr | AK12: 12/07/1992 | AV12: =IF(AND(AP12>0,J12>0),J12*1000/(AP12*0.2),"") | AW12: =IF(AND(AS12>0,M12>0),M12*1000/(AS12*0.3),"") | AX12: =IF(AND(AO12>0,O12>0),O12*1000/(AO12*0.1),"") | AY12: =IF(AND(AR12>0,N12>0),N12*1000/(AR12*0.25),"") | AZ12: =IF(AND(AQ12>0,Q12>0),Q12*1000/(AQ12*1),"") | BA12: =IFERROR(VLOOKUP($I12,'07_Settings'!$A$10:$F$14,6,FALSE()),0.25) -> 0.35 | BB12: 1 | BC12: 1 | BD12: 1 | BE12: =IFERROR(ROUND($S12*BA12*BC12*BD12*BB12,0),0) -> 5737 | BF12: =IF(COUNT(AO12:AU12)>0,"estimated","pending") -> pending
B13: =IF($C13="","",COUNTA($C$5:C13)) -> 9 | C13: Cellium | D13: Player | E13: Call of Duty Black Ops 7 | F13: Riyadh Falcons | G13: American | H13: 3 | I13: Tier 1 | J13: 11250 | K13: 4500 | L13: =IF($C13="","",ROUND($J13*0.17,0)) -> 1913 | M13: 8000 | N13: 3500 | O13: 2000 | P13: 2000 | Q13: 13500 | R13: 6075 | S13: =IF($C13="","",ROUND($J13*2.2,0)) -> 24750 | T13: 4638 | U13: 4063 | V13: 2438 | W13: 2400 | X13: 3 platforms | Y13: 0.3 | Z13: 1 | AA13: McArthur Jovel | AB13: https://twitter.com/Cellium | AC13: https://www.instagram.com/cellium/ | AD13: https://www.twitch.tv/Cellium | AK13: 24/12/2000 | AL13: Assault Rifle / Main AR | AO13: 130000 | AP13: 38000 | AQ13: 105230 | AV13: =IF(AND(AP13>0,J13>0),J13*1000/(AP13*0.2),"") -> 1480.2632 | AW13: =IF(AND(AS13>0,M13>0),M13*1000/(AS13*0.3),"") | AX13: =IF(AND(AO13>0,O13>0),O13*1000/(AO13*0.1),"") -> 153.84615 | AY13: =IF(AND(AR13>0,N13>0),N13*1000/(AR13*0.25),"") | AZ13: =IF(AND(AQ13>0,Q13>0),Q13*1000/(AQ13*1),"") -> 128.29041 | BA13: =IFERROR(VLOOKUP($I13,'07_Settings'!$A$10:$F$14,6,FALSE()),0.25) -> 0.55 | BB13: 1 | BC13: 1 | BD13: 1 | BE13: =IFERROR(ROUND($S13*BA13*BC13*BD13*BB13,0),0) -> 13613 | BF13: =IF(COUNT(AO13:AU13)>0,"estimated","pending") -> estimated
B14: =IF($C14="","",COUNTA($C$5:C14)) -> 10 | C14: Exnid | D14: Player | E14: Call of Duty Black Ops 7 | F14: Riyadh Falcons | G14: Saudi Arabia | H14: 2 | I14: Tier 2 | J14: 11000 | K14: 4600 | L14: =IF($C14="","",ROUND($J14*0.17,0)) -> 1870 | M14: 8600 | N14: 3500 | O14: 2200 | P14: 2200 | Q14: 15950 | R14: 7150 | S14: =IF($C14="","",ROUND($J14*2.2,0)) -> 24200 | T14: 3850 | U14: 3300 | V14: 2000 | W14: 2400 | X14: 2 platforms | Y14: 0.3 | Z14: 1 | AA14: Saud Alati | AB14: https://x.com/Exnid_ | AD14: https://www.twitch.tv/exnid | AK14: 28/10/2002 | AL14: Sub-Machine Gun (SMG) | AO14: 36000 | AQ14: 63000 | AV14: =IF(AND(AP14>0,J14>0),J14*1000/(AP14*0.2),"") | AW14: =IF(AND(AS14>0,M14>0),M14*1000/(AS14*0.3),"") | AX14: =IF(AND(AO14>0,O14>0),O14*1000/(AO14*0.1),"") -> 611.11111 | AY14: =IF(AND(AR14>0,N14>0),N14*1000/(AR14*0.25),"") | AZ14: =IF(AND(AQ14>0,Q14>0),Q14*1000/(AQ14*1),"") -> 253.1746 | BA14: =IFERROR(VLOOKUP($I14,'07_Settings'!$A$10:$F$14,6,FALSE()),0.25) -> 0.45 | BB14: 1 | BC14: 1 | BD14: 1 | BE14: =IFERROR(ROUND($S14*BA14*BC14*BD14*BB14,0),0) -> 10890 | BF14: =IF(COUNT(AO14:AU14)>0,"estimated","pending") -> estimated
B15: =IF($C15="","",COUNTA($C$5:C15)) -> 11 | C15: KiSMET | D15: Player | E15: Call of Duty Black Ops 7 | F15: Riyadh Falcons | G15: American | H15: 3 | I15: Tier 3 | J15: 12100 | K15: 5100 | L15: =IF($C15="","",ROUND($J15*0.17,0)) -> 2057 | M15: 9450 | N15: 3850 | O15: 2400 | P15: 2400 | Q15: 17550 | R15: 7850 | S15: =IF($C15="","",ROUND($J15*2.2,0)) -> 26620 | T15: 4250 | U15: 3650 | V15: 2200 | W15: 2400 | X15: 3 platforms | Y15: 0.3 | Z15: 1 | AA15: Matthew Tinsley | AB15: https://twitter.com/KiSMET6_ | AC15: https://www.instagram.com/kismet6_ | AD15: https://www.twitch.tv/kismet6_ | AK15: 36475 | AL15: Assault Rifle / Flex | AO15: 48000 | AP15: 3677 | AQ15: 39000 | AV15: =IF(AND(AP15>0,J15>0),J15*1000/(AP15*0.2),"") -> 16453.631 | AW15: =IF(AND(AS15>0,M15>0),M15*1000/(AS15*0.3),"") | AX15: =IF(AND(AO15>0,O15>0),O15*1000/(AO15*0.1),"") -> 500 | AY15: =IF(AND(AR15>0,N15>0),N15*1000/(AR15*0.25),"") | AZ15: =IF(AND(AQ15>0,Q15>0),Q15*1000/(AQ15*1),"") -> 450 | BA15: =IFERROR(VLOOKUP($I15,'07_Settings'!$A$10:$F$14,6,FALSE()),0.25) -> 0.35 | BB15: 1 | BC15: 1 | BD15: 1 | BE15: =IFERROR(ROUND($S15*BA15*BC15*BD15*BB15,0),0) -> 9317 | BF15: =IF(COUNT(AO15:AU15)>0,"estimated","pending") -> estimated
B16: =IF($C16="","",COUNTA($C$5:C16)) -> 12 | C16: Pred | D16: Player | E16: Call of Duty Black Ops 7 | F16: Riyadh Falcons | G16: American | H16: 3 | I16: Tier 1 | J16: 11000 | K16: 4600 | L16: =IF($C16="","",ROUND($J16*0.17,0)) -> 1870 | M16: 8600 | N16: 3500 | O16: 2200 | P16: 2200 | Q16: 15950 | R16: 7150 | S16: =IF($C16="","",ROUND($J16*2.2,0)) -> 24200 | T16: 3850 | U16: 3300 | V16: 2000 | W16: 2400 | X16: 3 platforms | Y16: 0.3 | Z16: 1 | AA16: Amer Zulbeari | AB16: https://x.com/Pred | AC16: https://www.instagram.com/amerzulbeariii | AD16: https://www.twitch.tv/pred | AK16: 19/08/2001 | AL16: Sub-Machine Gun (SMG) | AO16: 138000 | AP16: 37000 | AQ16: 174000 | AV16: =IF(AND(AP16>0,J16>0),J16*1000/(AP16*0.2),"") -> 1486.4865 | AW16: =IF(AND(AS16>0,M16>0),M16*1000/(AS16*0.3),"") | AX16: =IF(AND(AO16>0,O16>0),O16*1000/(AO16*0.1),"") -> 159.42029 | AY16: =IF(AND(AR16>0,N16>0),N16*1000/(AR16*0.25),"") | AZ16: =IF(AND(AQ16>0,Q16>0),Q16*1000/(AQ16*1),"") -> 91.666667 | BA16: =IFERROR(VLOOKUP($I16,'07_Settings'!$A$10:$F$14,6,FALSE()),0.25) -> 0.55 | BB16: 1 | BC16: 1 | BD16: 1 | BE16: =IFERROR(ROUND($S16*BA16*BC16*BD16*BB16,0),0) -> 13310 | BF16: =IF(COUNT(AO16:AU16)>0,"estimated","pending") -> estimated
B17: =IF($C17="","",COUNTA($C$5:C17)) -> 13 | C17: KingAbody | D17: Player | E17: Call of Duty Black Ops 7 | F17: FaZe Falcons | G17: Saudi Arabia | H17: 1 | I17: Tier 3 | J17: 11000 | K17: 4600 | L17: =IF($C17="","",ROUND($J17*0.17,0)) -> 1870 | M17: 8600 | N17: 3500 | O17: 2200 | P17: 2200 | Q17: 15950 | R17: 7150 | S17: =IF($C17="","",ROUND($J17*2.2,0)) -> 24200 | T17: 3850 | U17: 3300 | V17: 2000 | W17: 2400 | X17: 1 platform | Y17: 0.3 | Z17: 1 | AA17: Abdulelah Alrajhi | AB17: https://x.com/KingAbody_ | AK17: 36679 | AL17: Sub-Machine Gun (SMG) | AO17: 6000 | AV17: =IF(AND(AP17>0,J17>0),J17*1000/(AP17*0.2),"") | AW17: =IF(AND(AS17>0,M17>0),M17*1000/(AS17*0.3),"") | AX17: =IF(AND(AO17>0,O17>0),O17*1000/(AO17*0.1),"") -> 3666.6667 | AY17: =IF(AND(AR17>0,N17>0),N17*1000/(AR17*0.25),"") | AZ17: =IF(AND(AQ17>0,Q17>0),Q17*1000/(AQ17*1),"") | BA17: =IFERROR(VLOOKUP($I17,'07_Settings'!$A$10:$F$14,6,FALSE()),0.25) -> 0.35 | BB17: 1 | BC17: 1 | BD17: 1 | BE17: =IFERROR(ROUND($S17*BA17*BC17*BD17*BB17,0),0) -> 8470 | BF17: =IF(COUNT(AO17:AU17)>0,"estimated","pending") -> estimated
B18: =IF($C18="","",COUNTA($C$5:C18)) -> 14 | C18: Arcitys | D18: Player | E18: Call of Duty Black Ops 7 | F18: Falcons Academy White | G18: American | H18: 3 | I18: Tier 1 | J18: 12100 | K18: 5100 | L18: =IF($C18="","",ROUND($J18*0.17,0)) -> 2057 | M18: 9450 | N18: 3850 | O18: 2400 | P18: 2400 | Q18: 17550 | R18: 7850 | S18: =IF($C18="","",ROUND($J18*2.2,0)) -> 26620 | T18: 4250 | U18: 3650 | V18: 2200 | W18: 2400 | X18: 3 platforms | Y18: 0.3 | Z18: 1 | AA18: Alec Sanderson | AB18: https://x.com/Arcitys | AC18: https://www.instagram.com/arcitys9 | AD18: https://www.twitch.tv/arcitys | AK18: 36045 | AL18: Assault Rifle / Main AR | AO18: 192000 | AP18: 25000 | AQ18: 140000 | AV18: =IF(AND(AP18>0,J18>0),J18*1000/(AP18*0.2),"") -> 2420 | AW18: =IF(AND(AS18>0,M18>0),M18*1000/(AS18*0.3),"") | AX18: =IF(AND(AO18>0,O18>0),O18*1000/(AO18*0.1),"") -> 125 | AY18: =IF(AND(AR18>0,N18>0),N18*1000/(AR18*0.25),"") | AZ18: =IF(AND(AQ18>0,Q18>0),Q18*1000/(AQ18*1),"") -> 125.35714 | BA18: =IFERROR(VLOOKUP($I18,'07_Settings'!$A$10:$F$14,6,FALSE()),0.25) -> 0.55 | BB18: 1 | BC18: 1 | BD18: 1 | BE18: =IFERROR(ROUND($S18*BA18*BC18*BD18*BB18,0),0) -> 14641 | BF18: =IF(COUNT(AO18:AU18)>0,"estimated","pending") -> estimated
B19: =IF($C19="","",COUNTA($C$5:C19)) -> 15 | C19: Paulehx | D19: Player | E19: Call of Duty Black Ops 7 | F19: Falcons Academy White | G19: American | H19: 2 | I19: Tier 3 | J19: 11000 | K19: 4600 | L19: =IF($C19="","",ROUND($J19*0.17,0)) -> 1870 | M19: 8600 | N19: 3500 | O19: 2200 | P19: 2200 | Q19: 15950 | R19: 7150 | S19: =IF($C19="","",ROUND($J19*2.2,0)) -> 24200 | T19: 3850 | U19: 3300 | V19: 2000 | W19: 2400 | X19: 2 platforms | Y19: 0.3 | Z19: 1 | AA19: Paul Avila | AB19: https://x.com/Paulehx_ | AD19: https://www.twitch.tv/paulehx | AK19: 21/01/2002 | AL19: Assault Rifle / Flex | AO19: 19000 | AV19: =IF(AND(AP19>0,J19>0),J19*1000/(AP19*0.2),"") | AW19: =IF(AND(AS19>0,M19>0),M19*1000/(AS19*0.3),"") | AX19: =IF(AND(AO19>0,O19>0),O19*1000/(AO19*0.1),"") -> 1157.8947 | AY19: =IF(AND(AR19>0,N19>0),N19*1000/(AR19*0.25),"") | AZ19: =IF(AND(AQ19>0,Q19>0),Q19*1000/(AQ19*1),"") | BA19: =IFERROR(VLOOKUP($I19,'07_Settings'!$A$10:$F$14,6,FALSE()),0.25) -> 0.35 | BB19: 1 | BC19: 1 | BD19: 1 | BE19: =IFERROR(ROUND($S19*BA19*BC19*BD19*BB19,0),0) -> 8470 | BF19: =IF(COUNT(AO19:AU19)>0,"estimated","pending") -> estimated
B20: =IF($C20="","",COUNTA($C$5:C20)) -> 16 | C20: hmoodx | D20: Player | E20: Call of Duty Warzone | F20: Team Falcons MENA | G20: Saudi Arabia | H20: 2 | I20: Tier 3 | J20: 11000 | K20: 4600 | L20: =IF($C20="","",ROUND($J20*0.17,0)) -> 1870 | M20: 8600 | N20: 3500 | O20: 2200 | P20: 2200 | Q20: 15950 | R20: 7150 | S20: =IF($C20="","",ROUND($J20*2.2,0)) -> 24200 | T20: 3850 | U20: 3300 | V20: 2000 | W20: 2400 | X20: 2 platforms | Y20: 0.3 | Z20: 1 | AA20: Mohammed Altowairqi | AB20: https://x.com/xihamoodx | AD20: https://www.twitch.tv/i_hmoodx | AQ20: 22000 | AV20: =IF(AND(AP20>0,J20>0),J20*1000/(AP20*0.2),"") | AW20: =IF(AND(AS20>0,M20>0),M20*1000/(AS20*0.3),"") | AX20: =IF(AND(AO20>0,O20>0),O20*1000/(AO20*0.1),"") | AY20: =IF(AND(AR20>0,N20>0),N20*1000/(AR20*0.25),"") | AZ20: =IF(AND(AQ20>0,Q20>0),Q20*1000/(AQ20*1),"") -> 725 | BA20: =IFERROR(VLOOKUP($I20,'07_Settings'!$A$10:$F$14,6,FALSE()),0.25) -> 0.35 | BB20: 1 | BC20: 1 | BD20: 1 | BE20: =IFERROR(ROUND($S20*BA20*BC20*BD20*BB20,0),0) -> 8470 | BF20: =IF(COUNT(AO20:AU20)>0,"estimated","pending") -> estimated
B21: =IF($C21="","",COUNTA($C$5:C21)) -> 17 | C21: xizx7 | D21: Player | E21: Call of Duty Warzone | F21: Team Falcons MENA | G21: Saudi Arabia | H21: 4 | I21: Tier 3 | J21: 12100 | K21: 5100 | L21: =IF($C21="","",ROUND($J21*0.17,0)) -> 2057 | M21: 9450 | N21: 3850 | O21: 2400 | P21: 2400 | Q21: 17550 | R21: 7850 | S21: =IF($C21="","",ROUND($J21*2.2,0)) -> 26620 | T21: 4250 | U21: 3650 | V21: 2200 | W21: 2400 | X21: 4 platforms | Y21: 0.3 | Z21: 1 | AA21: Jawad Al-Thawab | AB21: https://x.com/Jawxd7 | AC21: https://www.instagram.com/Jawxd7 | AD21: https://www.twitch.tv/jawad | AE21: https://www.youtube.com/channel/UCUWL8dR-JyA4FXZ08aSjjcg/videos | AQ21: 5000 | AV21: =IF(AND(AP21>0,J21>0),J21*1000/(AP21*0.2),"") | AW21: =IF(AND(AS21>0,M21>0),M21*1000/(AS21*0.3),"") | AX21: =IF(AND(AO21>0,O21>0),O21*1000/(AO21*0.1),"") | AY21: =IF(AND(AR21>0,N21>0),N21*1000/(AR21*0.25),"") | AZ21: =IF(AND(AQ21>0,Q21>0),Q21*1000/(AQ21*1),"") -> 3510 | BA21: =IFERROR(VLOOKUP($I21,'07_Settings'!$A$10:$F$14,6,FALSE()),0.25) -> 0.35 | BB21: 1 | BC21: 1 | BD21: 1 | BE21: =IFERROR(ROUND($S21*BA21*BC21*BD21*BB21,0),0) -> 9317 | BF21: =IF(COUNT(AO21:AU21)>0,"estimated","pending") -> estimated
B22: =IF($C22="","",COUNTA($C$5:C22)) -> 18 | C22: Alpine | D22: Manager | E22: Call of Duty Warzone | F22: Team Falcons | G22: American | H22: 1 | I22: Tier 4 | J22: 22750 | K22: 9550 | L22: =IF($C22="","",ROUND($J22*0.17,0)) -> 3868 | M22: 17750 | N22: 7300 | O22: 4550 | P22: 0 | Q22: 33000 | R22: 14800 | S22: =IF($C22="","",ROUND($J22*2.2,0)) -> 50050 | T22: 7950 | U22: 6850 | V22: 4100 | W22: 0 | X22: 1 platform | Y22: 0.3 | Z22: 1 | AA22: Alejandro Ayala | AB22: https://x.com/alpinedadog?lang=en | AK22: 24/02/1997 | AO22: 1170 | AV22: =IF(AND(AP22>0,J22>0),J22*1000/(AP22*0.2),"") | AW22: =IF(AND(AS22>0,M22>0),M22*1000/(AS22*0.3),"") | AX22: =IF(AND(AO22>0,O22>0),O22*1000/(AO22*0.1),"") -> 38888.889 | AY22: =IF(AND(AR22>0,N22>0),N22*1000/(AR22*0.25),"") | AZ22: =IF(AND(AQ22>0,Q22>0),Q22*1000/(AQ22*1),"") | BA22: =IFERROR(VLOOKUP($I22,'07_Settings'!$A$10:$F$14,6,FALSE()),0.25) -> 0.25 | BB22: 1 | BC22: 1 | BD22: 1 | BE22: =IFERROR(ROUND($S22*BA22*BC22*BD22*BB22,0),0) -> 12513 | BF22: =IF(COUNT(AO22:AU22)>0,"estimated","pending") -> estimated
B23: =IF($C23="","",COUNTA($C$5:C23)) -> 19 | C23: Newbz | D23: Player | E23: Call of Duty Warzone | F23: Team Falcons | G23: American | H23: 2 | I23: Tier 2 | J23: 20700 | K23: 8700 | L23: =IF($C23="","",ROUND($J23*0.17,0)) -> 3519 | M23: 16150 | N23: 6600 | O23: 4150 | P23: 4150 | Q23: 30000 | R23: 13450 | S23: =IF($C23="","",ROUND($J23*2.2,0)) -> 45540 | T23: 7250 | U23: 6200 | V23: 3750 | W23: 2400 | X23: 2 platforms | Y23: 0.2 | Z23: 1 | AA23: Edy Juan | AB23: https://x.com/TBE_Newbzz | AD23: https://www.twitch.tv/newbz | AK23: 36527 | AO23: 36000 | AQ23: 108000 | AV23: =IF(AND(AP23>0,J23>0),J23*1000/(AP23*0.2),"") | AW23: =IF(AND(AS23>0,M23>0),M23*1000/(AS23*0.3),"") | AX23: =IF(AND(AO23>0,O23>0),O23*1000/(AO23*0.1),"") -> 1152.7778 | AY23: =IF(AND(AR23>0,N23>0),N23*1000/(AR23*0.25),"") | AZ23: =IF(AND(AQ23>0,Q23>0),Q23*1000/(AQ23*1),"") -> 277.77778 | BA23: =IFERROR(VLOOKUP($I23,'07_Settings'!$A$10:$F$14,6,FALSE()),0.25) -> 0.45 | BB23: 1 | BC23: 1 | BD23: 1 | BE23: =IFERROR(ROUND($S23*BA23*BC23*BD23*BB23,0),0) -> 20493 | BF23: =IF(COUNT(AO23:AU23)>0,"estimated","pending") -> estimated
B24: =IF($C24="","",COUNTA($C$5:C24)) -> 20 | C24: Dongy | D24: Player | E24: Call of Duty Warzone | F24: Team Falcons | G24: American | H24: 2 | I24: Tier 2 | J24: 6500 | K24: 2750 | L24: =IF($C24="","",ROUND($J24*0.17,0)) -> 1105 | M24: 5050 | N24: 2100 | O24: 1300 | P24: 1300 | Q24: 9400 | R24: 4200 | S24: =IF($C24="","",ROUND($J24*2.2,0)) -> 14300 | T24: 2300 | U24: 1950 | V24: 1150 | W24: 2400 | X24: 2 platforms | Y24: 0.2 | Z24: 1 | AA24: Christopher Ledbetter | AB24: https://x.com/zDongyy | AD24: https://www.twitch.tv/Dongy | AK24: 23/03/2004 | AO24: 9000 | AQ24: 60000 | AV24: =IF(AND(AP24>0,J24>0),J24*1000/(AP24*0.2),"") | AW24: =IF(AND(AS24>0,M24>0),M24*1000/(AS24*0.3),"") | AX24: =IF(AND(AO24>0,O24>0),O24*1000/(AO24*0.1),"") -> 1444.4444 | AY24: =IF(AND(AR24>0,N24>0),N24*1000/(AR24*0.25),"") | AZ24: =IF(AND(AQ24>0,Q24>0),Q24*1000/(AQ24*1),"") -> 156.66667 | BA24: =IFERROR(VLOOKUP($I24,'07_Settings'!$A$10:$F$14,6,FALSE()),0.25) -> 0.45 | BB24: 1 | BC24: 1 | BD24: 1 | BE24: =IFERROR(ROUND($S24*BA24*BC24*BD24*BB24,0),0) -> 6435 | BF24: =IF(COUNT(AO24:AU24)>0,"estimated","pending") -> estimated
B25: =IF($C25="","",COUNTA($C$5:C25)) -> 21 | C25: Soka | D25: Player | E25: Call of Duty Warzone | F25: Team Falcons | G25: Tongan | H25: 5 | I25: Tier 2 | J25: 6500 | K25: 2750 | L25: =IF($C25="","",ROUND($J25*0.17,0)) -> 1105 | M25: 5050 | N25: 2100 | O25: 1300 | P25: 1300 | Q25: 9400 | R25: 4200 | S25: =IF($C25="","",ROUND($J25*2.2,0)) -> 14300 | T25: 2300 | U25: 1950 | V25: 1150 | W25: 2400 | X25: 5 platforms | Y25: 0.2 | Z25: 1 | AA25: Kasimili Tonga Tongamoa | AB25: https://twitter.com/HisokaT42 | AC25: https://www.instagram.com/hisokat42 | AD25: https://www.twitch.tv/HisokaT42 | AE25: https://www.youtube.com/channel/UCQDRE8aZRsrvF5OwMk_KmBg | AF25: https://tiktok.com/@missionarysoka | AK25: 28/01/2002 | AO25: 39000 | AP25: 32000 | AQ25: 191000 | AV25: =IF(AND(AP25>0,J25>0),J25*1000/(AP25*0.2),"") -> 1015.625 | AW25: =IF(AND(AS25>0,M25>0),M25*1000/(AS25*0.3),"") | AX25: =IF(AND(AO25>0,O25>0),O25*1000/(AO25*0.1),"") -> 333.33333 | AY25: =IF(AND(AR25>0,N25>0),N25*1000/(AR25*0.25),"") | AZ25: =IF(AND(AQ25>0,Q25>0),Q25*1000/(AQ25*1),"") -> 49.21466 | BA25: =IFERROR(VLOOKUP($I25,'07_Settings'!$A$10:$F$14,6,FALSE()),0.25) -> 0.45 | BB25: 1 | BC25: 1 | BD25: 1 | BE25: =IFERROR(ROUND($S25*BA25*BC25*BD25*BB25,0),0) -> 6435 | BF25: =IF(COUNT(AO25:AU25)>0,"estimated","pending") -> estimated
B26: =IF($C26="","",COUNTA($C$5:C26)) -> 22 | C26: Alireza Firouzja | D26: Player | E26: Chess | F26: Chess | G26: French/Iranian | H26: 5 | I26: Tier 2 | J26: 20700 | K26: 8700 | L26: =IF($C26="","",ROUND($J26*0.17,0)) -> 3519 | M26: 16150 | N26: 6600 | O26: 4150 | P26: 4150 | Q26: 30000 | R26: 13450 | S26: =IF($C26="","",ROUND($J26*2.2,0)) -> 45540 | T26: 7250 | U26: 6200 | V26: 3750 | W26: 2400 | X26: 5 platforms | Y26: 0.5 | Z26: 1 | AA26: Alireza Firouzja | AB26: https://twitter.com/AlirezaFirouzja | AC26: https://www.instagram.com/alirezafirouzja | AD26: https://www.twitch.tv/alirezafirouzja | AE26: https://www.youtube.com/@alirezafirouzja4080 | AH26: https://www.facebook.com/login/?next=https%3A%2F%2Fwww.facebook.com%2FAlireza.Firouzja.chess%2F | AK26: 18/06/2003 | AO26: 90000 | AP26: 149000 | AQ26: 97000 | AR26: 34500 | AU26: 1300 | AV26: =IF(AND(AP26>0,J26>0),J26*1000/(AP26*0.2),"") -> 694.63087 | AW26: =IF(AND(AS26>0,M26>0),M26*1000/(AS26*0.3),"") | AX26: =IF(AND(AO26>0,O26>0),O26*1000/(AO26*0.1),"") -> 461.11111 | AY26: =IF(AND(AR26>0,N26>0),N26*1000/(AR26*0.25),"") -> 765.21739 | AZ26: =IF(AND(AQ26>0,Q26>0),Q26*1000/(AQ26*1),"") -> 309.27835 | BA26: =IFERROR(VLOOKUP($I26,'07_Settings'!$A$10:$F$14,6,FALSE()),0.25) -> 0.45 | BB26: 1 | BC26: 1 | BD26: 1 | BE26: =IFERROR(ROUND($S26*BA26*BC26*BD26*BB26,0),0) -> 20493 | BF26: =IF(COUNT(AO26:AU26)>0,"estimated","pending") -> estimated
B27: =IF($C27="","",COUNTA($C$5:C27)) -> 23 | C27: Hikaru Nakamura | D27: Player | E27: Chess | F27: Chess | G27: American | H27: 6 | I27: Tier S | J27: 22500 | K27: 9450 | L27: =IF($C27="","",ROUND($J27*0.17,0)) -> 3825 | M27: 17550 | N27: 7200 | O27: 4500 | P27: 4500 | Q27: 32600 | R27: 14600 | S27: =IF($C27="","",ROUND($J27*2.2,0)) -> 49500 | T27: 7850 | U27: 6750 | V27: 4050 | W27: 2400 | X27: 6 platforms | Y27: 0.5 | Z27: 1 | AA27: Hikaru Nakamura | AB27: https://twitter.com/GMHikaru | AC27: https://www.instagram.com/gmhikaru | AD27: https://www.twitch.tv/gmhikaru | AE27: https://www.youtube.com/@gmhikaru | AG27: https://kick.com/gmhikaru | AH27: https://www.facebook.com/login/?next=https%3A%2F%2Fwww.facebook.com%2FGMHikaru%2F | AK27: 32120 | AO27: 629600 | AP27: 1000000 | AQ27: 2010000 | AR27: 3120000 | AS27: 730700 | AT27: 199200 | AU27: 323000 | AV27: =IF(AND(AP27>0,J27>0),J27*1000/(AP27*0.2),"") -> 112.5 | AW27: =IF(AND(AS27>0,M27>0),M27*1000/(AS27*0.3),"") -> 80.060216 | AX27: =IF(AND(AO27>0,O27>0),O27*1000/(AO27*0.1),"") -> 71.473952 | AY27: =IF(AND(AR27>0,N27>0),N27*1000/(AR27*0.25),"") -> 9.2307692 | AZ27: =IF(AND(AQ27>0,Q27>0),Q27*1000/(AQ27*1),"") -> 16.218905 | BA27: =IFERROR(VLOOKUP($I27,'07_Settings'!$A$10:$F$14,6,FALSE()),0.25) -> 0.65 | BB27: 1 | BC27: 1 | BD27: 1 | BE27: =IFERROR(ROUND($S27*BA27*BC27*BD27*BB27,0),0) -> 32175 | BF27: =IF(COUNT(AO27:AU27)>0,"estimated","pending") -> estimated
B28: =IF($C28="","",COUNTA($C$5:C28)) -> 24 | C28: Jon Ellis | D28: Manager | E28: Chess | F28: Chess | H28: 0 | I28: Tier 4 | J28: 22500 | K28: 9450 | L28: =IF($C28="","",ROUND($J28*0.17,0)) -> 3825 | M28: 17550 | N28: 7200 | O28: 4500 | P28: 0 | Q28: 32600 | R28: 14600 | S28: =IF($C28="","",ROUND($J28*2.2,0)) -> 49500 | T28: 7850 | U28: 6750 | V28: 4050 | W28: 0 | X28: 0 platforms | Y28: 0.3 | Z28: 1 | AA28: Jonathan Ellis | AV28: =IF(AND(AP28>0,J28>0),J28*1000/(AP28*0.2),"") | AW28: =IF(AND(AS28>0,M28>0),M28*1000/(AS28*0.3),"") | AX28: =IF(AND(AO28>0,O28>0),O28*1000/(AO28*0.1),"") | AY28: =IF(AND(AR28>0,N28>0),N28*1000/(AR28*0.25),"") | AZ28: =IF(AND(AQ28>0,Q28>0),Q28*1000/(AQ28*1),"") | BA28: =IFERROR(VLOOKUP($I28,'07_Settings'!$A$10:$F$14,6,FALSE()),0.25) -> 0.25 | BB28: 1 | BC28: 1 | BD28: 1 | BE28: =IFERROR(ROUND($S28*BA28*BC28*BD28*BB28,0),0) -> 12375 | BF28: =IF(COUNT(AO28:AU28)>0,"estimated","pending") -> pending
B29: =IF($C29="","",COUNTA($C$5:C29)) -> 25 | C29: kyousuke | D29: Player | E29: Counterstrike2 | F29: Team Falcons | G29: Russian | H29: 3 | I29: Tier 1 | J29: 15000 | K29: 6750 | L29: =IF($C29="","",ROUND($J29*0.17,0)) -> 2550 | M29: 11000 | N29: 5000 | O29: 3200 | P29: 3200 | Q29: 19500 | R29: 8775 | S29: =IF($C29="","",ROUND($J29*2.2,0)) -> 33000 | T29: 6800 | U29: 5950 | V29: 3570 | W29: 2400 | X29: 3 platforms | Y29: 0.75 | Z29: 1 | AA29: Maxim Lukin | AB29: https://twitter.com/FLCkyousuke | AC29: https://www.instagram.com/flckyousuke | AD29: https://www.twitch.tv/kyousuke999 | AK29: 30/01/2008 | AL29: Rifler | AO29: 39000 | AP29: 76000 | AQ29: 266000 | AV29: =IF(AND(AP29>0,J29>0),J29*1000/(AP29*0.2),"") -> 986.84211 | AW29: =IF(AND(AS29>0,M29>0),M29*1000/(AS29*0.3),"") | AX29: =IF(AND(AO29>0,O29>0),O29*1000/(AO29*0.1),"") -> 820.51282 | AY29: =IF(AND(AR29>0,N29>0),N29*1000/(AR29*0.25),"") | AZ29: =IF(AND(AQ29>0,Q29>0),Q29*1000/(AQ29*1),"") -> 73.308271 | BA29: =IFERROR(VLOOKUP($I29,'07_Settings'!$A$10:$F$14,6,FALSE()),0.25) -> 0.55 | BB29: 1 | BC29: 1 | BD29: 1 | BE29: =IFERROR(ROUND($S29*BA29*BC29*BD29*BB29,0),0) -> 18150 | BF29: =IF(COUNT(AO29:AU29)>0,"estimated","pending") -> estimated
B30: =IF($C30="","",COUNTA($C$5:C30)) -> 26 | C30: kyxsan | D30: Player | E30: Counterstrike2 | F30: Team Falcons | G30: North Macedonia | H30: 2 | I30: Tier 3 | J30: 22500 | K30: 9450 | L30: =IF($C30="","",ROUND($J30*0.17,0)) -> 3825 | M30: 17550 | N30: 7200 | O30: 4500 | P30: 4500 | Q30: 32600 | R30: 14600 | S30: =IF($C30="","",ROUND($J30*2.2,0)) -> 49500 | T30: 7850 | U30: 6750 | V30: 4050 | W30: 2400 | X30: 2 platforms | Y30: 0.75 | Z30: 1 | AA30: Damjan Stoilkovski | AB30: https://x.com/kyxsancs | AC30: https://www.instagram.com/kyxsancs/ | AK30: 26/05/2000 | AL30: IGL | AO30: 16000 | AP30: 11000 | AV30: =IF(AND(AP30>0,J30>0),J30*1000/(AP30*0.2),"") -> 10227.273 | AW30: =IF(AND(AS30>0,M30>0),M30*1000/(AS30*0.3),"") | AX30: =IF(AND(AO30>0,O30>0),O30*1000/(AO30*0.1),"") -> 2812.5 | AY30: =IF(AND(AR30>0,N30>0),N30*1000/(AR30*0.25),"") | AZ30: =IF(AND(AQ30>0,Q30>0),Q30*1000/(AQ30*1),"") | BA30: =IFERROR(VLOOKUP($I30,'07_Settings'!$A$10:$F$14,6,FALSE()),0.25) -> 0.35 | BB30: 1 | BC30: 1 | BD30: 1 | BE30: =IFERROR(ROUND($S30*BA30*BC30*BD30*BB30,0),0) -> 17325 | BF30: =IF(COUNT(AO30:AU30)>0,"estimated","pending") -> estimated
B31: =IF($C31="","",COUNTA($C$5:C31)) -> 27 | C31: m0NESY | D31: Player | E31: Counterstrike2 | F31: Team Falcons | G31: Russian | H31: 4 | I31: Tier S | J31: 22500 | K31: 9450 | L31: =IF($C31="","",ROUND($J31*0.17,0)) -> 3825 | M31: 17550 | N31: 7200 | O31: 4500 | P31: 4500 | Q31: 32600 | R31: 14600 | S31: =IF($C31="","",ROUND($J31*2.2,0)) -> 49500 | T31: 7850 | U31: 6750 | V31: 4050 | W31: 2400 | X31: 4 platforms | Y31: 0.2 | Z31: 1 | AA31: Ilya Osipov | AB31: https://x.com/FLCm0NESY | AC31: https://www.instagram.com/m0nesy13 | AD31: https://www.twitch.tv/m0nesyof | AE31: https://www.youtube.com/channel/UCJxjKA1Cl--4tCN1l_cHHvQ | AK31: 38357 | AL31: Awper | AO31: 323100 | AP31: 524000 | AQ31: 1179231 | AR31: 261000 | AV31: =IF(AND(AP31>0,J31>0),J31*1000/(AP31*0.2),"") -> 214.69466 | AW31: =IF(AND(AS31>0,M31>0),M31*1000/(AS31*0.3),"") | AX31: =IF(AND(AO31>0,O31>0),O31*1000/(AO31*0.1),"") -> 139.27577 | AY31: =IF(AND(AR31>0,N31>0),N31*1000/(AR31*0.25),"") -> 110.34483 | AZ31: =IF(AND(AQ31>0,Q31>0),Q31*1000/(AQ31*1),"") -> 27.645135 | BA31: =IFERROR(VLOOKUP($I31,'07_Settings'!$A$10:$F$14,6,FALSE()),0.25) -> 0.65 | BB31: 1 | BC31: 1 | BD31: 1 | BE31: =IFERROR(ROUND($S31*BA31*BC31*BD31*BB31,0),0) -> 32175 | BF31: =IF(COUNT(AO31:AU31)>0,"estimated","pending") -> estimated
B32: =IF($C32="","",COUNTA($C$5:C32)) -> 28 | C32: NiKo | D32: Player | E32: Counterstrike2 | F32: Team Falcons | G32: Bosnian | H32: 5 | I32: Tier 1 | J32: 22500 | K32: 9450 | L32: =IF($C32="","",ROUND($J32*0.17,0)) -> 3825 | M32: 17550 | N32: 7200 | O32: 4500 | P32: 4500 | Q32: 32600 | R32: 14600 | S32: =IF($C32="","",ROUND($J32*2.2,0)) -> 49500 | T32: 7850 | U32: 6750 | V32: 4050 | W32: 2400 | X32: 5 platforms | Y32: 0.3 | Z32: 1 | AA32: Nikola Kovač | AB32: https://x.com/NiKoCS_ | AC32: https://www.instagram.com/csgoniko/# | AD32: https://www.twitch.tv/NiKo | AE32: https://www.youtube.com/@NiKo_cs | AH32: https://www.facebook.com/csgoNiKo | AK32: 16/02/1997 | AL32: Rifler | AO32: 878100 | AP32: 639000 | AQ32: 727186 | AV32: =IF(AND(AP32>0,J32>0),J32*1000/(AP32*0.2),"") -> 176.05634 | AW32: =IF(AND(AS32>0,M32>0),M32*1000/(AS32*0.3),"") | AX32: =IF(AND(AO32>0,O32>0),O32*1000/(AO32*0.1),"") -> 51.247011 | AY32: =IF(AND(AR32>0,N32>0),N32*1000/(AR32*0.25),"") | AZ32: =IF(AND(AQ32>0,Q32>0),Q32*1000/(AQ32*1),"") -> 44.830346 | BA32: =IFERROR(VLOOKUP($I32,'07_Settings'!$A$10:$F$14,6,FALSE()),0.25) -> 0.55 | BB32: 1 | BC32: 1 | BD32: 1 | BE32: =IFERROR(ROUND($S32*BA32*BC32*BD32*BB32,0),0) -> 27225 | BF32: =IF(COUNT(AO32:AU32)>0,"estimated","pending") -> estimated
B33: =IF($C33="","",COUNTA($C$5:C33)) -> 29 | C33: OMYA | D33: Manager | E33: Counterstrike2 | F33: Team Falcons | G33: French | H33: 1 | I33: Tier 4 | J33: 22500 | K33: 9450 | L33: =IF($C33="","",ROUND($J33*0.17,0)) -> 3825 | M33: 17550 | N33: 7200 | O33: 4500 | P33: 0 | Q33: 32600 | R33: 14600 | S33: =IF($C33="","",ROUND($J33*2.2,0)) -> 49500 | T33: 7850 | U33: 6750 | V33: 4050 | W33: 0 | X33: 1 platform | Y33: 0.3 | Z33: 1 | AA33: Xavier Roussac | AB33: https://x.com/Xavier_Roussac | AK33: 20/05/1987 | AO33: 2565 | AV33: =IF(AND(AP33>0,J33>0),J33*1000/(AP33*0.2),"") | AW33: =IF(AND(AS33>0,M33>0),M33*1000/(AS33*0.3),"") | AX33: =IF(AND(AO33>0,O33>0),O33*1000/(AO33*0.1),"") -> 17543.86 | AY33: =IF(AND(AR33>0,N33>0),N33*1000/(AR33*0.25),"") | AZ33: =IF(AND(AQ33>0,Q33>0),Q33*1000/(AQ33*1),"") | BA33: =IFERROR(VLOOKUP($I33,'07_Settings'!$A$10:$F$14,6,FALSE()),0.25) -> 0.25 | BB33: 1 | BC33: 1 | BD33: 1 | BE33: =IFERROR(ROUND($S33*BA33*BC33*BD33*BB33,0),0) -> 12375 | BF33: =IF(COUNT(AO33:AU33)>0,"estimated","pending") -> estimated
B34: =IF($C34="","",COUNTA($C$5:C34)) -> 30 | C34: TeSeS | D34: Player | E34: Counterstrike2 | F34: Team Falcons | G34: Danish | H34: 2 | I34: Tier 3 | J34: 11250 | K34: 4500 | L34: =IF($C34="","",ROUND($J34*0.17,0)) -> 1913 | M34: 8000 | N34: 3500 | O34: 2000 | P34: 2000 | Q34: 13500 | R34: 6075 | S34: =IF($C34="","",ROUND($J34*2.2,0)) -> 24750 | T34: 4638 | U34: 4063 | V34: 2438 | W34: 2400 | X34: 2 platforms | Y34: 0.75 | Z34: 1 | AA34: René Madsen | AB34: https://x.com/tesescs | AC34: Instagram/TeseS | AD34: https://www.twitch.tv/tesesss | AK34: 36872 | AL34: Rifler | AO34: 45700 | AV34: =IF(AND(AP34>0,J34>0),J34*1000/(AP34*0.2),"") | AW34: =IF(AND(AS34>0,M34>0),M34*1000/(AS34*0.3),"") | AX34: =IF(AND(AO34>0,O34>0),O34*1000/(AO34*0.1),"") -> 437.63676 | AY34: =IF(AND(AR34>0,N34>0),N34*1000/(AR34*0.25),"") | AZ34: =IF(AND(AQ34>0,Q34>0),Q34*1000/(AQ34*1),"") | BA34: =IFERROR(VLOOKUP($I34,'07_Settings'!$A$10:$F$14,6,FALSE()),0.25) -> 0.35 | BB34: 1 | BC34: 1 | BD34: 1 | BE34: =IFERROR(ROUND($S34*BA34*BC34*BD34*BB34,0),0) -> 8663 | BF34: =IF(COUNT(AO34:AU34)>0,"estimated","pending") -> estimated
B35: =IF($C35="","",COUNTA($C$5:C35)) -> 31 | C35: Aymeinstein | D35: Assistant Coach | E35: Counterstrike2 | F35: Team Falcons | G35: French | H35: 2 | I35: Tier 4 | J35: 11000 | K35: 4600 | L35: =IF($C35="","",ROUND($J35*0.17,0)) -> 1870 | M35: 8600 | N35: 3500 | O35: 2200 | P35: 0 | Q35: 15950 | R35: 7150 | S35: =IF($C35="","",ROUND($J35*2.2,0)) -> 24200 | T35: 3850 | U35: 3300 | V35: 2000 | W35: 0 | X35: 2 platforms | Y35: 0.5 | Z35: 1 | AA35: Aymen Bencheikh | AB35: https://x.com/aymeinstein | AC35: https://www.instagram.com/aymeinsteintv | AK35: 22/04/1996 | AO35: 4833 | AP35: 4318 | AV35: =IF(AND(AP35>0,J35>0),J35*1000/(AP35*0.2),"") -> 12737.378 | AW35: =IF(AND(AS35>0,M35>0),M35*1000/(AS35*0.3),"") | AX35: =IF(AND(AO35>0,O35>0),O35*1000/(AO35*0.1),"") -> 4552.0381 | AY35: =IF(AND(AR35>0,N35>0),N35*1000/(AR35*0.25),"") | AZ35: =IF(AND(AQ35>0,Q35>0),Q35*1000/(AQ35*1),"") | BA35: =IFERROR(VLOOKUP($I35,'07_Settings'!$A$10:$F$14,6,FALSE()),0.25) -> 0.25 | BB35: 1 | BC35: 1 | BD35: 1 | BE35: =IFERROR(ROUND($S35*BA35*BC35*BD35*BB35,0),0) -> 6050 | BF35: =IF(COUNT(AO35:AU35)>0,"estimated","pending") -> estimated
B36: =IF($C36="","",COUNTA($C$5:C36)) -> 32 | C36: Zonic | D36: Head Coach | E36: Counterstrike2 | F36: Team Falcons | G36: Danish | H36: 2 | I36: Tier 2 | J36: 0 | K36: 0 | L36: =IF($C36="","",ROUND($J36*0.17,0)) -> 0 | M36: 0 | N36: 0 | O36: 0 | P36: 0 | Q36: 0 | R36: 0 | S36: =IF($C36="","",ROUND($J36*2.2,0)) -> 0 | T36: 0 | U36: 0 | V36: 2000 | W36: 0 | X36: 2 platforms | Y36: 0.5 | Z36: 1 | AA36: Danny Sørensen | AB36: https://x.com/zonic | AC36: Instagram/Zonic | AD36: https://www.twitch.tv/zonic | AH36: Facebook/Zonic | AK36: 30/07/1986 | AO36: 121400 | AP36: 80000 | AV36: =IF(AND(AP36>0,J36>0),J36*1000/(AP36*0.2),"") | AW36: =IF(AND(AS36>0,M36>0),M36*1000/(AS36*0.3),"") | AX36: =IF(AND(AO36>0,O36>0),O36*1000/(AO36*0.1),"") | AY36: =IF(AND(AR36>0,N36>0),N36*1000/(AR36*0.25),"") | AZ36: =IF(AND(AQ36>0,Q36>0),Q36*1000/(AQ36*1),"") | BA36: =IFERROR(VLOOKUP($I36,'07_Settings'!$A$10:$F$14,6,FALSE()),0.25) -> 0.45 | BB36: 1 | BC36: 1 | BD36: 1 | BE36: =IFERROR(ROUND($S36*BA36*BC36*BD36*BB36,0),0) -> 0 | BF36: =IF(COUNT(AO36:AU36)>0,"estimated","pending") -> estimated
B37: =IF($C37="","",COUNTA($C$5:C37)) -> 33 | C37: clockzi | D37: Player | E37: Counterstrike2 | F37: Falcons Force | G37: Danish | H37: 1 | I37: Tier 3 | J37: 11000 | K37: 4600 | L37: =IF($C37="","",ROUND($J37*0.17,0)) -> 1870 | M37: 8600 | N37: 3500 | O37: 2200 | P37: 2200 | Q37: 15950 | R37: 7150 | S37: =IF($C37="","",ROUND($J37*2.2,0)) -> 24200 | T37: 3850 | U37: 3300 | V37: 2000 | W37: 2400 | X37: 1 platform | Y37: 0.75 | Z37: 1 | AA37: Oskar Led Blæsbjerg | AB37: https://x.com/flcclockzi | AK37: 21/04/2011 | AL37: Rifler | AO37: 361 | AV37: =IF(AND(AP37>0,J37>0),J37*1000/(AP37*0.2),"") | AW37: =IF(AND(AS37>0,M37>0),M37*1000/(AS37*0.3),"") | AX37: =IF(AND(AO37>0,O37>0),O37*1000/(AO37*0.1),"") -> 60941.828 | AY37: =IF(AND(AR37>0,N37>0),N37*1000/(AR37*0.25),"") | AZ37: =IF(AND(AQ37>0,Q37>0),Q37*1000/(AQ37*1),"") | BA37: =IFERROR(VLOOKUP($I37,'07_Settings'!$A$10:$F$14,6,FALSE()),0.25) -> 0.35 | BB37: 1 | BC37: 1 | BD37: 1 | BE37: =IFERROR(ROUND($S37*BA37*BC37*BD37*BB37,0),0) -> 8470 | BF37: =IF(COUNT(AO37:AU37)>0,"estimated","pending") -> estimated
B38: =IF($C38="","",COUNTA($C$5:C38)) -> 34 | C38: grecu | D38: Player | E38: Counterstrike2 | F38: Falcons Force | G38: Romanian | H38: 2 | I38: Tier 2 | J38: 5200 | K38: 2200 | L38: =IF($C38="","",ROUND($J38*0.17,0)) -> 884 | M38: 4050 | N38: 1650 | O38: 1050 | P38: 1050 | Q38: 7550 | R38: 3400 | S38: =IF($C38="","",ROUND($J38*2.2,0)) -> 11440 | T38: 1800 | U38: 1550 | V38: 950 | W38: 2400 | X38: 2 platforms | Y38: 0.75 | Z38: 1 | AA38: Andrei Grecu | AB38: https://x.com/grecuflc | AD38: https://www.twitch.tv/gbcgrecu | AK38: 15/11/2007 | AL38: AWPer | AV38: =IF(AND(AP38>0,J38>0),J38*1000/(AP38*0.2),"") | AW38: =IF(AND(AS38>0,M38>0),M38*1000/(AS38*0.3),"") | AX38: =IF(AND(AO38>0,O38>0),O38*1000/(AO38*0.1),"") | AY38: =IF(AND(AR38>0,N38>0),N38*1000/(AR38*0.25),"") | AZ38: =IF(AND(AQ38>0,Q38>0),Q38*1000/(AQ38*1),"") | BA38: =IFERROR(VLOOKUP($I38,'07_Settings'!$A$10:$F$14,6,FALSE()),0.25) -> 0.45 | BB38: 1 | BC38: 1 | BD38: 1 | BE38: =IFERROR(ROUND($S38*BA38*BC38*BD38*BB38,0),0) -> 5148 | BF38: =IF(COUNT(AO38:AU38)>0,"estimated","pending") -> pending
B39: =IF($C39="","",COUNTA($C$5:C39)) -> 35 | C39: VENO | D39: Player | E39: Counterstrike2 | F39: Falcons Force | G39: Serbian | H39: 3 | I39: Tier 2 | J39: 12100 | K39: 5100 | L39: =IF($C39="","",ROUND($J39*0.17,0)) -> 2057 | M39: 9450 | N39: 3850 | O39: 2400 | P39: 2400 | Q39: 17550 | R39: 7850 | S39: =IF($C39="","",ROUND($J39*2.2,0)) -> 26620 | T39: 4250 | U39: 3650 | V39: 2200 | W39: 2400 | X39: 3 platforms | Y39: 0.75 | Z39: 1 | AA39: Vladimir Stanković | AB39: https://x.com/venocs2 | AD39: https://www.twitch.tv/venocs2 | AE39: https://www.youtube.com/@venocs2 | AK39: 30/04/2007 | AL39: Rifler | AO39: 489 | AV39: =IF(AND(AP39>0,J39>0),J39*1000/(AP39*0.2),"") | AW39: =IF(AND(AS39>0,M39>0),M39*1000/(AS39*0.3),"") | AX39: =IF(AND(AO39>0,O39>0),O39*1000/(AO39*0.1),"") -> 49079.755 | AY39: =IF(AND(AR39>0,N39>0),N39*1000/(AR39*0.25),"") | AZ39: =IF(AND(AQ39>0,Q39>0),Q39*1000/(AQ39*1),"") | BA39: =IFERROR(VLOOKUP($I39,'07_Settings'!$A$10:$F$14,6,FALSE()),0.25) -> 0.45 | BB39: 1 | BC39: 1 | BD39: 1 | BE39: =IFERROR(ROUND($S39*BA39*BC39*BD39*BB39,0),0) -> 11979 | BF39: =IF(COUNT(AO39:AU39)>0,"estimated","pending") -> estimated
B40: =IF($C40="","",COUNTA($C$5:C40)) -> 36 | C40: NaToSaphiX | D40: Head Coach | E40: Counterstrike2 | F40: Falcons Force | G40: Danish | H40: 5 | I40: Tier 2 | J40: 11000 | K40: 4600 | L40: =IF($C40="","",ROUND($J40*0.17,0)) -> 1870 | M40: 8600 | N40: 3500 | O40: 2200 | P40: 0 | Q40: 15950 | R40: 7150 | S40: =IF($C40="","",ROUND($J40*2.2,0)) -> 24200 | T40: 3850 | U40: 3300 | V40: 2000 | W40: 0 | X40: 5 platforms | Y40: 0.2 | Z40: 1 | AA40: Niels Christian Sillassen | AB40: https://x.com/NaToSaphiX | AC40: https://www.instagram.com/natosaphix | AD40: https://www.twitch.tv/natosaphix | AE40: https://www.youtube.com/NaToSaphiX | AK40: 17/08/1996 | AO40: 30500 | AQ40: 108539 | AR40: 138000 | AV40: =IF(AND(AP40>0,J40>0),J40*1000/(AP40*0.2),"") | AW40: =IF(AND(AS40>0,M40>0),M40*1000/(AS40*0.3),"") | AX40: =IF(AND(AO40>0,O40>0),O40*1000/(AO40*0.1),"") -> 721.31148 | AY40: =IF(AND(AR40>0,N40>0),N40*1000/(AR40*0.25),"") -> 101.44928 | AZ40: =IF(AND(AQ40>0,Q40>0),Q40*1000/(AQ40*1),"") -> 146.95179 | BA40: =IFERROR(VLOOKUP($I40,'07_Settings'!$A$10:$F$14,6,FALSE()),0.25) -> 0.45 | BB40: 1 | BC40: 1 | BD40: 1 | BE40: =IFERROR(ROUND($S40*BA40*BC40*BD40*BB40,0),0) -> 10890 | BF40: =IF(COUNT(AO40:AU40)>0,"estimated","pending") -> estimated
B41: =IF($C41="","",COUNTA($C$5:C41)) -> 37 | C41: Neoskai | D41: Manager | E41: Counterstrike2 | F41: Falcons Force | G41: French | H41: 2 | I41: Tier 4 | J41: 0 | K41: 0 | L41: =IF($C41="","",ROUND($J41*0.17,0)) -> 0 | M41: 0 | N41: 0 | O41: 0 | P41: 0 | Q41: 0 | R41: 0 | S41: =IF($C41="","",ROUND($J41*2.2,0)) -> 0 | T41: 0 | U41: 0 | V41: 1200 | W41: 0 | X41: 2 platforms | Y41: 0.2 | Z41: 1 | AA41: Loïc Potages | AB41: https://x.com/Neoskai | AC41: https://www.instagram.com/neoskai/ | AK41: 16/06/1994 | AV41: =IF(AND(AP41>0,J41>0),J41*1000/(AP41*0.2),"") | AW41: =IF(AND(AS41>0,M41>0),M41*1000/(AS41*0.3),"") | AX41: =IF(AND(AO41>0,O41>0),O41*1000/(AO41*0.1),"") | AY41: =IF(AND(AR41>0,N41>0),N41*1000/(AR41*0.25),"") | AZ41: =IF(AND(AQ41>0,Q41>0),Q41*1000/(AQ41*1),"") | BA41: =IFERROR(VLOOKUP($I41,'07_Settings'!$A$10:$F$14,6,FALSE()),0.25) -> 0.25 | BB41: 1 | BC41: 1 | BD41: 1 | BE41: =IFERROR(ROUND($S41*BA41*BC41*BD41*BB41,0),0) -> 0 | BF41: =IF(COUNT(AO41:AU41)>0,"estimated","pending") -> pending
...

Sheet 02_Creator_Rate_Card
B2: CREATOR RATE CARD
B3: Top-tier content creators · Scoring: Reach 40% · Engagement 30% · Audience Quality 20% · Authority 10%
B4: # | C4: Creator | D4: Score | E4: Tier | F4: X Post / Quote | G4: X Repost | H4: IG Post | I4: IG Story | J4: IG Reels | K4: YT Full Video | L4: YT 1–2min Pre-roll | M4: YT Shorts | N4: Snapchat | O4: TikTok Our-side | P4: TikTok Client Vids | Q4: Event + Snap | R4: Twitch / Kick Live | S4: Kick IRL | T4: Telegram | U4: Notes | V4: Link
B5: =IF($C5="","",COUNTA($C$5:C5)) -> 1 | C5: BanderitaX | D5: 98 | E5: Tier S | F5: 56250 | G5: 22500 | H5: 28125 | I5: 16875 | J5: 28125 | K5: 67500 | L5: 50625 | M5: 39375 | N5: 31500 | O5: 14063 | P5: 28125 | Q5: 11250 | R5: 39375
B6: =IF($C6="","",COUNTA($C$5:C6)) -> 2 | C6: oPiiLz | D6: 72 | E6: Tier 1 | F6: 22500 | G6: 9000 | H6: 11250 | I6: 6750 | J6: 11250 | K6: 27000 | L6: 20250 | M6: 15750 | N6: 12600 | O6: 5625 | P6: 11250 | Q6: 4500 | R6: 15750
B7: =IF($C7="","",COUNTA($C$5:C7)) -> 3 | C7: Msdossary7 | D7: 72 | E7: Tier 1 | F7: 22500 | G7: 9000 | H7: 11250 | I7: 6750 | J7: 11250 | K7: 27000 | L7: 20250 | M7: 15750 | N7: 12600 | O7: 5625 | P7: 11250 | Q7: 4500 | R7: 15750
B8: =IF($C8="","",COUNTA($C$5:C8)) -> 4 | C8: Aziz | D8: 68 | E8: Tier 1 | F8: 18000 | G8: 7200 | H8: 9000 | I8: 5400 | J8: 9000 | K8: 21600 | L8: 16200 | M8: 12600 | N8: 10080 | O8: 4500 | P8: 9000 | Q8: 3600 | R8: 12600
B9: =IF($C9="","",COUNTA($C$5:C9)) -> 5 | C9: Bo3omar22 | D9: 68 | E9: Tier 1 | F9: 18000 | G9: 7200 | H9: 9000 | I9: 5400 | J9: 9000 | K9: 21600 | L9: 16200 | M9: 12600 | N9: 10080 | O9: 4500 | P9: 9000 | Q9: 3600 | R9: 12600
B10: =IF($C10="","",COUNTA($C$5:C10)) -> 6 | C10: Abu abeer | D10: 60 | E10: Tier 2 | F10: 11250 | G10: 4500 | H10: 5625 | I10: 3375 | J10: 5625 | K10: 13500 | L10: 10125 | M10: 7875 | N10: 6300 | O10: 2813 | P10: 5625 | Q10: 2250 | R10: 7875
B11: =IF($C11="","",COUNTA($C$5:C11)) -> 7 | C11: LLE | D11: 58 | E11: Tier 2 | F11: 10125 | G11: 4050 | H11: 5063 | I11: 3038 | J11: 5063 | K11: 12150 | L11: 9113 | M11: 7088 | N11: 5670 | O11: 2531 | P11: 5063 | Q11: 2025 | R11: 7088
B12: =IF($C12="","",COUNTA($C$5:C12)) -> 8 | C12: Oden | D12: 55 | E12: Tier 2 | F12: 9000 | G12: 3600 | H12: 4500 | I12: 2700 | J12: 4500 | K12: 10800 | L12: 8100 | M12: 6300 | N12: 5040 | O12: 2250 | P12: 4500 | Q12: 1800 | R12: 6300
B13: =IF($C13="","",COUNTA($C$5:C13)) -> 9 | C13: xSMA333 | D13: 52 | E13: Tier 2 | F13: 7875 | G13: 3150 | H13: 3938 | I13: 2363 | J13: 3938 | K13: 9450 | L13: 7088 | M13: 5513 | N13: 4410 | O13: 1969 | P13: 3938 | Q13: 1575 | R13: 5513
B14: =IF($C14="","",COUNTA($C$5:C14)) -> 10 | C14: 3ADEL | D14: 50 | E14: Tier 2 | F14: 6750 | G14: 2700 | H14: 3375 | I14: 2025 | J14: 3375 | K14: 8100 | L14: 6075 | M14: 4725 | N14: 3780 | O14: 1688 | P14: 3375 | Q14: 1350 | R14: 4725
B15: =IF($C15="","",COUNTA($C$5:C15)) -> 11 | C15: RAED | D15: 48 | E15: Tier 2 | F15: 6188 | G15: 2475 | H15: 3094 | I15: 1856 | J15: 3094 | K15: 7425 | L15: 5569 | M15: 4331 | N15: 3465 | O15: 1547 | P15: 3094 | Q15: 1238 | R15: 4331
B16: =IF($C16="","",COUNTA($C$5:C16)) -> 12 | C16: Falcons | D16: 45 | E16: Tier 2 | F16: 5625 | G16: 2250 | H16: 2813 | I16: 1688 | J16: 2813 | K16: 6750 | L16: 5063 | M16: 3938 | N16: 3150 | O16: 1406 | P16: 2813 | Q16: 1125 | R16: 3938
... B21: =IF($C21="","",COUNTA($C$5:C21)) -> 17 | C21: 9leeh | D21: 32 | E21: Tier 3 | F21: 2250 | G21: 900 | H21: 1125 | I21: 675 | J21: 1125 | K21: 2700 | L21: 2025 | M21: 1575 | N21: 1260 | O21: 563 | P21: 1125 | Q21: 450 | R21: 1575
B22: =IF($C22="","",COUNTA($C$5:C22))
B23: =IF($C23="","",COUNTA($C$5:C23))
B24: =IF($C24="","",COUNTA($C$5:C24))
B25: =IF($C25="","",COUNTA($C$5:C25))
B26: =IF($C26="","",COUNTA($C$5:C26))
B27: =IF($C27="","",COUNTA($C$5:C27))
B28: =IF($C28="","",COUNTA($C$5:C28))
B29: =IF($C29="","",COUNTA($C$5:C29))
B30: =IF($C30="","",COUNTA($C$5:C30))
B31: =IF($C31="","",COUNTA($C$5:C31))
B32: =IF($C32="","",COUNTA($C$5:C32))
B33: =IF($C33="","",COUNTA($C$5:C33))
... B36: =IF($C36="","",COUNTA($C$5:C36))

Sheet 02_Adjustment_Matrix
B2: DYNAMIC PRICING ADJUSTMENT MATRIX
B3: Select a player → choose an asset → adjust multipliers → get the final price
B5: 🔍 Search Player | D5: moaz | F5: =IFERROR(__xludf.dummyfunction("IF(TRIM(D5)="""","""",IFERROR(INDEX(FILTER('01_Player_Rate_Card'!C$5:C1016,REGEXMATCH(LOWER('01_Player_Rate_Card'!C$5:C1016),LOWER(TRIM(D5)))) ,1),""No match — check spelling""))"),"Moaz") -> Moaz | H5: Type a full or partial name in D5 → best matching player appears in F5 → selection syncs automatically below
B7: ① PLAYER SELECTOR
B8: Select Player | C8: Game | D8: Team | E8: Role | F8: Tier | G8: Nationality | H8: Platforms
B9: =IF(OR($F$5="",$F$5="No match — check spelling"),"",$F$5) -> Moaz | C9: =IFERROR(VLOOKUP(B9,'01_Player_Rate_Card'!$C$5:$AL$500,3,0),"") -> Esports Influencers | D9: =IFERROR(VLOOKUP(B9,'01_Player_Rate_Card'!$C$5:$AL$500,4,0),"") -> Esports Influencers | E9: =IFERROR(VLOOKUP(B9,'01_Player_Rate_Card'!$C$5:$AL$500,2,0),"") -> Influencer | F9: =IFERROR(VLOOKUP(B9,'01_Player_Rate_Card'!$C$5:$AL$500,7,0),"") -> Tier 2 | G9: =IFERROR(VLOOKUP(B9,'01_Player_Rate_Card'!$C$5:$AL$500,5,0),"") -> Saudi Arabia | H9: =IFERROR(VLOOKUP(B9,'01_Player_Rate_Card'!$C$5:$AL$500,6,0),"") -> 5
B10: ② PLAYER RATE CARD (all values in SAR)
B11: IG Reel | C11: IG Static | D11: IG Story | E11: TikTok Video | F11: YT Short | G11: X Post | H11: FB Post/Video | I11: Twitch 2h | J11: Twitch Integ. | K11: IRL / Appear. | L11: Rights Fee | M11: Exclusivity | N11: Rush Fee | O11: WL Fee | P11: Repost
B12: =IFERROR(VLOOKUP(B9,'01_Player_Rate_Card'!$C$5:$AL$500,8,0),"N/A") -> 6500 | C12: =IFERROR(VLOOKUP(B9,'01_Player_Rate_Card'!$C$5:$AL$500,9,0),"N/A") -> 5300 | D12: =IFERROR(VLOOKUP(B9,'01_Player_Rate_Card'!$C$5:$AL$500,10,0),"N/A") -> 1105 | E12: =IFERROR(VLOOKUP(B9,'01_Player_Rate_Card'!$C$5:$AL$500,11,0),"N/A") -> 3400 | F12: =IFERROR(VLOOKUP(B9,'01_Player_Rate_Card'!$C$5:$AL$500,12,0),"N/A") -> 4050 | G12: =IFERROR(VLOOKUP(B9,'01_Player_Rate_Card'!$C$5:$AL$500,13,0),"N/A") -> 2500 | H12: =IFERROR(VLOOKUP(B9,'01_Player_Rate_Card'!$C$5:$AL$500,14,0),"N/A") -> 2500 | I12: =IFERROR(VLOOKUP(B9,'01_Player_Rate_Card'!$C$5:$AL$500,15,0),"N/A") -> 15950 | J12: =IFERROR(VLOOKUP(B9,'01_Player_Rate_Card'!$C$5:$AL$500,16,0),"N/A") -> 8200 | K12: =IFERROR(VLOOKUP(B9,'01_Player_Rate_Card'!$C$5:$AL$500,17,0),"N/A") -> 14300 | L12: =IFERROR(VLOOKUP(B9,'01_Player_Rate_Card'!$C$5:$AL$500,18,0),"N/A") -> 3800 | M12: =IFERROR(VLOOKUP(B9,'01_Player_Rate_Card'!$C$5:$AL$500,19,0),"N/A") -> 1900 | N12: =IFERROR(VLOOKUP(B9,'01_Player_Rate_Card'!$C$5:$AL$500,20,0),"N/A") -> 3150 | O12: =IFERROR(VLOOKUP(B9,'01_Player_Rate_Card'!$C$5:$AL$500,21,0),"N/A") -> 1250 | P12: =IFERROR(ROUND(IFERROR(VLOOKUP(B9,'01_Player_Rate_Card'!$C$5:$AL$500,8,0),0)*0.15,0),"N/A") -> 975
B14: ③ ASSET SELECTOR — Choose the deliverable type
B15: Asset Type | D15: Base Fee (SAR) | F15: Notes / Basis
B16: Podcast Guesting | D16: {=IFERROR(xlookup(B16,$B$17:$B$34,$D$17:$D$34,0),0)} -> 0
B17: IG Reel | D17: =IFERROR(VLOOKUP($B$9,'01_Player_Rate_Card'!$C$5:$AL$500,8,FALSE()),0) -> 6500 | F17: Player IG Reel rate from Rate Card
B18: IG Static Post | D18: =IFERROR(VLOOKUP($B$9,'01_Player_Rate_Card'!$C$5:$AL$500,9,FALSE()),0) -> 5300 | F18: Player IG Static rate
B19: IG Story | D19: =IFERROR(VLOOKUP($B$9,'01_Player_Rate_Card'!$C$5:$AL$500,10,FALSE()),0) -> 1105 | F19: Player IG Story rate
B20: TikTok Video | D20: =IFERROR(VLOOKUP($B$9,'01_Player_Rate_Card'!$C$5:$AL$500,11,FALSE()),0) -> 3400 | F20: Player TikTok rate
B21: YT Short | D21: =IFERROR(VLOOKUP($B$9,'01_Player_Rate_Card'!$C$5:$AL$500,12,FALSE()),0) -> 4050 | F21: Player YT Short rate
B22: X Post | D22: =IFERROR(VLOOKUP($B$9,'01_Player_Rate_Card'!$C$5:$AL$500,13,FALSE()),0) -> 2500 | F22: Player X Post rate
B23: FB Post / Video | D23: =IFERROR(VLOOKUP($B$9,'01_Player_Rate_Card'!$C$5:$AL$500,14,FALSE()),0) -> 2500 | F23: Player FB rate
B24: Content Repost | D24: =IFERROR(VLOOKUP($B$9,'01_Player_Rate_Card'!$C$5:$AL$500,8,FALSE())*0.15,0) -> 975 | F24: 15% of IG Reel rate
B25: — LIVE & STREAM —
B26: Twitch Stream 2h | D26: =IFERROR(VLOOKUP($B$9,'01_Player_Rate_Card'!$C$5:$AL$500,15,FALSE()),0) -> 15950 | F26: Player Twitch 2h rate
B27: Twitch Integration | D27: =IFERROR(VLOOKUP($B$9,'01_Player_Rate_Card'!$C$5:$AL$500,16,FALSE()),0) -> 8200 | F27: Player Twitch Integ. rate
B28: — ON-GROUND & EVENTS —
B29: IRL Appearance | D29: =IFERROR(VLOOKUP($B$9,'01_Player_Rate_Card'!$C$5:$AL$500,17,FALSE()),0) -> 14300 | F29: Player IRL rate
B30: Podcast Guesting | D30: =IFERROR(VLOOKUP($B$9,'01_Player_Rate_Card'!$C$5:$AL$500,17,FALSE())*0.5,0) -> 7150 | F30: 50% of IRL — 1-2h time commitment
B31: PR Appearance / CSR | D31: =IFERROR(VLOOKUP($B$9,'01_Player_Rate_Card'!$C$5:$AL$500,17,FALSE()),0) -> 14300 | F31: Full IRL rate — brand presence + media
